Workbook

Sheet Blackbutt
A1: File | B1: Vegetation | C1: Thermal Energy (kW/m2) | D1: Std Err | E1: R_sqrd | F1: D pos | G1: D ht | H1: D fwhm | I1: D area | J1: D %area | K1: D fwhm/G fwhm | L1: Ad/AG | M1: Band sepration | N1: G_G pos | O1: G_G ht | P1: G_G fwhm | Q1: G_G area | R1: G_G %area | S1: S_L pos | T1: S_L ht | U1: S_L fwhm | V1: S_L area | W1: S_L %area | X1: S pos | Y1: S ht | Z1: S fwhm | AA1: S area | AB1: S %area | AC1: D_S pos | AD1: D_S ht | AE1: D_S fwhm | AF1: D_S area | AG1: D_S %area | AH1: A_1 pos | AI1: A_1 ht | AJ1: A_1 fwhm | AK1: A_1 area | AL1: A_1 %area | AM1: A_2 pos | AN1: A_2 ht | AO1: A_2 fwhm | AP1: A_2 area | AQ1: A_2 %area | AR1: G_L pos | AS1: G_L ht | AT1: G_L fwhm | AU1: G_L area | AV1: G_L %area | AW1: C pos | AX1: C ht | AY1: C fwhm | AZ1: C area | BA1: C %area
A2: data/Blackbutt Eucalyptus/BE- 25 (2).txt | B2: Blackbutt | C2: 25 | D2: 41.21 counts | E2: 0.993322 | F2: 1365 | G2: 36427 | H2: 200 | I2: 7755068 | J2: 47.9 | K2: 1.8018018 | L2: 1.3437247 | M2: 223 | N2: 1588 | O2: 48845 | P2: 111 | Q2: 5771322 | R2: 35.6 | S2: 1073 | T2: 3661 | U2: 166 | V2: 646904 | W2: 4 | X2: 1188 | Y2: 7865 | Z2: 112 | AA2: 937668 | AB2: 5.8 | AC2: 1264 | AD2: 1537 | AE2: 50 | AF2: 81804 | AG2: 0.5 | AH2: 1458 | AI2: 1819 | AJ2: 50 | AK2: 96813 | AL2: 0.6 | AM2: 1492 | AN2: 5745 | AO2: 50 | AP2: 305768 | AQ2: 1.9 | AR2: 1592 | AS2: 2701 | AT2: 50 | AU2: 143756 | AV2: 0.9 | AW2: 1734 | AX2: 4269 | AY2: 100 | AZ2: 454421 | BA2: 2.8
A3: data/Blackbutt Eucalyptus/BE- 25 (3).txt | B3: Blackbutt | C3: 25 | D3: 41.71 counts | E3: 0.995251 | F3: 1365 | G3: 43981 | H3: 200 | I3: 9363265 | J3: 47.8 | K3: 1.8348624 | L3: 1.4034379 | M3: 223 | N3: 1588 | O3: 57501 | P3: 109 | Q3: 6671663 | R3: 34.1 | S3: 1073 | T3: 4547 | U3: 160 | V3: 774421 | W3: 4 | X3: 1194 | Y3: 9663 | Z3: 118 | AA3: 1213742 | AB3: 6.2 | AC3: 1272 | AD3: 363 | AE3: 50 | AF3: 19320 | AG3: 0.1 | AH3: 1458 | AI3: 3747 | AJ3: 50 | AK3: 199428 | AL3: 1 | AM3: 1498 | AN3: 8381 | AO3: 52 | AP3: 463908 | AQ3: 2.4 | AR3: 1586 | AS3: 3831 | AT3: 50 | AU3: 203899 | AV3: 1 | AW3: 1732 | AX3: 5745 | AY3: 108 | AZ3: 660459 | BA3: 3.4
A4: data/Blackbutt Eucalyptus/BE- 25 (4).txt | B4: Blackbutt | C4: 25 | D4: 28.01 counts | E4: 0.995017 | F4: 1365 | G4: 29209 | H4: 200 | I4: 6218404 | J4: 48.8 | K4: 1.8348624 | L4: 1.4439339 | M4: 221 | N4: 1586 | O4: 37117 | P4: 109 | Q4: 4306571 | R4: 33.8 | S4: 1073 | T4: 2979 | U4: 180 | V4: 570789 | W4: 4.5 | X4: 1192 | Y4: 5929 | Z4: 116 | AA4: 732102 | AB4: 5.7 | AC4: 1268 | AD4: 485 | AE4: 50 | AF4: 25813 | AG4: 0.2 | AH4: 1458 | AI4: 2019 | AJ4: 50 | AK4: 107458 | AL4: 0.8 | AM4: 1494 | AN4: 4313 | AO4: 50 | AP4: 229552 | AQ4: 1.8 | AR4: 1594 | AS4: 3267 | AT4: 50 | AU4: 173881 | AV4: 1.4 | AW4: 1728 | AX4: 3467 | AY4: 104 | AZ4: 383813 | BA4: 3
A5: data/Blackbutt Eucalyptus/BE- 25 (5).txt | B5: Blackbutt | C5: 25 | D5: 21.74 counts | E5: 0.993975 | F5: 1365 | G5: 21091 | H5: 200 | I5: 4490135 | J5: 49.9 | K5: 1.980198 | L5: 1.5129272 | M5: 225 | N5: 1590 | O5: 27605 | P5: 101 | Q5: 2967846 | R5: 33 | S5: 1073 | T5: 2047 | U5: 172 | V5: 374782 | W5: 4.2 | X5: 1188 | Y5: 4217 | Z5: 114 | AA5: 511730 | AB5: 5.7 | AC5: 1266 | AD5: 463 | AE5: 50 | AF5: 24642 | AG5: 0.3 | AH5: 1458 | AI5: 1063 | AJ5: 50 | AK5: 56576 | AL5: 0.6 | AM5: 1498 | AN5: 4627 | AO5: 52 | AP5: 256115 | AQ5: 2.8 | AR5: 1598 | AS5: 653 | AT5: 50 | AU5: 34755 | AV5: 0.4 | AW5: 1724 | AX5: 2283 | AY5: 114 | AZ5: 277040 | BA5: 3.1
A6: data/Blackbutt Eucalyptus/BE- 35 (1).txt | B6: Blackbutt | C6: 35 | D6: 22.19 counts | E6: 0.992744 | F6: 1365 | G6: 19087 | H6: 200 | I6: 4063496 | J6: 48.4 | K6: 1.8348624 | L6: 1.447729 | M6: 221 | N6: 1586 | O6: 24191 | P6: 109 | Q6: 2806807 | R6: 33.4 | S6: 1073 | T6: 2013 | U6: 158 | V6: 338558 | W6: 4 | X6: 1192 | Y6: 4301 | Z6: 118 | AA6: 540236 | AB6: 6.4 | AC6: 1270 | AD6: 333 | AE6: 50 | AF6: 17723 | AG6: 0.2 | AH6: 1458 | AI6: 1551 | AJ6: 50 | AK6: 82549 | AL6: 1 | AM6: 1496 | AN6: 3151 | AO6: 50 | AP6: 167707 | AQ6: 2 | AR6: 1594 | AS6: 2263 | AT6: 50 | AU6: 120444 | AV6: 1.4 | AW6: 1728 | AX6: 2185 | AY6: 110 | AZ6: 255845 | BA6: 3
A7: data/Blackbutt Eucalyptus/BE- 35 (2).txt | B7: Blackbutt | C7: 35 | D7: 17.28 counts | E7: 0.99622 | F7: 1365 | G7: 19953 | H7: 200 | I7: 4247862 | J7: 46.3 | K7: 1.6806723 | L7: 1.2992311 | M7: 219 | N7: 1584 | O7: 25811 | P7: 119 | Q7: 3269520 | R7: 35.6 | S7: 1073 | T7: 2389 | U7: 174 | V7: 442484 | W7: 4.8 | X7: 1186 | Y7: 4145 | Z7: 114 | AA7: 502993 | AB7: 5.5 | AC7: 1256 | AD7: 843 | AE7: 50 | AF7: 44867 | AG7: 0.5 | AH7: 1456 | AI7: 1615 | AJ7: 50 | AK7: 85956 | AL7: 0.9 | AM7: 1488 | AN7: 2491 | AO7: 50 | AP7: 132579 | AQ7: 1.4 | AR7: 1594 | AS7: 3027 | AT7: 50 | AU7: 161107 | AV7: 1.8 | AW7: 1740 | AX7: 2395 | AY7: 114 | AZ7: 290631 | BA7: 3.2
A8: data/Blackbutt Eucalyptus/BE- 35 (3).txt | B8: Blackbutt | C8: 35 | D8: 19.46 counts | E8: 0.993667 | F8: 1365 | G8: 16225 | H8: 200 | I8: 3454196 | J8: 45.3 | K8: 1.980198 | L8: 1.2414974 | M8: 225 | N8: 1590 | O8: 25879 | P8: 101 | Q8: 2782282 | R8: 36.5 | S8: 1073 | T8: 1547 | U8: 152 | V8: 250303 | W8: 3.3 | X8: 1190 | Y8: 4203 | Z8: 112 | AA8: 501083 | AB8: 6.6 | AC8: 1258 | AD8: 601 | AE8: 50 | AF8: 31987 | AG8: 0.4 | AH8: 1458 | AI8: 2237 | AJ8: 56 | AK8: 133348 | AL8: 1.7 | AM8: 1500 | AN8: 3713 | AO8: 50 | AP8: 197618 | AQ8: 2.6 | AR8: 1592 | AS8: 447 | AT8: 50 | AU8: 23791 | AV8: 0.3 | AW8: 1730 | AX8: 1993 | AY8: 118 | AZ8: 250335 | BA8: 3.3
A9: data/Blackbutt Eucalyptus/BE- 35 (4).txt | B9: Blackbutt | C9: 35 | D9: 20.48 counts | E9: 0.993732 | F9: 1365 | G9: 18259 | H9: 200 | I9: 3887221 | J9: 46.8 | K9: 1.8348624 | L9: 1.3193698 | M9: 223 | N9: 1588 | O9: 25393 | P9: 109 | Q9: 2946271 | R9: 35.5 | S9: 1073 | T9: 1813 | U9: 148 | V9: 285622 | W9: 3.4 | X9: 1188 | Y9: 4483 | Z9: 114 | AA9: 544009 | AB9: 6.6 | AC9: 1262 | AD9: 681 | AE9: 50 | AF9: 36245 | AG9: 0.4 | AH9: 1458 | AI9: 1575 | AJ9: 54 | AK9: 90533 | AL9: 1.1 | AM9: 1492 | AN9: 3169 | AO9: 52 | AP9: 175411 | AQ9: 2.1 | AR9: 1592 | AS9: 1645 | AT9: 50 | AU9: 87552 | AV9: 1.1 | AW9: 1736 | AX9: 2135 | AY9: 110 | AZ9: 249990 | BA9: 3
A10: data/Blackbutt Eucalyptus/BE- 35 (5).txt | B10: Blackbutt | C10: 35 | D10: 19.93 counts | E10: 0.995322 | F10: 1367 | G10: 21267 | H10: 200 | I10: 4527604 | J10: 48.3 | K10: 1.8348624 | L10: 1.4366929 | M10: 221 | N10: 1588 | O10: 27161 | P10: 109 | Q10: 3151407 | R10: 33.6 | S10: 1073 | T10: 2311 | U10: 174 | V10: 428037 | W10: 4.6 | X10: 1196 | Y10: 4505 | Z10: 122 | AA10: 585042 | AB10: 6.2 | AC10: 1268 | AD10: 147 | AE10: 50 | AF10: 7824 | AG10: 0.1 | AH10: 1458 | AI10: 1627 | AJ10: 50 | AK10: 86594 | AL10: 0.9 | AM10: 1498 | AN10: 3649 | AO10: 50 | AP10: 194212 | AQ10: 2.1 | AR10: 1588 | AS10: 2109 | AT10: 50 | AU10: 112248 | AV10: 1.2 | AW10: 1732 | AX10: 2521 | AY10: 102 | AZ10: 273719 | BA10: 2.9
A11: data/Blackbutt Eucalyptus/BE- 50 (1).txt | B11: Blackbutt | C11: 50 | D11: 38.01 counts | E11: 0.996497 | F11: 1367 | G11: 44983 | H11: 200 | I11: 9576584 | J11: 46.5 | K11: 1.8348624 | L11: 1.3383972 | M11: 221 | N11: 1588 | O11: 61669 | P11: 109 | Q11: 7155263 | R11: 34.7 | S11: 1073 | T11: 4853 | U11: 178 | V11: 919523 | W11: 4.5 | X11: 1192 | Y11: 9999 | Z11: 120 | AA11: 1277233 | AB11: 6.2 | AC11: 1264 | AD11: 1583 | AE11: 50 | AF11: 84253 | AG11: 0.4 | AH11: 1458 | AI11: 4451 | AJ11: 50 | AK11: 236897 | AL11: 1.2 | AM11: 1498 | AN11: 8905 | AO11: 52 | AP11: 492912 | AQ11: 2.4 | AR11: 1586 | AS11: 3807 | AT11: 50 | AU11: 202621 | AV11: 1 | AW11: 1730 | AX11: 5797 | AY11: 106 | AZ11: 654096 | BA11: 3.2
A12: data/Blackbutt Eucalyptus/BE- 50 (2).txt | B12: Blackbutt | C12: 50 | D12: 36.10 counts | E12: 0.996335 | F12: 1365 | G12: 41725 | H12: 200 | I12: 8882977 | J12: 46 | K12: 1.8348624 | L12: 1.3177898 | M12: 223 | N12: 1588 | O12: 58097 | P12: 109 | Q12: 6740815 | R12: 34.9 | S12: 1073 | T12: 4701 | U12: 174 | V12: 870706 | W12: 4.5 | X12: 1188 | Y12: 9081 | Z12: 112 | AA12: 1082640 | AB12: 5.6 | AC12: 1260 | AD12: 1655 | AE12: 50 | AF12: 88085 | AG12: 0.5 | AH12: 1458 | AI12: 5201 | AJ12: 54 | AK12: 298960 | AL12: 1.5 | AM12: 1498 | AN12: 8167 | AO12: 50 | AP12: 434675 | AQ12: 2.3 | AR12: 1586 | AS12: 3335 | AT12: 50 | AU12: 177500 | AV12: 0.9 | AW12: 1728 | AX12: 6111 | AY12: 110 | AZ12: 715545 | BA12: 3.7
A13: data/Blackbutt Eucalyptus/BE- 50 (3).txt | B13: Blackbutt | C13: 50 | D13: 24.21 counts | E13: 0.996431 | F13: 1365 | G13: 28445 | H13: 200 | I13: 6055753 | J13: 46.6 | K13: 1.8348624 | L13: 1.3253931 | M13: 223 | N13: 1588 | O13: 39379 | P13: 109 | Q13: 4569024 | R13: 35.2 | S13: 1073 | T13: 3087 | U13: 180 | V13: 591482 | W13: 4.6 | X13: 1190 | Y13: 6047 | Z13: 116 | AA13: 746673 | AB13: 5.7 | AC13: 1262 | AD13: 645 | AE13: 50 | AF13: 34329 | AG13: 0.3 | AH13: 1458 | AI13: 3303 | AJ13: 50 | AK13: 175797 | AL13: 1.4 | AM13: 1498 | AN13: 5521 | AO13: 50 | AP13: 293846 | AQ13: 2.3 | AR13: 1590 | AS13: 2095 | AT13: 50 | AU13: 111503 | AV13: 0.9 | AW13: 1728 | AX13: 3735 | AY13: 104 | AZ13: 413482 | BA13: 3.2
... A15: data/Blackbutt Eucalyptus/BE- 50 (5).txt | B15: Blackbutt | C15: 50 | D15: 30.70 counts | E15: 0.993441 | F15: 1367 | G15: 27127 | H15: 200 | I15: 5775159 | J15: 47.2 | K15: 1.8018018 | L15: 1.3296013 | M15: 223 | N15: 1590 | O15: 36761 | P15: 111 | Q15: 4343527 | R15: 35.5 | S15: 1073 | T15: 2911 | U15: 172 | V15: 532970 | W15: 4.4 | X15: 1196 | Y15: 5953 | Z15: 118 | AA15: 747739 | AB15: 6.1 | AC15: 1270 | AD15: 337 | AE15: 50 | AF15: 17936 | AG15: 0.1 | AH15: 1458 | AI15: 2233 | AJ15: 50 | AK15: 118848 | AL15: 1 | AM15: 1498 | AN15: 5029 | AO15: 50 | AP15: 267660 | AQ15: 2.2 | AR15: 1586 | AS15: 1519 | AT15: 50 | AU15: 80846 | AV15: 0.7 | AW15: 1734 | AX15: 3085 | AY15: 106 | AZ15: 348091 | BA15: 2.8
A19: =2*SQRT(2*LN(2)) -> 2.35482 | B19: =MAX(B22:B919) -> 36426.681 | C19: =MAX(C22:C919) -> 48844.324 | D19: =MAX(D22:D919) -> 3660.9887 | E19: =MAX(E22:E919) -> 7865.0001 | F19: =MAX(F22:F919) -> 1536.8088 | G19: =MAX(G22:G919) -> 1818.5254 | H19: =MAX(H22:H919) -> 5743.3034 | I19: =MAX(I22:I919) -> 2700.9254 | ... L19: =MAX(L22:L919) -> 52526.247
A21: =A2 -> data/Blackbutt Eucalyptus/BE- 25 (2).txt | B21: D | C21: G_G | D21: S_L | E21: S | F21: D_S | G21: A_1 | H21: A_2 | I21: G_L | J21: C | K21: TOTAL | L21: Chris | M21: diff
A22: 900.27148 | B22: =$I$2*_xlfn.NORM.DIST($A22,$F$2,$H$2/$A$19,0) -> 0.01148155 | C22: =$Q$2*_xlfn.NORM.DIST($A22,$N$2,$P$2/$A$19,0) -> 2.9231264e-42 | D22: =$V$2*_xlfn.NORM.DIST($A22,$S$2,$U$2/$A$19,0) -> 181.92296 | E22: =$AA$2*_xlfn.NORM.DIST($A22,$X$2,$Z$2/$A$19,0) -> 8.8872267e-05 | F22: =$AF$2*_xlfn.NORM.DIST($A22,$AC$2,$AE$2/$A$19,0) -> 2.9200979e-61 | G22: =$AK$2*_xlfn.NORM.DIST($A22,$AH$2,$AJ$2/$A$19,0) -> 2.7408048e-147 | H22: =$AP$2*_xlfn.NORM.DIST($A22,$AM$2,$AO$2/$A$19,0) -> 1.2995458e-165 | I22: =$AU$2*_xlfn.NORM.DIST($A22,$AR$2,$AT$2/$A$19,0) -> 9.3019751e-228 | J22: =$AZ$2*_xlfn.NORM.DIST($A22,$AW$2,$AY$2/$A$19,0) -> 8.5419347e-81 | K22: =SUM(B22:J22) -> 181.93453 | L22: 66.808167 | M22: =K22-L22 -> 115.12636
A23: 901.60938 | B23: =$I$2*_xlfn.NORM.DIST($A23,$F$2,$H$2/$A$19,0) -> 0.012513537 | C23: =$Q$2*_xlfn.NORM.DIST($A23,$N$2,$P$2/$A$19,0) -> 4.4209424e-42 | D23: =$V$2*_xlfn.NORM.DIST($A23,$S$2,$U$2/$A$19,0) -> 190.54846 | E23: =$AA$2*_xlfn.NORM.DIST($A23,$X$2,$Z$2/$A$19,0) -> 0.00010531697 | F23: =$AF$2*_xlfn.NORM.DIST($A23,$AC$2,$AE$2/$A$19,0) -> 8.576363e-61 | G23: =$AK$2*_xlfn.NORM.DIST($A23,$AH$2,$AJ$2/$A$19,0) -> 1.4315553e-146 | H23: =$AP$2*_xlfn.NORM.DIST($A23,$AM$2,$AO$2/$A$19,0) -> 7.5082775e-165 | I23: =$AU$2*_xlfn.NORM.DIST($A23,$AR$2,$AT$2/$A$19,0) -> 7.2310673e-227 | J23: =$AZ$2*_xlfn.NORM.DIST($A23,$AW$2,$AY$2/$A$19,0) -> 1.5847652e-80 | K23: =SUM(B23:J23) -> 190.56108 | L23: 70.931419 | M23: =K23-L23 -> 119.62966
A24: 902.94531 | B24: =$I$2*_xlfn.NORM.DIST($A24,$F$2,$H$2/$A$19,0) -> 0.013633192 | C24: =$Q$2*_xlfn.NORM.DIST($A24,$N$2,$P$2/$A$19,0) -> 6.6768365e-42 | D24: =$V$2*_xlfn.NORM.DIST($A24,$S$2,$U$2/$A$19,0) -> 199.4977 | E24: =$AA$2*_xlfn.NORM.DIST($A24,$X$2,$Z$2/$A$19,0) -> 0.00012467515 | F24: =$AF$2*_xlfn.NORM.DIST($A24,$AC$2,$AE$2/$A$19,0) -> 2.5049865e-60 | G24: =$AK$2*_xlfn.NORM.DIST($A24,$AH$2,$AJ$2/$A$19,0) -> 7.4296728e-146 | H24: =$AP$2*_xlfn.NORM.DIST($A24,$AM$2,$AO$2/$A$19,0) -> 4.3097948e-164 | I24: =$AU$2*_xlfn.NORM.DIST($A24,$AR$2,$AT$2/$A$19,0) -> 5.582247e-226 | J24: =$AZ$2*_xlfn.NORM.DIST($A24,$AW$2,$AY$2/$A$19,0) -> 2.9346186e-80 | K24: =SUM(B24:J24) -> 199.51146 | L24: 75.267606 | M24: =K24-L24 -> 124.24386
A25: 904.28125 | B25: =$I$2*_xlfn.NORM.DIST($A25,$F$2,$H$2/$A$19,0) -> 0.014849353 | C25: =$Q$2*_xlfn.NORM.DIST($A25,$N$2,$P$2/$A$19,0) -> 1.0075756e-41 | D25: =$V$2*_xlfn.NORM.DIST($A25,$S$2,$U$2/$A$19,0) -> 208.79225 | E25: =$AA$2*_xlfn.NORM.DIST($A25,$X$2,$Z$2/$A$19,0) -> 0.00014747512 | F25: =$AF$2*_xlfn.NORM.DIST($A25,$AC$2,$AE$2/$A$19,0) -> 7.287659e-60 | G25: =$AK$2*_xlfn.NORM.DIST($A25,$AH$2,$AJ$2/$A$19,0) -> 3.8407097e-145 | H25: =$AP$2*_xlfn.NORM.DIST($A25,$AM$2,$AO$2/$A$19,0) -> 2.4640702e-163 | I25: =$AU$2*_xlfn.NORM.DIST($A25,$AR$2,$AT$2/$A$19,0) -> 4.2923568e-225 | J25: =$AZ$2*_xlfn.NORM.DIST($A25,$AW$2,$AY$2/$A$19,0) -> 5.428857e-80 | K25: =SUM(B25:J25) -> 208.80725 | L25: 79.831818 | M25: =K25-L25 -> 128.97543
A26: 905.61914 | B26: =$I$2*_xlfn.NORM.DIST($A26,$F$2,$H$2/$A$19,0) -> 0.016172014 | C26: =$Q$2*_xlfn.NORM.DIST($A26,$N$2,$P$2/$A$19,0) -> 1.5201847e-41 | D26: =$V$2*_xlfn.NORM.DIST($A26,$S$2,$U$2/$A$19,0) -> 218.45574 | E26: =$AA$2*_xlfn.NORM.DIST($A26,$X$2,$Z$2/$A$19,0) -> 0.00017434959 | F26: =$AF$2*_xlfn.NORM.DIST($A26,$AC$2,$AE$2/$A$19,0) -> 2.1150764e-59 | G26: =$AK$2*_xlfn.NORM.DIST($A26,$AH$2,$AJ$2/$A$19,0) -> 1.9823201e-144 | H26: =$AP$2*_xlfn.NORM.DIST($A26,$AM$2,$AO$2/$A$19,0) -> 1.4068056e-162 | I26: =$AU$2*_xlfn.NORM.DIST($A26,$AR$2,$AT$2/$A$19,0) -> 3.2972761e-224 | J26: =$AZ$2*_xlfn.NORM.DIST($A26,$AW$2,$AY$2/$A$19,0) -> 1.0042114e-79 | K26: =SUM(B26:J26) -> 218.47209 | L26: 84.640727 | M26: =K26-L26 -> 133.83136
A27: 906.95508 | B27: =$I$2*_xlfn.NORM.DIST($A27,$F$2,$H$2/$A$19,0) -> 0.017605933 | C27: =$Q$2*_xlfn.NORM.DIST($A27,$N$2,$P$2/$A$19,0) -> 2.290367e-41 | D27: =$V$2*_xlfn.NORM.DIST($A27,$S$2,$U$2/$A$19,0) -> 228.46925 | E27: =$AA$2*_xlfn.NORM.DIST($A27,$X$2,$Z$2/$A$19,0) -> 0.00020590837 | F27: =$AF$2*_xlfn.NORM.DIST($A27,$AC$2,$AE$2/$A$19,0) -> 6.1047483e-59 | G27: =$AK$2*_xlfn.NORM.DIST($A27,$AH$2,$AJ$2/$A$19,0) -> 1.0166574e-143 | H27: =$AP$2*_xlfn.NORM.DIST($A27,$AM$2,$AO$2/$A$19,0) -> 7.9797559e-162 | I27: =$AU$2*_xlfn.NORM.DIST($A27,$AR$2,$AT$2/$A$19,0) -> 2.5153656e-223 | J27: =$AZ$2*_xlfn.NORM.DIST($A27,$AW$2,$AY$2/$A$19,0) -> 1.8540509e-79 | K27: =SUM(B27:J27) -> 228.48707 | L27: 89.689994 | M27: =K27-L27 -> 138.79707
A28: 908.29102 | B28: =$I$2*_xlfn.NORM.DIST($A28,$F$2,$H$2/$A$19,0) -> 0.019162252 | C28: =$Q$2*_xlfn.NORM.DIST($A28,$N$2,$P$2/$A$19,0) -> 3.4479828e-41 | D28: =$V$2*_xlfn.NORM.DIST($A28,$S$2,$U$2/$A$19,0) -> 238.85597 | E28: =$AA$2*_xlfn.NORM.DIST($A28,$X$2,$Z$2/$A$19,0) -> 0.00024298782 | F28: =$AF$2*_xlfn.NORM.DIST($A28,$AC$2,$AE$2/$A$19,0) -> 1.7550544e-58 | G28: =$AK$2*_xlfn.NORM.DIST($A28,$AH$2,$AJ$2/$A$19,0) -> 5.1934598e-143 | H28: =$AP$2*_xlfn.NORM.DIST($A28,$AM$2,$AO$2/$A$19,0) -> 4.5084419e-161 | I28: =$AU$2*_xlfn.NORM.DIST($A28,$AR$2,$AT$2/$A$19,0) -> 1.9112978e-222 | J28: =$AZ$2*_xlfn.NORM.DIST($A28,$AW$2,$AY$2/$A$19,0) -> 3.4197042e-79 | K28: =SUM(B28:J28) -> 238.87537 | L28: 94.996396 | M28: =K28-L28 -> 143.87898
A29: 909.62695 | B29: =$I$2*_xlfn.NORM.DIST($A29,$F$2,$H$2/$A$19,0) -> 0.020850985 | C29: =$Q$2*_xlfn.NORM.DIST($A29,$N$2,$P$2/$A$19,0) -> 5.1865209e-41 | D29: =$V$2*_xlfn.NORM.DIST($A29,$S$2,$U$2/$A$19,0) -> 249.62521 | E29: =$AA$2*_xlfn.NORM.DIST($A29,$X$2,$Z$2/$A$19,0) -> 0.00028651827 | F29: =$AF$2*_xlfn.NORM.DIST($A29,$AC$2,$AE$2/$A$19,0) -> 5.0256686e-58 | G29: =$AK$2*_xlfn.NORM.DIST($A29,$AH$2,$AJ$2/$A$19,0) -> 2.6425254e-142 | H29: =$AP$2*_xlfn.NORM.DIST($A29,$AM$2,$AO$2/$A$19,0) -> 2.5371349e-160 | I29: =$AU$2*_xlfn.NORM.DIST($A29,$AR$2,$AT$2/$A$19,0) -> 1.4465576e-221 | J29: =$AZ$2*_xlfn.NORM.DIST($A29,$AW$2,$AY$2/$A$19,0) -> 6.3012314e-79 | K29: =SUM(B29:J29) -> 249.64635 | L29: 100.57007 | M29: =K29-L29 -> 149.07628
A30: 910.96094 | B30: =$I$2*_xlfn.NORM.DIST($A30,$F$2,$H$2/$A$19,0) -> 0.022680143 | C30: =$Q$2*_xlfn.NORM.DIST($A30,$N$2,$P$2/$A$19,0) -> 7.7907635e-41 | D30: =$V$2*_xlfn.NORM.DIST($A30,$S$2,$U$2/$A$19,0) -> 260.76973 | E30: =$AA$2*_xlfn.NORM.DIST($A30,$X$2,$Z$2/$A$19,0) -> 0.00033749992 | F30: =$AF$2*_xlfn.NORM.DIST($A30,$AC$2,$AE$2/$A$19,0) -> 1.4312452e-57 | G30: =$AK$2*_xlfn.NORM.DIST($A30,$AH$2,$AJ$2/$A$19,0) -> 1.3360838e-141 | H30: =$AP$2*_xlfn.NORM.DIST($A30,$AM$2,$AO$2/$A$19,0) -> 1.4185638e-159 | I30: =$AU$2*_xlfn.NORM.DIST($A30,$AR$2,$AT$2/$A$19,0) -> 1.0872847e-220 | J30: =$AZ$2*_xlfn.NORM.DIST($A30,$AW$2,$AY$2/$A$19,0) -> 1.1588991e-78 | K30: =SUM(B30:J30) -> 260.79275 | L30: 106.41263 | M30: =K30-L30 -> 154.38011
A31: 912.29688 | B31: =$I$2*_xlfn.NORM.DIST($A31,$F$2,$H$2/$A$19,0) -> 0.024666702 | C31: =$Q$2*_xlfn.NORM.DIST($A31,$N$2,$P$2/$A$19,0) -> 1.1700216e-40 | D31: =$V$2*_xlfn.NORM.DIST($A31,$S$2,$U$2/$A$19,0) -> 272.33145 | E31: =$AA$2*_xlfn.NORM.DIST($A31,$X$2,$Z$2/$A$19,0) -> 0.0003973349 | F31: =$AF$2*_xlfn.NORM.DIST($A31,$AC$2,$AE$2/$A$19,0) -> 4.0661311e-57 | G31: =$AK$2*_xlfn.NORM.DIST($A31,$AH$2,$AJ$2/$A$19,0) -> 6.7446617e-141 | H31: =$AP$2*_xlfn.NORM.DIST($A31,$AM$2,$AO$2/$A$19,0) -> 7.9200884e-159 | I31: =$AU$2*_xlfn.NORM.DIST($A31,$AR$2,$AT$2/$A$19,0) -> 8.16422e-220 | J31: =$AZ$2*_xlfn.NORM.DIST($A31,$AW$2,$AY$2/$A$19,0) -> 2.1311966e-78 | K31: =SUM(B31:J31) -> 272.35652 | L31: 112.55173 | M31: =K31-L31 -> 159.80478
A32: 913.63086 | B32: =$I$2*_xlfn.NORM.DIST($A32,$F$2,$H$2/$A$19,0) -> 0.026817349 | C32: =$Q$2*_xlfn.NORM.DIST($A32,$N$2,$P$2/$A$19,0) -> 1.7546945e-40 | D32: =$V$2*_xlfn.NORM.DIST($A32,$S$2,$U$2/$A$19,0) -> 284.28585 | E32: =$AA$2*_xlfn.NORM.DIST($A32,$X$2,$Z$2/$A$19,0) -> 0.00046729834 | F32: =$AF$2*_xlfn.NORM.DIST($A32,$AC$2,$AE$2/$A$19,0) -> 1.1488685e-56 | G32: =$AK$2*_xlfn.NORM.DIST($A32,$AH$2,$AJ$2/$A$19,0) -> 3.3833216e-140 | H32: =$AP$2*_xlfn.NORM.DIST($A32,$AM$2,$AO$2/$A$19,0) -> 4.3934316e-158 | I32: =$AU$2*_xlfn.NORM.DIST($A32,$AR$2,$AT$2/$A$19,0) -> 6.0882249e-219 | J32: =$AZ$2*_xlfn.NORM.DIST($A32,$AW$2,$AY$2/$A$19,0) -> 3.9118822e-78 | K32: =SUM(B32:J32) -> 284.31314 | L32: 118.98016 | M32: =K32-L32 -> 165.33297
A33: 914.9668 | B33: =$I$2*_xlfn.NORM.DIST($A33,$F$2,$H$2/$A$19,0) -> 0.029151869 | C33: =$Q$2*_xlfn.NORM.DIST($A33,$N$2,$P$2/$A$19,0) -> 2.6309848e-40 | D33: =$V$2*_xlfn.NORM.DIST($A33,$S$2,$U$2/$A$19,0) -> 296.6772 | E33: =$AA$2*_xlfn.NORM.DIST($A33,$X$2,$Z$2/$A$19,0) -> 0.00054927843 | F33: =$AF$2*_xlfn.NORM.DIST($A33,$AC$2,$AE$2/$A$19,0) -> 3.238188e-56 | G33: =$AK$2*_xlfn.NORM.DIST($A33,$AH$2,$AJ$2/$A$19,0) -> 1.6944718e-139 | H33: =$AP$2*_xlfn.NORM.DIST($A33,$AM$2,$AO$2/$A$19,0) -> 2.4336026e-157 | I33: =$AU$2*_xlfn.NORM.DIST($A33,$AR$2,$AT$2/$A$19,0) -> 4.5355174e-218 | J33: =$AZ$2*_xlfn.NORM.DIST($A33,$AW$2,$AY$2/$A$19,0) -> 7.1796768e-78 | K33: =SUM(B33:J33) -> 296.7069 | L33: 125.72771 | M33: =K33-L33 -> 170.97919
... A919: 1999.1406 | B919: =$I$2*_xlfn.NORM.DIST($A919,$F$2,$H$2/$A$19,0) -> 2.857418e-08 | C919: =$Q$2*_xlfn.NORM.DIST($A919,$N$2,$P$2/$A$19,0) -> 1.4758002e-12 | D919: =$V$2*_xlfn.NORM.DIST($A919,$S$2,$U$2/$A$19,0) -> 1.2103749e-34 | E919: =$AA$2*_xlfn.NORM.DIST($A919,$X$2,$Z$2/$A$19,0) -> 5.4706611e-60 | F919: =$AF$2*_xlfn.NORM.DIST($A919,$AC$2,$AE$2/$A$19,0) -> 7.7412319e-258 | G919: =$AK$2*_xlfn.NORM.DIST($A919,$AH$2,$AJ$2/$A$19,0) -> 1.649377e-138 | H919: =$AP$2*_xlfn.NORM.DIST($A919,$AM$2,$AO$2/$A$19,0) -> 7.6465465e-121 | I919: =$AU$2*_xlfn.NORM.DIST($A919,$AR$2,$AT$2/$A$19,0) -> 3.9072589e-77 | J919: =$AZ$2*_xlfn.NORM.DIST($A919,$AW$2,$AY$2/$A$19,0) -> 1.463581e-05 | K919: =SUM(B919:J919) -> 1.4664386e-05 | L919: 3.1e-05 | M919: =K919-L919 -> -1.6335614e-05

Sheet GreyIronbark
A1: File | B1: Vegetation | C1: Thermal Energy | D1: Std Err | E1: R_sqrd | F1: D pos | G1: D ht | H1: D fwhm | I1: D area | J1: D %area | K1: D fwhm/G fwhm | L1: AD/AG | M1: R1= D ht/ G ht | N1: RBS ( Band sepration ) | O1: G_G pos | P1: G_G ht | Q1: G_G fwhm | R1: G_G area | S1: G_G %area | T1: S_L pos | U1: S_L ht | V1: S_L fwhm | W1: S_L area | X1: S_L %area | Y1: S pos | Z1: S ht | AA1: S fwhm | AB1: S area | AC1: S %area | AD1: D_S pos | AE1: D_S ht | AF1: D_S fwhm | AG1: D_S area | AH1: D_S %area | AI1: A_1 pos | AJ1: A_1 ht | AK1: A_1 fwhm | AL1: A_1 area | AM1: A_1 %area | AN1: A_2 pos | AO1: A_2 ht | AP1: A_2 fwhm | AQ1: A_2 area | AR1: A_2 %area | AS1: G_L pos | AT1: G_L ht | AU1: G_L fwhm | AV1: G_L area | AW1: G_L %area | AX1: C pos | AY1: C ht | AZ1: C fwhm | BA1: C area | BB1: C %area
A2: data/Grey Ironback/GI-25 (1) | B2: Grey Ironback | C2: 25 kW/m2 | D2: 28.41 | E2: 0.995729 | F2: 1367 | G2: 29083 | H2: 200 | I2: 6191579 | J2: 44.5 | K2: 1.6806723 | L2: 1.1652004 | M2: 0.69329424 | N2: 219 | O2: 1586 | P2: 41949 | Q2: 119 | R2: 5313746 | S2: 38.2 | T2: 1073 | U2: 3523 | V2: 194 | W2: 727523 | X2: 5.2 | Y2: 1190 | Z2: 5439 | AA2: 114 | AB2: 660019 | AC2: 4.7 | AD2: 1260 | AE2: 915 | AF2: 50 | AG2: 48699 | AH2: 0.4 | AI2: 1456 | AJ2: 2935 | AK2: 58 | AL2: 181204 | AM2: 1.3 | AN2: 1490 | AO2: 3747 | AP2: 50 | AQ2: 199428 | AR2: 1.4 | AS2: 1594 | AT2: 3167 | AU2: 50 | AV2: 168558 | AW2: 1.2 | AX2: 1744 | AY2: 3833 | AZ2: 102 | BA2: 416170 | BB2: 3
A3: data/Grey Ironback/GI-25 (2) | B3: Grey Ironback | C3: 25 kW/m2 | D3: 30.58 | E3: 0.995298 | F3: 1365 | G3: 29669 | H3: 200 | I3: 6316335 | J3: 44.9 | K3: 1.6806723 | L3: 1.1597057 | M3: 0.69002489 | N3: 221 | O3: 1586 | P3: 42997 | Q3: 119 | R3: 5446498 | S3: 38.7 | T3: 1073 | U3: 3199 | V3: 174 | W3: 592510 | X3: 4.2 | Y3: 1188 | Z3: 5465 | AA3: 114 | AB3: 663174 | AC3: 4.7 | AD3: 1256 | AE3: 271 | AF3: 50 | AG3: 14424 | AH3: 0.1 | AI3: 1454 | AJ3: 3553 | AK3: 54 | AL3: 204231 | AM3: 1.5 | AN3: 1490 | AO3: 3763 | AP3: 50 | AQ3: 200279 | AR3: 1.4 | AS3: 1596 | AT3: 3643 | AU3: 50 | AV3: 193893 | AW3: 1.4 | AX3: 1742 | AY3: 4073 | AZ3: 100 | BA3: 433557 | BB3: 3.1
A4: data/Grey Ironback/GI-25 (3) | B4: Grey Ironback | C4: 25 kW/m2 | D4: 31.85 | E4: 0.994884 | F4: 1365 | G4: 29695 | H4: 200 | I4: 6321870 | J4: 44.1 | K4: 1.6528926 | L4: 1.1327898 | M4: 0.68533776 | N4: 221 | O4: 1586 | P4: 43329 | Q4: 121 | R4: 5580797 | S4: 39 | T4: 1073 | U4: 3383 | V4: 172 | W4: 619388 | X4: 4.3 | Y4: 1184 | Z4: 5623 | AA4: 112 | AB4: 670376 | AC4: 4.7 | AD4: 1250 | AE4: 799 | AF4: 50 | AG4: 42525 | AH4: 0.3 | AI4: 1448 | AJ4: 3571 | AK4: 56 | AL4: 212868 | AM4: 1.5 | AN4: 1488 | AO4: 4037 | AP4: 50 | AQ4: 214863 | AR4: 1.5 | AS4: 1596 | AT4: 3257 | AU4: 50 | AV4: 173348 | AW4: 1.2 | AX4: 1748 | AY4: 4203 | AZ4: 108 | BA4: 483187 | BB4: 3.4
A5: data/Grey Ironback/GI-25 (4) | B5: Grey Ironback | C5: 25 kW/m2 | D5: 25.95 | E5: 0.994823 | F5: 1365 | G5: 23921 | H5: 200 | I5: 5092623 | J5: 44.4 | K5: 1.6806723 | L5: 1.1447101 | M5: 0.68110247 | N5: 221 | O5: 1586 | P5: 35121 | Q5: 119 | R5: 4448832 | S5: 38.8 | T5: 1073 | U5: 2653 | V5: 184 | W5: 519622 | X5: 4.5 | Y5: 1190 | Z5: 4231 | AA5: 112 | AB5: 504421 | AC5: 4.4 | AD5: 1258 | AE5: 1 | AF5: 50 | AG5: 53 | AH5: 0 | AI5: 1450 | AJ5: 3053 | AK5: 52 | AL5: 168991 | AM5: 1.5 | AN5: 1490 | AO5: 3327 | AP5: 50 | AQ5: 177074 | AR5: 1.5 | AS5: 1598 | AT5: 3235 | AU5: 50 | AV5: 172178 | AW5: 1.5 | AX5: 1738 | AY5: 3595 | AZ5: 100 | BA5: 382676 | BB5: 3.3
A6: data/Grey Ironback/GI-25 (5) | B6: Grey Ironback | C6: 25 kW/m2 | D6: 26.55 | E6: 0.995509 | F6: 1365 | G6: 26555 | H6: 200 | I6: 5653384 | J6: 44.7 | K6: 1.6806723 | L6: 1.1656154 | M6: 0.69354123 | N6: 221 | O6: 1586 | P6: 38289 | Q6: 119 | R6: 4850128 | S6: 38.3 | T6: 1073 | U6: 2937 | V6: 172 | W6: 537730 | X6: 4.3 | Y6: 1182 | Z6: 4799 | AA6: 110 | AB6: 561922 | AC6: 4.4 | AD6: 1250 | AE6: 773 | AF6: 50 | AG6: 41142 | AH6: 0.3 | AI6: 1452 | AJ6: 3147 | AK6: 54 | AL6: 180893 | AM6: 1.4 | AN6: 1490 | AO6: 3315 | AP6: 50 | AQ6: 176435 | AR6: 1.4 | AS6: 1598 | AT6: 3891 | AU6: 50 | AV6: 207092 | AW6: 1.6 | AX6: 1748 | AY6: 3519 | AZ6: 118 | BA6: 442011 | BB6: 3.5
A7: data/Grey Ironback/GI-35 (1) | B7: Grey Ironback | C7: 35 kW/m2 | D7: 2.36 | E7: 0.962196 | F7: 1365 | G7: 843 | H7: 200 | I7: 179469 | J7: 46.4 | K7: 2.1978022 | L7: 1.4004167 | M7: 0.63718821 | N7: 223 | O7: 1588 | P7: 1323 | Q7: 91 | R7: 128154 | S7: 33.1 | T7: 1073 | U7: 43 | V7: 170 | W7: 7781 | X7: 2 | Y7: 1192 | Z7: 193 | AA7: 100 | AB7: 20544 | AC7: 5.3 | AD7: 1258 | AE7: 7 | AF7: 50 | AG7: 373 | AH7: 0.1 | AI7: 1454 | AJ7: 145 | AK7: 52 | AL7: 8026 | AM7: 2.1 | AN7: 1500 | AO7: 195 | AP7: 50 | AQ7: 10379 | AR7: 2.7 | AS7: 1598 | AT7: 57 | AU7: 50 | AV7: 3034 | AW7: 0.8 | AX7: 1748 | AY7: 137 | AZ7: 198 | BA7: 28875 | BB7: 7.5
A8: data/Grey Ironback/GI-35 (2) | B8: Grey Ironback | C8: 35 kW/m2 | D8: 10.83 | E8: 0.995348 | F8: 1365 | G8: 10005 | H8: 200 | I8: 2129999 | J8: 45.6 | K8: 2.1505376 | L8: 1.2245251 | M8: 0.56940413 | N8: 227 | O8: 1592 | P8: 17571 | Q8: 93 | R8: 1739449 | S8: 37.3 | T8: 1073 | U8: 773 | V8: 152 | W8: 125071 | X8: 2.7 | Y8: 1186 | Z8: 2383 | AA8: 104 | AB8: 263809 | AC8: 5.7 | AD8: 1252 | AE8: 507 | AF8: 50 | AG8: 26984 | AH8: 0.6 | AI8: 1458 | AJ8: 1651 | AK8: 58 | AL8: 101931 | AM8: 2.2 | AN8: 1504 | AO8: 2485 | AP8: 50 | AQ8: 132260 | AR8: 2.8 | AS8: 1598 | AT8: 267 | AU8: 50 | AV8: 14211 | AW8: 0.3 | AX8: 1720 | AY8: 1137 | AZ8: 110 | BA8: 133133 | BB8: 2.9
A9: data/Grey Ironback/GI-35 (3) | B9: Grey Ironback | C9: 35 kW/m2 | D9: 10.09 | E9: 0.994607 | F9: 1365 | G9: 8629 | H9: 200 | I9: 1837057 | J9: 44.7 | K9: 2.1505376 | L9: 1.2083731 | M9: 0.5618936 | N9: 227 | O9: 1592 | P9: 15357 | Q9: 93 | R9: 1520273 | S9: 37 | T9: 1073 | U9: 633 | V9: 148 | W9: 99724 | X9: 2.4 | Y9: 1188 | Z9: 2127 | AA9: 108 | AB9: 244525 | AC9: 5.9 | AD9: 1254 | AE9: 297 | AF9: 50 | AG9: 15807 | AH9: 0.4 | AI9: 1454 | AJ9: 1447 | AK9: 58 | AL9: 89336 | AM9: 2.2 | AN9: 1502 | AO9: 2397 | AP9: 54 | AQ9: 137782 | AR9: 3.3 | AS9: 1598 | AT9: 149 | AU9: 50 | AV9: 7930 | AW9: 0.2 | AX9: 1722 | AY9: 1051 | AZ9: 144 | BA9: 161101 | BB9: 3.9
A10: data/Grey Ironback/GI-35 (4) | B10: Grey Ironback | C10: 35 kW/m2 | D10: 7.74 | E10: 0.975058 | F10: 1367 | G10: 3051 | H10: 200 | I10: 649538 | J10: 45.3 | K10: 2.2988506 | L10: 1.2354762 | M10: 0.53743174 | N10: 225 | O10: 1592 | P10: 5677 | Q10: 87 | R10: 525739 | S10: 36.7 | T10: 1073 | U10: 213 | V10: 160 | W10: 36277 | X10: 2.5 | Y10: 1194 | Z10: 751 | AA10: 114 | AB10: 91133 | AC10: 6.4 | AD10: 1260 | AE10: 39 | AF10: 50 | AG10: 2076 | AH10: 0.1 | AI10: 1452 | AJ10: 493 | AK10: 50 | AL10: 26239 | AM10: 1.8 | AN10: 1504 | AO10: 967 | AP10: 52 | AQ10: 53526 | AR10: 3.7 | AS10: 1598 | AT10: 1 | AU10: 50 | AV10: 53 | AW10: 0 | AX10: 1726 | AY10: 333 | AZ10: 136 | BA10: 48208 | BB10: 3.4
A11: data/Grey Ironback/GI-35 (5) | B11: Grey Ironback | C11: 35 kW/m2 | D11: 13.06 | E11: 0.993268 | F11: 1365 | G11: 9921 | H11: 200 | I11: 2112116 | J11: 44.9 | K11: 2.1505376 | L11: 1.2117615 | M11: 0.56346907 | N11: 227 | O11: 1592 | P11: 17607 | Q11: 93 | R11: 1743013 | S11: 37 | T11: 1073 | U11: 753 | V11: 154 | W11: 123438 | X11: 2.6 | Y11: 1190 | Z11: 2437 | AA11: 110 | AB11: 285352 | AC11: 6.1 | AD11: 1256 | AE11: 277 | AF11: 50 | AG11: 14743 | AH11: 0.3 | AI11: 1458 | AJ11: 1599 | AK11: 64 | AL11: 108933 | AM11: 2.3 | AN11: 1504 | AO11: 2711 | AP11: 52 | AQ11: 150060 | AR11: 3.2 | AS11: 1598 | AT11: 229 | AU11: 50 | AV11: 12188 | AW11: 0.3 | AX11: 1720 | AY11: 1257 | AZ11: 118 | BA11: 157888 | BB11: 3.4
A12: data/Grey Ironback/GI-50 (1) | B12: Grey Ironback | C12: 50 kW/m2 | D12: 41.22 | E12: 0.99056 | F12: 1365 | G12: 29733 | H12: 200 | I12: 6329960 | J12: 51.5 | K12: 2.4096386 | L12: 1.5480604 | M12: 0.64244506 | N12: 229 | O12: 1594 | P12: 46281 | Q12: 83 | R12: 4088962 | S12: 33.3 | T12: 1073 | U12: 1383 | V12: 110 | W12: 161937 | X12: 1.3 | Y12: 1188 | Z12: 7955 | AA12: 110 | AB12: 931462 | AC12: 7.6 | AD12: 1256 | AE12: 1149 | AF12: 50 | AG12: 61154 | AH12: 0.5 | AI12: 1458 | AJ12: 1165 | AK12: 50 | AL12: 62005 | AM12: 0.5 | AN12: 1502 | AO12: 7355 | AP12: 52 | AQ12: 407116 | AR12: 3.3 | AS12: 1598 | AT12: 1 | AU12: 50 | AV12: 53 | AW12: 0 | AX12: 1712 | AY12: 2095 | AZ12: 112 | BA12: 249767 | BB12: 2
A13: data/Grey Ironback/GI-50 (2) | B13: Grey Ironback | C13: 50 kW/m2 | D13: 62.38 | E13: 0.989439 | F13: 1365 | G13: 44065 | H13: 200 | I13: 9381148 | J13: 48.8 | K13: 2.020202 | L13: 1.4590844 | M13: 0.72224681 | N13: 225 | O13: 1590 | P13: 61011 | Q13: 99 | R13: 6429476 | S13: 33.5 | T13: 1073 | U13: 3541 | V13: 188 | W13: 708624 | X13: 3.7 | Y13: 1190 | Z13: 9999 | AA13: 118 | AB13: 1255945 | AC13: 6.5 | AD13: 1252 | AE13: 2145 | AF13: 52 | AG13: 118731 | AH13: 0.6 | AI13: 1458 | AJ13: 3147 | AK13: 50 | AL13: 167494 | AM13: 0.9 | AN13: 1498 | AO13: 8475 | AP13: 50 | AQ13: 451068 | AR13: 2.3 | AS13: 1588 | AT13: 3163 | AU13: 50 | AV13: 168345 | AW13: 0.9 | AX13: 1732 | AY13: 4281 | AZ13: 116 | BA13: 528610 | BB13: 2.8
... A16: data/Grey Ironback/GI-50 (5) | B16: Grey Ironback | C16: 50 kW/m2 | D16: 28.99 | E16: 0.992236 | F16: 1365 | G16: 23593 | H16: 200 | I16: 5022794 | J16: 49.4 | K16: 2.1505376 | L16: 1.4647545 | M16: 0.68111089 | N16: 225 | O16: 1590 | P16: 34639 | Q16: 93 | R16: 3429103 | S16: 33.7 | T16: 1073 | U16: 1521 | V16: 122 | W16: 197525 | X16: 1.9 | Y16: 1186 | Z16: 6233 | AA16: 114 | AB16: 756370 | AC16: 7.4 | AD16: 1260 | AE16: 1037 | AF16: 50 | AG16: 55193 | AH16: 0.5 | AI16: 1458 | AJ16: 895 | AK16: 50 | AL16: 47635 | AM16: 0.5 | AN16: 1500 | AO16: 5701 | AP16: 54 | AQ16: 327700 | AR16: 3.2 | AS16: 1596 | AT16: 453 | AU16: 50 | AV16: 24110 | AW16: 0.2 | AX16: 1722 | AY16: 2323 | AZ16: 122 | BA16: 301676 | BB16: 3

Sheet SilvertopAsh
A1: File | B1: Vegetation | C1: Thermal Energy | D1: Std Err | E1: R_sqrd | F1: D pos | G1: D ht | H1: D fwhm | I1: D area | J1: D %area | K1: Dfwhm/ Gfwhm | L1: AD/AG | M1: R1= Dht/G ht | N1: RBS | O1: G_G pos | P1: G_G ht | Q1: G_G fwhm | R1: G_G area | S1: G_G %area | T1: S_L pos | U1: S_L ht | V1: S_L fwhm | W1: S_L area | X1: S_L %area | Y1: S pos | Z1: S ht | AA1: S fwhm | AB1: S area | AC1: S %area | AD1: D_S pos | AE1: D_S ht | AF1: D_S fwhm | AG1: D_S area | AH1: D_S %area | AI1: A_1 pos | AJ1: A_1 ht | AK1: A_1 fwhm | AL1: A_1 area | AM1: A_1 %area | AN1: A_2 pos | AO1: A_2 ht | AP1: A_2 fwhm | AQ1: A_2 area | AR1: A_2 %area | AS1: G_L pos | AT1: G_L ht | AU1: G_L fwhm | AV1: G_L area | AW1: G_L %area | AX1: C pos | AY1: C ht | AZ1: C fwhm | BA1: C area | BB1: C %area
A2: data/Silvertop Ash/SA-20(1).txt | B2: Silvertop Ash | C2: 20 kW/m2 | D2: 72.66 counts | E2: 0.990203 | F2: 1367 | G2: 33995 | H2: 200 | I2: 7237311 | J2: 37.4 | K2: =H2/Q2 -> 1.5748031 | L2: =I2/R2 -> 0.73625667 | M2: =G2/P2 -> 0.467523 | N2: =O2-F2 -> 219 | O2: 1586 | P2: 72713 | Q2: 127 | R2: 9829875 | S2: 50.8 | T2: 1073 | U2: 1 | V2: 50 | W2: 53 | X2: 0 | Y2: 1166 | Z2: 4481 | AA2: 64 | AB2: 305272 | AC2: 1.6 | AD2: 1250 | AE2: 1 | AF2: 50 | AG2: 53 | AH2: 0 | AI2: 1446 | AJ2: 9999 | AK2: 72 | AL2: 766340 | AM2: 4 | AN2: 1492 | AO2: 4325 | AP2: 50 | AQ2: 230191 | AR2: 1.2 | AS2: 1590 | AT2: 6503 | AU2: 50 | AV2: 346111 | AW2: 1.8 | AX2: 1748 | AY2: 5621 | AZ2: 104 | BA2: 622270 | BB2: 3.2
A3: data/Silvertop Ash/SA-20(2)_Copy | B3: Silvertop Ash | C3: 20 kW/m2 | D3: 73.24 counts | E3: 0.987892 | F3: 1367 | G3: 36105 | H3: 200 | I3: 7686516 | J3: 38.1 | K3: =H3/Q3 -> 1.459854 | L3: =I3/R3 -> 0.81907081 | M3: =G3/P3 -> 0.56106354 | N3: =O3-F3 -> 217 | O3: 1584 | P3: 64351 | Q3: 137 | R3: 9384434 | S3: 46.5 | T3: 1073 | U3: 3779 | V3: 156 | W3: 627529 | X3: 3.1 | Y3: 1184 | Z3: 7295 | AA3: 106 | AB3: 823120 | AC3: 4.1 | AD3: 1264 | AE3: 993 | AF3: 50 | AG3: 52851 | AH3: 0.3 | AI3: 1450 | AJ3: 5887 | AK3: 58 | AL3: 363458 | AM3: 1.8 | AN3: 1494 | AO3: 3203 | AP3: 52 | AQ3: 177293 | AR3: 0.9 | AS3: 1582 | AT3: 4991 | AU3: 50 | AV3: 265638 | AW3: 1.3 | AX3: 1748 | AY3: 4097 | AZ3: 180 | BA3: 785002 | BB3: 3.9
A4: data/Silvertop Ash/SA-20 (3).txt | B4: Silvertop Ash | C4: 20 kW/m2 | D4: 46.91 counts | E4: 0.994374 | F4: 1367 | G4: 31959 | H4: 200 | I4: 6803860 | J4: 39.1 | K4: =H4/Q4 -> 1.6260163 | L4: =I4/R4 -> 0.84194768 | M4: =G4/P4 -> 0.51779783 | N4: =O4-F4 -> 217 | O4: 1584 | P4: 61721 | Q4: 123 | R4: 8081096 | S4: 46.5 | T4: 1073 | U4: 963 | V4: 92 | W4: 94308 | X4: 0.5 | Y4: 1168 | Z4: 5365 | AA4: 86 | AB4: 491134 | AC4: 2.8 | AD4: 1250 | AE4: 1 | AF4: 50 | AG4: 53 | AH4: 0 | AI4: 1446 | AJ4: 8649 | AK4: 60 | AL4: 552395 | AM4: 3.2 | AN4: 1496 | AO4: 5021 | AP4: 50 | AQ4: 267234 | AR4: 1.5 | AS4: 1594 | AT4: 6747 | AU4: 50 | AV4: 359098 | AW4: 2.1 | AX4: 1748 | AY4: 5295 | AZ4: 130 | BA4: 732726 | BB4: 4.2
A5: data/Silvertop Ash/SA-20(12).txt | B5: Silvertop Ash | C5: 20 kW/m2 | D5: 1.95 counts | E5: 0.912712 | F5: 1369 | G5: 275 | H5: 188 | I5: 55033 | J5: 39.1 | K5: =H5/Q5 -> 1.8613861 | L5: =I5/R5 -> 0.79856345 | M5: =G5/P5 -> 0.42901716 | N5: =O5-F5 -> 215 | O5: 1584 | P5: 641 | Q5: 101 | R5: 68915 | S5: 48.9 | T5: 1023 | U5: 1 | V5: 50 | W5: 53 | X5: 0 | Y5: 1198 | Z5: 1 | AA5: 50 | AB5: 53 | AC5: 0 | AD5: 1282 | AE5: 7 | AF5: 50 | AG5: 373 | AH5: 0.3 | AI5: 1452 | AJ5: 101 | AK5: 72 | AL5: 7741 | AM5: 5.5 | AN5: 1504 | AO5: 131 | AP5: 58 | AQ5: 8088 | AR5: 5.7 | AS5: 1598 | AT5: 5 | AU5: 76 | AV5: 404 | AW5: 0.3 | AX5: 1700 | AY5: 1 | AZ5: 198 | BA5: 211 | BB5: 0.1
A6: data/Silvertop Ash/SA-20(13).txt | B6: Silvertop Ash | C6: 20 kW/m2 | D6: 51.68 counts | E6: 0.994758 | F6: 1367 | G6: 39493 | H6: 200 | I6: 8407799 | J6: 39.7 | K6: =H6/Q6 -> 1.6806723 | L6: =I6/R6 -> 0.90546057 | M6: =G6/P6 -> 0.53874906 | N6: =O6-F6 -> 221 | O6: 1588 | P6: 73305 | Q6: 119 | R6: 9285660 | S6: 43.8 | T6: 1073 | U6: 3659 | V6: 146 | W6: 568653 | X6: 2.7 | Y6: 1178 | Z6: 7437 | AA6: 100 | AB6: 791644 | AC6: 3.7 | AD6: 1252 | AE6: 921 | AF6: 50 | AG6: 49019 | AH6: 0.2 | AI6: 1450 | AJ6: 9177 | AK6: 66 | AL6: 644729 | AM6: 3 | AN6: 1498 | AO6: 6153 | AP6: 50 | AQ6: 327483 | AR6: 1.5 | AS6: 1598 | AT6: 5489 | AU6: 50 | AV6: 292143 | AW6: 1.4 | AX6: 1744 | AY6: 7845 | AZ6: 100 | BA6: 835074 | BB6: 3.9
A7: data/Silvertop Ash/SA-20(14).txt | B7: Silvertop Ash | C7: 20 kW/m2 | D7: 45.19 counts | E7: 0.99522 | F7: 1367 | G7: 36337 | H7: 200 | I7: 7735908 | J7: 40.1 | K7: =H7/Q7 -> 1.7094017 | L7: =I7/R7 -> 0.93288873 | M7: =G7/P7 -> 0.5457399 | N7: =O7-F7 -> 221 | O7: 1588 | P7: 66583 | Q7: 117 | R7: 8292423 | S7: 43 | T7: 1073 | U7: 3179 | V7: 132 | W7: 446680 | X7: 2.3 | Y7: 1178 | Z7: 7169 | AA7: 102 | AB7: 778379 | AC7: 4 | AD7: 1254 | AE7: 489 | AF7: 50 | AG7: 26026 | AH7: 0.1 | AI7: 1450 | AJ7: 8519 | AK7: 62 | AL7: 562228 | AM7: 2.9 | AN7: 1500 | AO7: 7317 | AP7: 52 | AQ7: 405013 | AR7: 2.1 | AS7: 1598 | AT7: 5353 | AU7: 50 | AV7: 284905 | AW7: 1.5 | AX7: 1742 | AY7: 7249 | AZ7: 98 | BA7: 756200 | BB7: 3.9
A8: data/Silvertop Ash/SA-20(15).txt | B8: Silvertop Ash | C8: 20 kW/m2 | D8: 62.79 counts | E8: 0.994234 | F8: 1365 | G8: 45811 | H8: 200 | I8: 9752860 | J8: 38.8 | K8: =H8/Q8 -> 1.5748031 | L8: =I8/R8 -> 0.89847824 | M8: =G8/P8 -> 0.57053366 | N8: =O8-F8 -> 219 | O8: 1584 | P8: 80295 | Q8: 127 | R8: 10854865 | S8: 43.2 | T8: 1073 | U8: 4493 | V8: 132 | W8: 631310 | X8: 2.5 | Y8: 1176 | Z8: 8941 | AA8: 100 | AB8: 951740 | AC8: 3.8 | AD8: 1254 | AE8: 557 | AF8: 50 | AG8: 29645 | AH8: 0.1 | AI8: 1450 | AJ8: 9171 | AK8: 62 | AL8: 605258 | AM8: 2.4 | AN8: 1490 | AO8: 4145 | AP8: 50 | AQ8: 220611 | AR8: 0.9 | AS8: 1596 | AT8: 9999 | AU8: 50 | AV8: 532180 | AW8: 2.1 | AX8: 1748 | AY8: 7265 | AZ8: 198 | BA8: 1531204 | BB8: 6.1
A9: data/Silvertop Ash/SA-20(16).txt | B9: Silvertop Ash | C9: 20 kW/m2 | D9: 16.15 counts | E9: 0.978626 | F9: 1365 | G9: 6219 | H9: 200 | I9: 1323984 | J9: 36.3 | K9: =H9/Q9 -> 1.459854 | L9: =I9/R9 -> 0.83192834 | M9: =G9/P9 -> 0.5698708 | N9: =O9-F9 -> 219 | O9: 1584 | P9: 10913 | Q9: 137 | R9: 1591464 | S9: 43.7 | T9: 1073 | U9: 369 | V9: 134 | W9: 52634 | X9: 1.4 | Y9: 1180 | Z9: 1369 | AA9: 102 | AB9: 148640 | AC9: 4.1 | AD9: 1250 | AE9: 23 | AF9: 50 | AG9: 1224 | AH9: 0 | AI9: 1450 | AJ9: 1761 | AK9: 58 | AL9: 108723 | AM9: 3 | AN9: 1492 | AO9: 581 | AP9: 50 | AQ9: 30923 | AR9: 0.8 | AS9: 1584 | AT9: 903 | AU9: 50 | AV9: 48061 | AW9: 1.3 | AX9: 1748 | AY9: 1605 | AZ9: 198 | BA9: 338277 | BB9: 9.3
A10: data/Silvertop Ash/SA-20(17).txt | B10: Silvertop Ash | C10: 20 kW/m2 | D10: 19.70 counts | E10: 0.988978 | F10: 1367 | G10: 10383 | H10: 200 | I10: 2210472 | J10: 38.3 | K10: =H10/Q10 -> 1.5748031 | L10: =I10/R10 -> 0.86969721 | M10: =G10/P10 -> 0.55225786 | N10: =O10-F10 -> 219 | O10: 1586 | P10: 18801 | Q10: 127 | R10: 2541657 | S10: 44 | T10: 1073 | U10: 759 | V10: 148 | W10: 119574 | X10: 2.1 | Y10: 1180 | Z10: 2131 | AA10: 100 | AB10: 226838 | AC10: 3.9 | AD10: 1250 | AE10: 153 | AF10: 50 | AG10: 8143 | AH10: 0.1 | AI10: 1452 | AJ10: 2839 | AK10: 60 | AL10: 181321 | AM10: 3.1 | AN10: 1498 | AO10: 1551 | AP10: 50 | AQ10: 82549 | AR10: 1.4 | AS10: 1590 | AT10: 1615 | AU10: 50 | AV10: 85956 | AW10: 1.5 | AX10: 1748 | AY10: 2779 | AZ10: 108 | BA10: 319481 | BB10: 5.5
A11: data/Silvertop Ash/SA-20(18).txt | B11: Silvertop Ash | C11: 20 kW/m2 | D11: 27.76 counts | E11: 0.97943 | F11: 1365 | G11: 9983 | H11: 200 | I11: 2125315 | J11: 36.9 | K11: =H11/Q11 -> 1.4388489 | L11: =I11/R11 -> 0.73991815 | M11: =G11/P11 -> 0.51424303 | N11: =O11-F11 -> 221 | O11: 1586 | P11: 19413 | Q11: 139 | R11: 2872365 | S11: 49.8 | T11: 1073 | U11: 227 | V11: 104 | W11: 25130 | X11: 0.4 | Y11: 1170 | Z11: 2005 | AA11: 86 | AB11: 183546 | AC11: 3.2 | AD11: 1250 | AE11: 1 | AF11: 50 | AG11: 53 | AH11: 0 | AI11: 1446 | AJ11: 2901 | AK11: 60 | AL11: 185281 | AM11: 3.2 | AN11: 1488 | AO11: 985 | AP11: 50 | AQ11: 52425 | AR11: 0.9 | AS11: 1586 | AT11: 1335 | AU11: 50 | AV11: 71053 | AW11: 1.2 | AX11: 1748 | AY11: 2771 | AZ11: 84 | BA11: 247770 | BB11: 4.3
A12: data/Silvertop Ash/SA-20(19).txt | B12: Silvertop Ash | C12: 20 kW/m2 | D12: 19.83 counts | E12: 0.975558 | F12: 1367 | G12: 6011 | H12: 200 | I12: 1279702 | J12: 38.6 | K12: =H12/Q12 -> 1.5748031 | L12: =I12/R12 -> 0.76966732 | M12: =G12/P12 -> 0.48873892 | N12: =O12-F12 -> 219 | O12: 1586 | P12: 12299 | Q12: 127 | R12: 1662669 | S12: 50.1 | T12: 1073 | U12: 1 | V12: 50 | W12: 53 | X12: 0 | Y12: 1180 | Z12: 995 | AA12: 80 | AB12: 84732 | AC12: 2.6 | AD12: 1250 | AE12: 29 | AF12: 50 | AG12: 1543 | AH12: 0 | AI12: 1452 | AJ12: 1897 | AK12: 64 | AL12: 129235 | AM12: 3.9 | AN12: 1500 | AO12: 799 | AP12: 50 | AQ12: 42525 | AR12: 1.3 | AS12: 1582 | AT12: 1397 | AU12: 50 | AV12: 74353 | AW12: 2.2 | AX12: 1742 | AY12: 687 | AZ12: 60 | BA12: 43877 | BB12: 1.3
A13: data/Silvertop Ash/SA-20(4).txt | B13: Silvertop Ash | C13: 20 kW/m2 | D13: 57.78 counts | E13: 0.988007 | F13: 1365 | G13: 25793 | H13: 200 | I13: 5491160 | J13: 37.5 | K13: =H13/Q13 -> 1.459854 | L13: =I13/R13 -> 0.74108954 | M13: =G13/P13 -> 0.50764628 | N13: =O13-F13 -> 219 | O13: 1584 | P13: 50809 | Q13: 137 | R13: 7409577 | S13: 50.7 | T13: 1073 | U13: 1091 | V13: 108 | W13: 125424 | X13: 0.9 | Y13: 1174 | Z13: 4809 | AA13: 86 | AB13: 440236 | AC13: 3 | AD13: 1250 | AE13: 1 | AF13: 50 | AG13: 53 | AH13: 0 | AI13: 1446 | AJ13: 6655 | AK13: 56 | AL13: 396706 | AM13: 2.7 | AN13: 1490 | AO13: 2661 | AP13: 50 | AQ13: 141627 | AR13: 1 | AS13: 1584 | AT13: 5785 | AU13: 50 | AV13: 307897 | AW13: 2.1 | AX13: 1748 | AY13: 2629 | AZ13: 112 | BA13: 313430 | BB13: 2.1
... A99: data/Silvertop Ash/SA-50 (9).txt | B99: Silvertop Ash | C99: 50 kW/m2 | D99: 20.52 counts | E99: 0.995506 | F99: 1365 | G99: 22091 | H99: 200 | I99: 4703028 | J99: 47.7 | K99: =H99/Q99 -> 1.8348624 | L99: =I99/R99 -> 1.3999911 | M99: =G99/P99 -> 0.7629952 | N99: =O99-F99 -> 223 | O99: 1588 | P99: 28953 | Q99: 109 | R99: 3359327 | S99: 34.1 | T99: 1073 | U99: 2381 | V99: 168 | W99: 425795 | X99: 4.3 | Y99: 1190 | Z99: 4895 | AA99: 114 | AB99: 594005 | AC99: 6 | AD99: 1264 | AE99: 697 | AF99: 50 | AG99: 37097 | AH99: 0.4 | AI99: 1458 | AJ99: 1939 | AK99: 50 | AL99: 103200 | AM99: 1 | AN99: 1498 | AO99: 4879 | AP99: 54 | AQ99: 280451 | AR99: 2.8 | AS99: 1584 | AT99: 1493 | AU99: 50 | AV99: 79462 | AW99: 0.8 | AX99: 1732 | AY99: 2341 | AZ99: 108 | BA99: 269127 | BB99: 2.7

Sheet SpottedGum
A1: File | B1: Vegetation | C1: Thermal Energy | D1: Std Err | E1: R_sqrd | F1: D pos | G1: D ht | H1: D fwhm | I1: D area | J1: D %area | K1: D fwhm/ G_G fwhm | L1: AD/AG | M1: R1= Dht/G ht | N1: Band separation | O1: G_G pos | P1: G_G ht | Q1: G_G fwhm | R1: G_G area | S1: G_G %area | T1: S_L pos | U1: S_L ht | V1: S_L fwhm | W1: S_L area | X1: S_L %area | Y1: S pos | Z1: S ht | AA1: S fwhm | AB1: S area | AC1: S %area | AD1: D_S pos | AE1: D_S ht | AF1: D_S fwhm | AG1: D_S area | AH1: D_S %area | AI1: A_1 pos | AJ1: A_1 ht | AK1: A_1 fwhm | AL1: A_1 area | AM1: A_1 %area | AN1: A_2 pos | AO1: A_2 ht | AP1: A_2 fwhm | AQ1: A_2 area | AR1: A_2 %area | AS1: G_L pos | AT1: G_L ht | AU1: G_L fwhm | AV1: G_L area | AW1: G_L %area | AX1: C pos | AY1: C ht | AZ1: C fwhm | BA1: C area | BB1: C %area
A2: data/Spotted Gum/SG-25(1).txt | B2: Spotted Gum | C2: 25 kW/m2 | D2: 14.00 counts | E2: 0.996135 | F2: 1365 | G2: 14673 | H2: 200 | I2: 3123785 | J2: 44 | K2: 1.8348624 | L2: 1.1856668 | M2: =G2/P2 -> 0.6461884 | N2: 223 | O2: 1588 | P2: 22707 | Q2: 109 | R2: 2634623 | S2: 37.1 | T2: 1073 | U2: 1569 | V2: 166 | W2: 277245 | X2: 3.9 | Y2: 1188 | Z2: 3571 | AA2: 112 | AB2: 425736 | AC2: 6 | AD2: 1260 | AE2: 573 | AF2: 50 | AG2: 30497 | AH2: 0.4 | AI2: 1458 | AJ2: 2193 | AK2: 58 | AL2: 135394 | AM2: 1.9 | AN2: 1500 | AO2: 3133 | AP2: 54 | AQ2: 180089 | AR2: 2.5 | AS2: 1590 | AT2: 1167 | AU2: 50 | AV2: 62112 | AW2: 0.9 | AX2: 1734 | AY2: 1987 | AZ2: 108 | BA2: 228430 | BB2: 3.2
A3: data/Spotted Gum/SG-25(2).txt | B3: Spotted Gum | C3: 25 kW/m2 | D3: 27.46 counts | E3: 0.995679 | F3: 1365 | G3: 26957 | H3: 200 | I3: 5738968 | J3: 44.2 | K3: 1.7094017 | L3: 1.1476761 | M3: =G3/P3 -> 0.6713905 | N3: 219 | O3: 1584 | P3: 40151 | Q3: 117 | R3: 5000512 | S3: 38.5 | T3: 1073 | U3: 2241 | V3: 144 | W3: 343508 | X3: 2.6 | Y3: 1184 | Z3: 5487 | AA3: 110 | AB3: 642480 | AC3: 4.9 | AD3: 1254 | AE3: 441 | AF3: 50 | AG3: 23471 | AH3: 0.2 | AI3: 1448 | AJ3: 3853 | AK3: 56 | AL3: 229678 | AM3: 1.8 | AN3: 1486 | AO3: 4713 | AP3: 50 | AQ3: 250842 | AR3: 1.9 | AS3: 1598 | AT3: 4227 | AU3: 50 | AV3: 224975 | AW3: 1.7 | AX3: 1740 | AY3: 4133 | AZ3: 120 | BA3: 527933 | BB3: 4.1
A4: data/Spotted Gum/SG-25(3).txt | B4: Spotted Gum | C4: 25 kW/m2 | D4: 23.10 counts | E4: 0.995137 | F4: 1365 | G4: 21399 | H4: 200 | I4: 4555706 | J4: 43.7 | K4: 1.6806723 | L4: 1.1114281 | M4: =G4/P4 -> 0.66129979 | N4: 221 | O4: 1586 | P4: 32359 | Q4: 119 | R4: 4098966 | S4: 39.3 | T4: 1073 | U4: 2163 | V4: 158 | W4: 363786 | X4: 3.5 | Y4: 1186 | Z4: 4885 | AA4: 110 | AB4: 571991 | AC4: 5.5 | AD4: 1252 | AE4: 817 | AF4: 50 | AG4: 43483 | AH4: 0.4 | AI4: 1458 | AJ4: 2885 | AK4: 64 | AL4: 196543 | AM4: 1.9 | AN4: 1490 | AO4: 2515 | AP4: 52 | AQ4: 139211 | AR4: 1.3 | AS4: 1592 | AT4: 2509 | AU4: 50 | AV4: 133537 | AW4: 1.3 | AX4: 1746 | AY4: 2731 | AZ4: 114 | BA4: 331405 | BB4: 3.2
A5: data/Spotted Gum/SG-25(4).txt | B5: Spotted Gum | C5: 25 kW/m2 | D5: 18.20 counts | E5: =AVERAGE(E2:E4) -> 0.99565033 | F5: =AVERAGE(F2:F4) -> 1365 | G5: =AVERAGE(G2:G4) -> 21009.667 | H5: =AVERAGE(H2:H4) -> 200 | I5: =AVERAGE(I2:I4) -> 4472819.7 | J5: =AVERAGE(J2:J4) -> 43.966667 | K5: =AVERAGE(K2:K4) -> 1.7416455 | L5: =AVERAGE(L2:L4) -> 1.148257 | M5: =G5/P5 -> 0.66195112 | N5: =AVERAGE(N2:N4) -> 221 | O5: =AVERAGE(O2:O4) -> 1586 | P5: =AVERAGE(P2:P4) -> 31739 | Q5: =AVERAGE(Q2:Q4) -> 115 | R5: =AVERAGE(R2:R4) -> 3911367 | S5: =AVERAGE(S2:S4) -> 38.3 | T5: =AVERAGE(T2:T4) -> 1073 | U5: =AVERAGE(U2:U4) -> 1991 | ... BB5: =AVERAGE(BB2:BB4) -> 3.5
A6: data/Spotted Gum/SG-25(5).txt | B6: Spotted Gum | C6: 25 kW/m2 | D6: 24.04 counts | E6: 0.995015 | F6: 1367 | G6: 21707 | H6: 200 | I6: 4621277 | J6: 42.4 | K6: 1.7094017 | L6: 1.1095953 | M6: =G6/P6 -> 0.64911336 | N6: 219 | O6: 1586 | P6: 33441 | Q6: 117 | R6: 4164831 | S6: 38.3 | T6: 1073 | U6: 2525 | V6: 180 | W6: 483800 | X6: 4.4 | Y6: 1188 | Z6: 4777 | AA6: 112 | AB6: 569515 | AC6: 5.2 | AD6: 1256 | AE6: 791 | AF6: 50 | AG6: 42100 | AH6: 0.4 | AI6: 1450 | AJ6: 3709 | AK6: 58 | AL6: 228990 | AM6: 2.1 | AN6: 1496 | AO6: 3729 | AP6: 50 | AQ6: 198470 | AR6: 1.8 | AS6: 1594 | AT6: 2961 | AU6: 50 | AV6: 157594 | AW6: 1.4 | AX6: 1740 | AY6: 3535 | AZ6: 112 | BA6: 421444 | BB6: 3.9
A7: data/Spotted Gum/SG-35(1).txt | B7: Spotted Gum | C7: 35 kW/m2 | D7: 27.09 counts | E7: 0.994717 | F7: 1365 | G7: 24641 | H7: 200 | I7: 5245906 | J7: 45.2 | K7: 1.980198 | L7: 1.2418003 | M7: =G7/P7 -> 0.62710915 | N7: 225 | O7: 1590 | P7: 39293 | Q7: 101 | R7: 4224436 | S7: 36.4 | T7: 1073 | U7: 2251 | V7: 138 | W7: 330664 | X7: 2.8 | Y7: 1186 | Z7: 6591 | AA7: 108 | AB7: 757717 | AC7: 6.5 | AD7: 1256 | AE7: 1495 | AF7: 50 | AG7: 79569 | AH7: 0.7 | AI7: 1458 | AJ7: 3321 | AK7: 58 | AL7: 205036 | AM7: 1.8 | AN7: 1500 | AO7: 5783 | AP7: 52 | AQ7: 320102 | AR7: 2.8 | AS7: 1592 | AT7: 929 | AU7: 50 | AV7: 49444 | AW7: 0.4 | AX7: 1730 | AY7: 3389 | AZ7: 110 | BA7: 396823 | BB7: 3.4
A8: data/Spotted Gum/SG-35(2).txt | B8: Spotted Gum | C8: 35 kW/m2 | D8: 32.37 counts | E8: 0.99249 | F8: 1367 | G8: 25029 | H8: 200 | I8: 5328509 | J8: 44.8 | K8: 1.8018018 | L8: 1.2001941 | M8: =G8/P8 -> 0.66610778 | N8: 221 | O8: 1588 | P8: 37575 | Q8: 111 | R8: 4439706 | S8: 37.3 | T8: 1073 | U8: 2431 | V8: 170 | W8: 439912 | X8: 3.7 | Y8: 1190 | Z8: 6321 | AA8: 112 | AB8: 753592 | AC8: 6.3 | AD8: 1260 | AE8: 1279 | AF8: 50 | AG8: 68073 | AH8: 0.6 | AI8: 1458 | AJ8: 2525 | AK8: 54 | AL8: 145140 | AM8: 1.2 | AN8: 1492 | AO8: 3865 | AP8: 50 | AQ8: 205708 | AR8: 1.7 | AS8: 1592 | AT8: 2193 | AU8: 50 | AV8: 116719 | AW8: 1 | AX8: 1738 | AY8: 3065 | AZ8: 120 | BA8: 391511 | BB8: 3.3
A9: data/Spotted Gum/SG-35(3).txt | B9: Spotted Gum | C9: 35 kW/m2 | D9: 37.54 counts | E9: 0.994271 | F9: 1365 | G9: 32811 | H9: 200 | I9: 6985246 | J9: 45.1 | K9: 1.980198 | L9: 1.246949 | M9: =G9/P9 -> 0.62970924 | N9: 225 | O9: 1590 | P9: 52105 | Q9: 101 | R9: 5601870 | S9: 36.1 | T9: 1073 | U9: 3017 | V9: 172 | W9: 552377 | X9: 3.6 | Y9: 1188 | Z9: 8137 | AA9: 110 | AB9: 952773 | AC9: 6.1 | AD9: 1256 | AE9: 1711 | AF9: 50 | AG9: 91065 | AH9: 0.6 | AI9: 1458 | AJ9: 4489 | AK9: 60 | AL9: 286704 | AM9: 1.9 | AN9: 1500 | AO9: 7403 | AP9: 52 | AQ9: 409773 | AR9: 2.6 | AS9: 1592 | AT9: 1263 | AU9: 50 | AV9: 67221 | AW9: 0.4 | AX9: 1728 | AY9: 4527 | AZ9: 114 | BA9: 549348 | BB9: 3.5
A10: data/Spotted Gum/SG-35(4).txt | B10: Spotted Gum | C10: 35 kW/m2 | D10: 41.89 counts | E10: 0.995402 | F10: 1365 | G10: 40659 | H10: 200 | I10: 8656033 | J10: 45 | K10: 1.8348624 | L10: 1.2106858 | M10: =G10/P10 -> 0.65982376 | N10: 221 | O10: 1586 | P10: 61621 | Q10: 109 | R10: 7149694 | S10: 37.1 | T10: 1073 | U10: 3967 | V10: 142 | W10: 599629 | X10: 3.1 | Y10: 1186 | Z10: 9999 | AA10: 112 | AB10: 1192084 | AC10: 6.2 | AD10: 1250 | AE10: 2277 | AF10: 50 | AG10: 121190 | AH10: 0.6 | AI10: 1458 | AJ10: 5251 | AK10: 58 | AL10: 324192 | AM10: 1.7 | AN10: 1492 | AO10: 5825 | AP10: 50 | AQ10: 310026 | AR10: 1.6 | AS10: 1596 | AT10: 5257 | AU10: 50 | AV10: 279795 | AW10: 1.5 | AX10: 1732 | AY10: 5549 | AZ10: 104 | BA10: 614300 | BB10: 3.2
A11: data/Spotted Gum/SG-35(5).txt | B11: Spotted Gum | C11: 35 kW/m2 | D11: 31.00 counts | E11: 0.993974 | F11: 1365 | G11: 26597 | H11: 200 | I11: 5662326 | J11: 44.9 | K11: 1.8018018 | L11: 1.200434 | M11: =G11/P11 -> 0.66624083 | N11: 221 | O11: 1586 | P11: 39921 | Q11: 111 | R11: 4716899 | S11: 37.4 | T11: 1073 | U11: 2575 | V11: 158 | W11: 433078 | X11: 3.4 | Y11: 1188 | Z11: 6677 | AA11: 108 | AB11: 767604 | AC11: 6.1 | AD11: 1256 | AE11: 1213 | AF11: 50 | AG11: 64560 | AH11: 0.5 | AI11: 1456 | AJ11: 3045 | AK11: 50 | AL11: 162065 | AM11: 1.3 | AN11: 1490 | AO11: 4045 | AP11: 50 | AQ11: 215288 | AR11: 1.7 | AS11: 1596 | AT11: 3195 | AU11: 50 | AV11: 170049 | AW11: 1.3 | AX11: 1730 | AY11: 3755 | AZ11: 104 | BA11: 415696 | BB11: 3.3
A12: data/Spotted Gum/SG-50(1).txt | B12: Spotted Gum | C12: 50 kW/m2 | D12: 13.78 counts | E12: 0.997577 | F12: 1367 | G12: 16463 | H12: 200 | I12: 3504864 | J12: 42.9 | K12: 1.7391304 | L12: 1.0567008 | M12: =G12/P12 -> 0.60760288 | N12: 217 | O12: 1584 | P12: 27095 | Q12: 115 | R12: 3316799 | S12: 40.6 | T12: 1073 | U12: 1347 | V12: 164 | W12: 235149 | X12: 2.9 | Y12: 1184 | Z12: 3805 | AA12: 104 | AB12: 421231 | AC12: 5.2 | AD12: 1260 | AE12: 909 | AF12: 50 | AG12: 48380 | AH12: 0.6 | AI12: 1454 | AJ12: 2803 | AK12: 56 | AL12: 167087 | AM12: 2 | AN12: 1496 | AO12: 2793 | AP12: 50 | AQ12: 148653 | AR12: 1.8 | AS12: 1590 | AT12: 3047 | AU12: 50 | AV12: 162172 | AW12: 2 | AX12: 1742 | AY12: 1679 | AZ12: 96 | BA12: 171575 | BB12: 2.1
A13: data/Spotted Gum/SG-50(2).txt | B13: Spotted Gum | C13: 50 kW/m2 | D13: 22.38 counts | E13: 0.992692 | F13: 1367 | G13: 14343 | H13: 200 | I13: 3053530 | J13: 43.8 | K13: 1.7699115 | L13: 1.0086955 | M13: =G13/P13 -> 0.56991298 | N13: 217 | O13: 1584 | P13: 25167 | Q13: 113 | R13: 3027207 | S13: 43.4 | T13: 1073 | U13: 453 | V13: 124 | W13: 59793 | X13: 0.9 | Y13: 1184 | Z13: 2823 | AA13: 104 | AB13: 312519 | AC13: 4.5 | AD13: 1260 | AE13: 335 | AF13: 50 | AG13: 17830 | AH13: 0.3 | AI13: 1456 | AJ13: 2685 | AK13: 58 | AL13: 165769 | AM13: 2.4 | AN13: 1500 | AO13: 2625 | AP13: 50 | AQ13: 139711 | AR13: 2 | AS13: 1590 | AT13: 2593 | AU13: 50 | AV13: 138008 | AW13: 2 | AX13: 1730 | AY13: 987 | AZ13: 58 | BA13: 60936 | BB13: 0.9
A14: data/Spotted Gum/SG-50(3).txt | B14: Spotted Gum | C14: 50 kW/m2 | D14: 107.25 counts | E14: 0.96114 | F14: 1369 | G14: 18521 | H14: 148 | I14: 2917819 | J14: 29.2 | K14: 1.7831325 | L14: 0.5736863 | M14: =G14/P14 -> 0.32172946 | N14: 223 | O14: 1592 | P14: 57567 | Q14: 83 | R14: 5086088 | S14: 50.9 | T14: 975 | U14: 1 | V14: 50 | W14: 53 | X14: 0 | Y14: 1150 | Z14: 1 | AA14: 50 | AB14: 53 | AC14: 0 | AD14: 1298 | AE14: 433 | AF14: 50 | AG14: 23046 | AH14: 0.2 | AI14: 1454 | AJ14: 9999 | AK14: 104 | AL14: 1106935 | AM14: 11.1 | AN14: 1520 | AO14: 9999 | AP14: 68 | AQ14: 723765 | AR14: 7.2 | AS14: 1570 | AT14: 1405 | AU14: 90 | AV14: 134602 | AW14: 1.3 | AX14: 1700 | AY14: 1 | AZ14: 50 | BA14: 53 | BB14: 0
A15: data/Spotted Gum/SG-50(4).txt | B15: Spotted Gum | C15: 50 kW/m2 | D15: 18.50 counts | E15: 0.994282 | F15: 1365 | G15: 12067 | H15: 200 | I15: 2568985 | J15: 44.4 | K15: 2.020202 | L15: 0.98819506 | M15: =G15/P15 -> 0.48915643 | N15: 219 | O15: 1584 | P15: 24669 | Q15: 99 | R15: 2599674 | S15: 44.9 | T15: 1073 | U15: 1 | V15: 50 | W15: 53 | X15: 0 | Y15: 1178 | Z15: 1661 | AA15: 76 | AB15: 134374 | AC15: 2.3 | AD15: 1250 | AE15: 279 | AF15: 50 | AG15: 14849 | AH15: 0.3 | AI15: 1452 | AJ15: 2145 | AK15: 62 | AL15: 141563 | AM15: 2.4 | AN15: 1496 | AO15: 3585 | AP15: 56 | AQ15: 213702 | AR15: 3.7 | AS15: 1598 | AT15: 1973 | AU15: 50 | AV15: 105010 | AW15: 1.8 | AX15: 1700 | AY15: 203 | AZ15: 50 | BA15: 10804 | BB15: 0.2
A16: data/Spotted Gum/SG-50(5).txt | B16: Spotted Gum | C16: 50 kW/m2 | D16: 13.19 counts | E16: 0.997835 | F16: 1367 | G16: 16701 | H16: 200 | I16: 3555533 | J16: 42.5 | K16: 1.7391304 | L16: 1.0588467 | M16: =G16/P16 -> 0.60883672 | N16: 217 | O16: 1584 | P16: 27431 | Q16: 115 | R16: 3357930 | S16: 40.1 | T16: 1073 | U16: 1559 | V16: 152 | W16: 252245 | X16: 3 | Y16: 1186 | Z16: 3963 | AA16: 110 | AB16: 464033 | AC16: 5.5 | AD16: 1258 | AE16: 925 | AF16: 50 | AG16: 49232 | AH16: 0.6 | AI16: 1452 | AJ16: 2923 | AK16: 60 | AL16: 186686 | AM16: 2.2 | AN16: 1496 | AO16: 3155 | AP16: 50 | AQ16: 167920 | AR16: 2 | AS16: 1590 | AT16: 2677 | AU16: 50 | AV16: 142479 | AW16: 1.7 | AX16: 1736 | AY16: 1989 | AZ16: 90 | BA16: 190550 | BB16: 2.3
A19: =2*SQRT(2*LN(2)) -> 2.35482 | B19: =MAX(B22:B919) -> 14672.872 | C19: =MAX(C22:C919) -> 22706.675 | D19: =MAX(D22:D919) -> 1568.9976 | E19: =MAX(E22:E919) -> 3571.0013 | F19: =MAX(F22:F919) -> 900.27148 | G19: =MAX(G22:G919) -> 2192.5823 | H19: =MAX(H22:H919) -> 3133.0055 | I19: =MAX(I22:I919) -> 1166.614 | ... L19: =MAX(L22:L919) -> 24306.606 | AJ19: =MAX(AJ22:AJ572) -> 24350.578
B21: D | C21: G_G | D21: S_L | E21: S | F21: D_S | G21: A_1 | H21: A_2 | I21: G_L | J21: C | K21: TOTAL | L21: Chris | M21: diff | AA21: D | AB21: G_G | AC21: S_L | AD21: S | AE21: D_S | AF21: A_1 | AG21: A_2 | AH21: G_L | AI21: C | AJ21: TOTAL
A22: 900.27148 | B22: 900.27148 | C22: 900.27148 | D22: 900.27148 | E22: 900.27148 | F22: 900.27148 | G22: 900.27148 | H22: 900.27148 | I22: 900.27148 | J22: 900.27148 | K22: 900.27148 | L22: 43.12811 | M22: =K22-L22 -> 857.14337 | N22: =SUM(K22:K919) -> 5780993.6 | O22: =SUM(L22:L919) -> 5818863.9 | P22: =(O22-N22)/N22 -> 0.0065508257 | Z22: 900 | AA22: =$I$2*_xlfn.NORM.DIST($Z22,$F$2,$H$2/$A$19,0) -> 0.0045446229 | AB22: =$R$2*_xlfn.NORM.DIST($Z22,$O$2,$Q$2/$A$19,0) -> 2.4183379e-44 | AC22: =$W$2*_xlfn.NORM.DIST($Z22,$T$2,$V$2/$A$19,0) -> 77.23426 | AD22: =$AB$2*_xlfn.NORM.DIST($Z22,$Y$2,$AA$2/$A$19,0) -> 3.8981086e-05 | AE22: =$AG$2*_xlfn.NORM.DIST($Z22,$AD$2,$AF$2/$A$19,0) -> 2.170576e-60 | AF22: =$AL$2*_xlfn.NORM.DIST($Z22,$AI$2,$AK$2/$A$19,0) -> 7.7714113e-109 | AG22: =$AQ$2*_xlfn.NORM.DIST($Z22,$AN$2,$AP$2/$A$19,0) -> 6.9051519e-146 | AH22: =$AV$2*_xlfn.NORM.DIST($Z22,$AS$2,$AU$2/$A$19,0) -> 5.6815104e-227 | AI22: =$BA$2*_xlfn.NORM.DIST($Z22,$AX$2,$AZ$2/$A$19,0) -> 3.1135236e-69 | AJ22: =SUM(AA22:AI22) -> 77.238844
A23: 901.60938 | B23: =$I$2*_xlfn.NORM.DIST($A23,$F$2,$H$2/$A$19,0) -> 0.005040523 | C23: =$R$2*_xlfn.NORM.DIST($A23,$O$2,$Q$2/$A$19,0) -> 4.0521959e-44 | D23: =$W$2*_xlfn.NORM.DIST($A23,$T$2,$V$2/$A$19,0) -> 81.663751 | E23: =$AB$2*_xlfn.NORM.DIST($A23,$Y$2,$AA$2/$A$19,0) -> 4.7817803e-05 | F23: =$AG$2*_xlfn.NORM.DIST($A23,$AD$2,$AF$2/$A$19,0) -> 7.8241489e-60 | G23: =$AL$2*_xlfn.NORM.DIST($A23,$AI$2,$AK$2/$A$19,0) -> 3.4076944e-108 | H23: =$AQ$2*_xlfn.NORM.DIST($A23,$AN$2,$AP$2/$A$19,0) -> 4.3210115e-145 | I23: =$AV$2*_xlfn.NORM.DIST($A23,$AS$2,$AU$2/$A$19,0) -> 6.6516039e-226 | J23: =$BA$2*_xlfn.NORM.DIST($A23,$AX$2,$AZ$2/$A$19,0) -> 5.8899238e-69 | K23: =SUM(B23:J23) -> 81.668839 | L23: 45.513184 | M23: =K23-L23 -> 36.155655 | Z23: 902 | AA23: =$I$2*_xlfn.NORM.DIST($Z23,$F$2,$H$2/$A$19,0) -> 0.0051685535 | AB23: =$R$2*_xlfn.NORM.DIST($Z23,$O$2,$Q$2/$A$19,0) -> 4.5922159e-44 | AC23: =$W$2*_xlfn.NORM.DIST($Z23,$T$2,$V$2/$A$19,0) -> 82.770135 | AD23: =$AB$2*_xlfn.NORM.DIST($Z23,$Y$2,$AA$2/$A$19,0) -> 5.0240322e-05 | AE23: =$AG$2*_xlfn.NORM.DIST($Z23,$AD$2,$AF$2/$A$19,0) -> 1.0671403e-59 | AF23: =$AL$2*_xlfn.NORM.DIST($Z23,$AI$2,$AK$2/$A$19,0) -> 4.8752481e-108 | AG23: =$AQ$2*_xlfn.NORM.DIST($Z23,$AN$2,$AP$2/$A$19,0) -> 6.7385545e-145 | AH23: =$AV$2*_xlfn.NORM.DIST($Z23,$AS$2,$AU$2/$A$19,0) -> 1.2074959e-225 | AI23: =$BA$2*_xlfn.NORM.DIST($Z23,$AX$2,$AZ$2/$A$19,0) -> 6.8742837e-69 | AJ23: =SUM(AA23:AI23) -> 82.775354
A24: 902.94531 | B24: =$I$2*_xlfn.NORM.DIST($A24,$F$2,$H$2/$A$19,0) -> 0.0054915263 | C24: =$R$2*_xlfn.NORM.DIST($A24,$O$2,$Q$2/$A$19,0) -> 6.214089e-44 | D24: =$W$2*_xlfn.NORM.DIST($A24,$T$2,$V$2/$A$19,0) -> 85.499149 | E24: =$AB$2*_xlfn.NORM.DIST($A24,$Y$2,$AA$2/$A$19,0) -> 5.6607135e-05 | F24: =$AG$2*_xlfn.NORM.DIST($A24,$AD$2,$AF$2/$A$19,0) -> 2.2583524e-59 | G24: =$AL$2*_xlfn.NORM.DIST($A24,$AI$2,$AK$2/$A$19,0) -> 1.1586231e-107 | H24: =$AQ$2*_xlfn.NORM.DIST($A24,$AN$2,$AP$2/$A$19,0) -> 1.9726966e-144 | I24: =$AV$2*_xlfn.NORM.DIST($A24,$AS$2,$AU$2/$A$19,0) -> 5.1045707e-225 | J24: =$BA$2*_xlfn.NORM.DIST($A24,$AX$2,$AZ$2/$A$19,0) -> 9.9890038e-69 | K24: =SUM(B24:J24) -> 85.504697 | L24: 48.006341 | M24: =K24-L24 -> 37.498356 | Z24: 904 | AA24: =$I$2*_xlfn.NORM.DIST($Z24,$F$2,$H$2/$A$19,0) -> 0.0058748848 | AB24: =$R$2*_xlfn.NORM.DIST($Z24,$O$2,$Q$2/$A$19,0) -> 8.7039588e-44 | AC24: =$W$2*_xlfn.NORM.DIST($Z24,$T$2,$V$2/$A$19,0) -> 88.63143 | AD24: =$AB$2*_xlfn.NORM.DIST($Z24,$Y$2,$AA$2/$A$19,0) -> 6.4637263e-05 | AE24: =$AG$2*_xlfn.NORM.DIST($Z24,$AD$2,$AF$2/$A$19,0) -> 5.2001379e-59 | AF24: =$AL$2*_xlfn.NORM.DIST($Z24,$AI$2,$AK$2/$A$19,0) -> 3.0382954e-107 | AG24: =$AQ$2*_xlfn.NORM.DIST($Z24,$AN$2,$AP$2/$A$19,0) -> 6.5261458e-144 | AH24: =$AV$2*_xlfn.NORM.DIST($Z24,$AS$2,$AU$2/$A$19,0) -> 2.5436324e-224 | AI24: =$BA$2*_xlfn.NORM.DIST($Z24,$AX$2,$AZ$2/$A$19,0) -> 1.5148752e-68 | AJ24: =SUM(AA24:AI24) -> 88.63737
A25: 904.28125 | B25: =$I$2*_xlfn.NORM.DIST($A25,$F$2,$H$2/$A$19,0) -> 0.005981403 | C25: =$R$2*_xlfn.NORM.DIST($A25,$O$2,$Q$2/$A$19,0) -> 9.5214392e-44 | D25: =$W$2*_xlfn.NORM.DIST($A25,$T$2,$V$2/$A$19,0) -> 89.482532 | E25: =$AB$2*_xlfn.NORM.DIST($A25,$Y$2,$AA$2/$A$19,0) -> 6.6959167e-05 | F25: =$AG$2*_xlfn.NORM.DIST($A25,$AD$2,$AF$2/$A$19,0) -> 6.4927214e-59 | G25: =$AL$2*_xlfn.NORM.DIST($A25,$AI$2,$AK$2/$A$19,0) -> 3.9277664e-107 | H25: =$AQ$2*_xlfn.NORM.DIST($A25,$AN$2,$AP$2/$A$19,0) -> 8.9755432e-144 | I25: =$AV$2*_xlfn.NORM.DIST($A25,$AS$2,$AU$2/$A$19,0) -> 3.9018644e-224 | J25: =$BA$2*_xlfn.NORM.DIST($A25,$AX$2,$AZ$2/$A$19,0) -> 1.6926455e-68 | K25: =SUM(B25:J25) -> 89.488581 | L25: 50.614951 | M25: =K25-L25 -> 38.87363 | Z25: 906 | AA25: =$I$2*_xlfn.NORM.DIST($Z25,$F$2,$H$2/$A$19,0) -> 0.0066740411 | AB25: =$R$2*_xlfn.NORM.DIST($Z25,$O$2,$Q$2/$A$19,0) -> 1.6466473e-43 | AC25: =$W$2*_xlfn.NORM.DIST($Z25,$T$2,$V$2/$A$19,0) -> 94.831425 | AD25: =$AB$2*_xlfn.NORM.DIST($Z25,$Y$2,$AA$2/$A$19,0) -> 8.3012897e-05 | AE25: =$AG$2*_xlfn.NORM.DIST($Z25,$AD$2,$AF$2/$A$19,0) -> 2.5116262e-58 | AF25: =$AL$2*_xlfn.NORM.DIST($Z25,$AI$2,$AK$2/$A$19,0) -> 1.8810474e-106 | AG25: =$AQ$2*_xlfn.NORM.DIST($Z25,$AN$2,$AP$2/$A$19,0) -> 6.2725382e-143 | AH25: =$AV$2*_xlfn.NORM.DIST($Z25,$AS$2,$AU$2/$A$19,0) -> 5.3109212e-223 | AI25: =$BA$2*_xlfn.NORM.DIST($Z25,$AX$2,$AZ$2/$A$19,0) -> 3.3319649e-68 | AJ25: =SUM(AA25:AI25) -> 94.838182
A26: 905.61914 | B26: =$I$2*_xlfn.NORM.DIST($A26,$F$2,$H$2/$A$19,0) -> 0.0065141783 | C26: =$R$2*_xlfn.NORM.DIST($A26,$O$2,$Q$2/$A$19,0) -> 1.4586001e-43 | D26: =$W$2*_xlfn.NORM.DIST($A26,$T$2,$V$2/$A$19,0) -> 93.624034 | E26: =$AB$2*_xlfn.NORM.DIST($A26,$Y$2,$AA$2/$A$19,0) -> 7.9161169e-05 | F26: =$AG$2*_xlfn.NORM.DIST($A26,$AD$2,$AF$2/$A$19,0) -> 1.8621285e-58 | G26: =$AL$2*_xlfn.NORM.DIST($A26,$AI$2,$AK$2/$A$19,0) -> 1.3299771e-106 | H26: =$AQ$2*_xlfn.NORM.DIST($A26,$AN$2,$AP$2/$A$19,0) -> 4.0789315e-143 | I26: =$AV$2*_xlfn.NORM.DIST($A26,$AS$2,$AU$2/$A$19,0) -> 2.9795735e-223 | J26: =$BA$2*_xlfn.NORM.DIST($A26,$AX$2,$AZ$2/$A$19,0) -> 2.8679764e-68 | K26: =SUM(B26:J26) -> 93.630628 | L26: 53.347136 | M26: =K26-L26 -> 40.283492 | Z26: 908 | AA26: =$I$2*_xlfn.NORM.DIST($Z26,$F$2,$H$2/$A$19,0) -> 0.0075777029 | AB26: =$R$2*_xlfn.NORM.DIST($Z26,$O$2,$Q$2/$A$19,0) -> 3.1093781e-43 | AC26: =$W$2*_xlfn.NORM.DIST($Z26,$T$2,$V$2/$A$19,0) -> 101.38348 | AD26: =$AB$2*_xlfn.NORM.DIST($Z26,$Y$2,$AA$2/$A$19,0) -> 0.00010642416 | AE26: =$AG$2*_xlfn.NORM.DIST($Z26,$AD$2,$AF$2/$A$19,0) -> 1.2023806e-57 | AF26: =$AL$2*_xlfn.NORM.DIST($Z26,$AI$2,$AK$2/$A$19,0) -> 1.1569269e-105 | AG26: =$AQ$2*_xlfn.NORM.DIST($Z26,$AN$2,$AP$2/$A$19,0) -> 5.9831015e-142 | AH26: =$AV$2*_xlfn.NORM.DIST($Z26,$AS$2,$AU$2/$A$19,0) -> 1.0990873e-221 | AI26: =$BA$2*_xlfn.NORM.DIST($Z26,$AX$2,$AZ$2/$A$19,0) -> 7.3147265e-68 | AJ26: =SUM(AA26:AI26) -> 101.39117
