Workbook

Sheet Corrale Swamp
A1: File | B1: Std Err | C1: R_sqrd | D1: D pos | E1: D ht | F1: D fwhm | G1: D area | H1: D %area | I1: G_G pos | J1: G_G ht | K1: G_G fwhm | L1: G_G area | M1: G_G %area | N1: S_L pos | O1: S_L ht | P1: S_L fwhm | Q1: S_L area | R1: S_L %area | S1: S pos | T1: S ht | U1: S fwhm | V1: S area | W1: S %area | X1: D_S pos | Y1: D_S ht | Z1: D_S fwhm | AA1: D_S area | AB1: D_S %area | AC1: A_1 pos | AD1: A_1 ht | AE1: A_1 fwhm | AF1: A_1 area | AG1: A_1 %area | AH1: A_2 pos | AI1: A_2 ht | AJ1: A_2 fwhm | AK1: A_2 area | AL1: A_2 %area | AM1: G_L pos | AN1: G_L ht | AO1: G_L fwhm | AP1: G_L area | AQ1: G_L %area | AR1: C pos | AS1: C ht | AT1: C fwhm | AU1: C area | AV1: C %area
A2: /Users/christophermarjo/Documents/Python/Projects/data/bushfire Raman/Corrale Swamp/CS 0.5 (1) | B2: 7.16 counts | C2: 0.983397 | D2: 1369 | E2: 3963 | F2: 326 | G2: 1375225 | H2: 74.3 | I2: 1590 | J2: 3613 | K2: 102 | L2: 392284 | M2: 21.2 | N2: 1041 | O2: 159 | P2: 67 | Q2: 11340 | R2: 0.6 | S2: 1172 | T2: 1 | U2: 1 | V2: 1 | W2: 0 | X2: 1270 | Y2: 1 | Z2: 1 | AA2: 1 | AB2: 0 | AC2: 1400 | AD2: 1 | AE2: 1 | AF2: 1 | AG2: 0 | AH2: 1500 | AI2: 143 | AJ2: 31 | AK2: 4719 | AL2: 0.3 | AM2: 1598 | AN2: 331 | AO2: 25 | AP2: 8808 | AQ2: 0.5 | AR2: 1740 | AS2: 315 | AT2: 171 | AU2: 57338 | AV2: 3.1
A3: /Users/christophermarjo/Documents/Python/Projects/data/bushfire Raman/Corrale Swamp/CS 0.5 (2) | B3: 15.30 counts | C3: 0.991694 | D3: 1369 | E3: 11427 | F3: 330 | G3: 4014009 | H3: 70.4 | I3: 1588 | J3: 12371 | K3: 104 | L3: 1369526 | M3: 24 | N3: 1039 | O3: 459 | P3: 61 | Q3: 29804 | R3: 0.5 | S3: 1172 | T3: 1 | U3: 1 | V3: 1 | W3: 0 | X3: 1270 | Y3: 1 | Z3: 1 | AA3: 1 | AB3: 0 | AC3: 1456 | AD3: 63 | AE3: 149 | AF3: 9992 | AG3: 0.2 | AH3: 1498 | AI3: 531 | AJ3: 33 | AK3: 18653 | AL3: 0.3 | AM3: 1596 | AN3: 681 | AO3: 23 | AP3: 16673 | AQ3: 0.3 | AR3: 1744 | AS3: 1271 | AT3: 179 | AU3: 242176 | AV3: 4.2
A4: /Users/christophermarjo/Documents/Python/Projects/data/bushfire Raman/Corrale Swamp/CS 0.5 (4) | B4: 46.94 counts | C4: 0.985017 | D4: 1367 | E4: 27373 | F4: 320 | G4: 9324050 | H4: 71.1 | I4: 1590 | J4: 27339 | K4: 100 | L4: 2910146 | M4: 22.2 | N4: 1041 | O4: 1383 | P4: 85 | Q4: 125133 | R4: 1 | S4: 1150 | T4: 125 | U4: 1 | V4: 133 | W4: 0 | X4: 1270 | Y4: 1 | Z4: 1 | AA4: 1 | AB4: 0 | AC4: 1400 | AD4: 1 | AE4: 1 | AF4: 1 | AG4: 0 | AH4: 1500 | AI4: 869 | AJ4: 23 | AK4: 21276 | AL4: 0.2 | AM4: 1598 | AN4: 4177 | AO4: 29 | AP4: 128942 | AQ4: 1 | AR4: 1748 | AS4: 2887 | AT4: 199 | AU4: 611550 | AV4: 4.7
A5: /Users/christophermarjo/Documents/Python/Projects/data/bushfire Raman/Corrale Swamp/CS 0.5 (5) | B5: 29.58 counts | C5: 0.987831 | D5: 1369 | E5: 18647 | F5: 318 | G5: 6312019 | H5: 72.3 | I5: 1592 | J5: 18871 | K5: 100 | L5: 2008756 | M5: 23 | N5: 1049 | O5: 875 | P5: 85 | Q5: 79170 | R5: 0.9 | S5: 1158 | T5: 1 | U5: 1 | V5: 1 | W5: 0 | X5: 1270 | Y5: 1 | Z5: 1 | AA5: 1 | AB5: 0 | AC5: 1400 | AD5: 1 | AE5: 1 | AF5: 1 | AG5: 0 | AH5: 1500 | AI5: 555 | AJ5: 15 | AK5: 8862 | AL5: 0.1 | AM5: 1598 | AN5: 3363 | AO5: 29 | AP5: 103814 | AQ5: 1.2 | AR5: 1740 | AS5: 1403 | AT5: 147 | AU5: 219537 | AV5: 2.5
A6: /Users/christophermarjo/Documents/Python/Projects/data/bushfire Raman/Corrale Swamp/CS 0.5 (6) | B6: 44.67 counts | C6: 0.985305 | D6: 1369 | E6: 25703 | F6: 320 | G6: 8755199 | H6: 72 | I6: 1592 | J6: 26285 | K6: 100 | L6: 2797952 | M6: 23 | N6: 1045 | O6: 1035 | P6: 85 | Q6: 93646 | R6: 0.8 | S6: 1154 | T6: 75 | U6: 1 | V6: 80 | W6: 0 | X6: 1270 | Y6: 1 | Z6: 1 | AA6: 1 | AB6: 0 | AC6: 1400 | AD6: 1 | AE6: 1 | AF6: 1 | AG6: 0 | AH6: 1500 | AI6: 577 | AJ6: 25 | AK6: 15355 | AL6: 0.1 | AM6: 1592 | AN6: 3635 | AO6: 29 | AP6: 112211 | AQ6: 0.9 | AR6: 1748 | AS6: 1915 | AT6: 189 | AU6: 385268 | AV6: 3.2
A7: /Users/christophermarjo/Documents/Python/Projects/data/bushfire Raman/Corrale Swamp/CS 2.5 (1) | B7: 75.77 counts | C7: 0.9828 | D7: 1365 | E7: 40141 | F7: 300 | G7: 12818631 | H7: 71.8 | I7: 1592 | J7: 41441 | K7: 100 | L7: 4411258 | M7: 24.7 | N7: 1069 | O7: 1409 | P7: 81 | Q7: 121487 | R7: 0.7 | S7: 1152 | T7: 133 | U7: 5 | V7: 708 | W7: 0 | X7: 1256 | Y7: 1 | Z7: 1 | AA7: 1 | AB7: 0 | AC7: 1406 | AD7: 1 | AE7: 1 | AF7: 1 | AG7: 0 | AH7: 1506 | AI7: 1283 | AJ7: 35 | AK7: 47800 | AL7: 0.3 | AM7: 1594 | AN7: 7009 | AO7: 29 | AP7: 216365 | AQ7: 1.2 | AR7: 1724 | AS7: 2883 | AT7: 79 | AU7: 242440 | AV7: 1.4
A8: /Users/christophermarjo/Documents/Python/Projects/data/bushfire Raman/Corrale Swamp/CS 2.5 (2) | B8: 115.68 counts | C8: 0.981734 | D8: 1369 | E8: 60665 | F8: 306 | G8: 19760223 | H8: 70.5 | I8: 1592 | J8: 60023 | K8: 100 | L8: 6389251 | M8: 22.8 | N8: 1041 | O8: 3335 | P8: 69 | Q8: 244950 | R8: 0.9 | S8: 1152 | T8: 1779 | U8: 25 | V8: 47342 | W8: 0.2 | X8: 1256 | Y8: 1 | Z8: 1 | AA8: 1 | AB8: 0 | AC8: 1406 | AD8: 1 | AE8: 1 | AF8: 1 | AG8: 0 | AH8: 1506 | AI8: 1415 | AJ8: 31 | AK8: 46693 | AL8: 0.2 | AM8: 1596 | AN8: 9999 | AO8: 31 | AP8: 329952 | AQ8: 1.2 | AR8: 1738 | AS8: 5679 | AT8: 197 | AU8: 1190886 | AV8: 4.3
A9: /Users/christophermarjo/Documents/Python/Projects/data/bushfire Raman/Corrale Swamp/CS 2.5 (3) | B9: 48.13 counts | C9: 0.983832 | D9: 1367 | E9: 27023 | F9: 310 | G9: 8917179 | H9: 73.9 | I9: 1590 | J9: 24985 | K9: 100 | L9: 2659571 | M9: 22 | N9: 1045 | O9: 1455 | P9: 85 | Q9: 131648 | R9: 1.1 | S9: 1186 | T9: 1 | U9: 1 | V9: 1 | W9: 0 | X9: 1256 | Y9: 1 | Z9: 1 | AA9: 1 | AB9: 0 | AC9: 1406 | AD9: 1 | AE9: 1 | AF9: 1 | AG9: 0 | AH9: 1506 | AI9: 671 | AJ9: 21 | AK9: 14999 | AL9: 0.1 | AM9: 1598 | AN9: 4939 | AO9: 33 | AP9: 173494 | AQ9: 1.4 | AR9: 1724 | AS9: 1581 | AT9: 99 | AU9: 166609 | AV9: 1.4
A10: /Users/christophermarjo/Documents/Python/Projects/data/bushfire Raman/Corrale Swamp/CS 2.5 (4) | B10: 105.68 counts | C10: 0.982746 | D10: 1365 | E10: 57323 | F10: 308 | G10: 18793681 | H10: 71.7 | I10: 1590 | J10: 55439 | K10: 100 | L10: 5901299 | M10: 22.5 | N10: 1041 | O10: 2965 | P10: 75 | Q10: 236711 | R10: 0.9 | S10: 1152 | T10: 7 | U10: 5 | V10: 37 | W10: 0 | X10: 1256 | Y10: 1 | Z10: 1 | AA10: 1 | AB10: 0 | AC10: 1406 | AD10: 1 | AE10: 1 | AF10: 1 | AG10: 0 | AH10: 1506 | AI10: 727 | AJ10: 29 | AK10: 22442 | AL10: 0.1 | AM10: 1598 | AN10: 9999 | AO10: 35 | AP10: 372526 | AQ10: 1.4 | AR10: 1730 | AS10: 4479 | AT10: 189 | AU10: 901104 | AV10: 3.4
A11: /Users/christophermarjo/Documents/Python/Projects/data/bushfire Raman/Corrale Swamp/CS 2.5 (5) | B11: 98.11 counts | C11: 0.980453 | D11: 1367 | E11: 49299 | F11: 298 | G11: 15638194 | H11: 70.8 | I11: 1592 | J11: 51379 | K11: 100 | L11: 5469125 | M11: 24.8 | N11: 1073 | O11: 1253 | P11: 97 | Q11: 129376 | R11: 0.6 | S11: 1152 | T11: 27 | U11: 5 | V11: 144 | W11: 0 | X11: 1256 | Y11: 1 | Z11: 1 | AA11: 1 | AB11: 0 | AC11: 1406 | AD11: 1 | AE11: 1 | AF11: 1 | AG11: 0 | AH11: 1506 | AI11: 825 | AJ11: 35 | AK11: 30736 | AL11: 0.1 | AM11: 1598 | AN11: 9935 | AO11: 29 | AP11: 306689 | AQ11: 1.4 | AR11: 1730 | AS11: 4261 | AT11: 115 | AU11: 521605 | AV11: 2.4
A12: /Users/christophermarjo/Documents/Python/Projects/data/bushfire Raman/Corrale Swamp/CS 3.5 (1) | B12: 18.10 counts | C12: 0.990002 | D12: 1369 | E12: 12263 | F12: 340 | G12: 4438210 | H12: 71.3 | I12: 1588 | J12: 13401 | K12: 104 | L12: 1483552 | M12: 23.8 | N12: 1035 | O12: 473 | P12: 65 | Q12: 32727 | R12: 0.5 | S12: 1186 | T12: 1 | U12: 1 | V12: 1 | W12: 0 | X12: 1256 | Y12: 1 | Z12: 1 | AA12: 1 | AB12: 0 | AC12: 1440 | AD12: 15 | AE12: 157 | AF12: 2507 | AG12: 0 | AH12: 1506 | AI12: 313 | AJ12: 31 | AK12: 10329 | AL12: 0.2 | AM12: 1598 | AN12: 475 | AO12: 25 | AP12: 12641 | AQ12: 0.2 | AR12: 1726 | AS12: 1495 | AT12: 153 | AU12: 243481 | AV12: 3.9
A13: /Users/christophermarjo/Documents/Python/Projects/data/bushfire Raman/Corrale Swamp/CS 3.5 (2) | B13: 37.27 counts | C13: 0.978272 | D13: 1369 | E13: 17359 | F13: 326 | G13: 6023855 | H13: 64.7 | I13: 1588 | J13: 19315 | K13: 112 | L13: 2302740 | M13: 24.7 | N13: 1017 | O13: 669 | P13: 39 | Q13: 27773 | R13: 0.3 | S13: 1152 | T13: 195 | U13: 5 | V13: 1038 | W13: 0 | X13: 1256 | Y13: 1 | Z13: 1 | AA13: 1 | AB13: 0 | AC13: 1440 | AD13: 593 | AE13: 109 | AF13: 68804 | AG13: 0.7 | AH13: 1506 | AI13: 697 | AJ13: 93 | AK13: 69000 | AL13: 0.7 | AM13: 1582 | AN13: 685 | AO13: 5 | AP13: 3646 | AQ13: 0 | AR13: 1742 | AS13: 3839 | AT13: 199 | AU13: 813211 | AV13: 8.7
... A75: /Users/christophermarjo/Documents/Python/Projects/data/bushfire Raman/Corrale Swamp/CS 18.5 (6) | B75: 9.46 counts | C75: 0.988448 | D75: 1369 | E75: 5753 | F75: 298 | G75: 1824916 | H75: 65.8 | I75: 1590 | J75: 7455 | K75: 104 | L75: 825303 | M75: 29.8 | N75: 1061 | O75: 133 | P75: 65 | Q75: 9202 | R75: 0.3 | S75: 1170 | T75: 57 | U75: 1 | V75: 61 | W75: 0 | X75: 1270 | Y75: 1 | Z75: 1 | AA75: 1 | AB75: 0 | AC75: 1456 | AD75: 65 | AE75: 99 | AF75: 6850 | AG75: 0.2 | AH75: 1492 | AI75: 191 | AJ75: 45 | AK75: 9149 | AL75: 0.3 | AM75: 1592 | AN75: 207 | AO75: 23 | AP75: 5068 | AQ75: 0.2 | AR75: 1738 | AS75: 655 | AT75: 133 | AU75: 92731 | AV75: 3.3

Sheet Horsefly Swamp
A1: File | B1: Std Err | C1: R_sqrd | D1: D pos | E1: D ht | F1: D fwhm | G1: D area | H1: D %area | I1: G_G pos | J1: G_G ht | K1: G_G fwhm | L1: G_G area | M1: G_G %area | N1: S_L pos | O1: S_L ht | P1: S_L fwhm | Q1: S_L area | R1: S_L %area | S1: S pos | T1: S ht | U1: S fwhm | V1: S area | W1: S %area | X1: D_S pos | Y1: D_S ht | Z1: D_S fwhm | AA1: D_S area | AB1: D_S %area | AC1: A_1 pos | AD1: A_1 ht | AE1: A_1 fwhm | AF1: A_1 area | AG1: A_1 %area | AH1: A_2 pos | AI1: A_2 ht | AJ1: A_2 fwhm | AK1: A_2 area | AL1: A_2 %area | AM1: G_L pos | AN1: G_L ht | AO1: G_L fwhm | AP1: G_L area | AQ1: G_L %area | AR1: C pos | AS1: C ht | AT1: C fwhm | AU1: C area | AV1: C %area
A2: /Users/christophermarjo/Documents/Python/Projects/data/bushfire Raman/Horsefly Swamp/HF 0(1) | B2: 38.17 counts | C2: 0.988327 | D2: 1369 | E2: 24279 | F2: 344 | G2: 8890403 | H2: 72.1 | I2: 1586 | J2: 24671 | K2: 114 | L2: 2993807 | M2: 24.3 | N2: 1051 | O2: 743 | P2: 51 | Q2: 40336 | R2: 0.3 | S2: 1154 | T2: 1 | U2: 1 | V2: 1 | W2: 0 | X2: 1256 | Y2: 1 | Z2: 1 | AA2: 1 | AB2: 0 | AC2: 1456 | AD2: 341 | AE2: 69 | AF2: 25046 | AG2: 0.2 | AH2: 1506 | AI2: 379 | AJ2: 11 | AK2: 4438 | AL2: 0 | AM2: 1596 | AN2: 481 | AO2: 23 | AP2: 11776 | AQ2: 0.1 | AR2: 1730 | AS2: 3151 | AT2: 107 | AU2: 358893 | AV2: 2.9
A3: /Users/christophermarjo/Documents/Python/Projects/data/bushfire Raman/Horsefly Swamp/HF 0(2) | B3: 20.12 counts | C3: 0.98871 | D3: 1369 | E3: 13083 | F3: 334 | G3: 4651425 | H3: 73.9 | I3: 1590 | J3: 12779 | K3: 100 | L3: 1360282 | M3: 21.6 | N3: 1035 | O3: 461 | P3: 75 | Q3: 36804 | R3: 0.6 | S3: 1154 | T3: 1 | U3: 1 | V3: 1 | W3: 0 | X3: 1298 | Y3: 381 | Z3: 7 | AA3: 2839 | AB3: 0 | AC3: 1416 | AD3: 1 | AE3: 1 | AF3: 1 | AG3: 0 | AH3: 1506 | AI3: 415 | AJ3: 21 | AK3: 9277 | AL3: 0.1 | AM3: 1598 | AN3: 2063 | AO3: 25 | AP3: 54900 | AQ3: 0.9 | AR3: 1736 | AS3: 863 | AT3: 191 | AU3: 175459 | AV3: 2.8
A4: /Users/christophermarjo/Documents/Python/Projects/data/bushfire Raman/Horsefly Swamp/HF 0(3) | B4: 15.54 counts | C4: 0.989395 | D4: 1369 | E4: 10431 | F4: 334 | G4: 3708554 | H4: 73.7 | I4: 1588 | J4: 10427 | K4: 100 | L4: 1109920 | M4: 22.1 | N4: 1035 | O4: 391 | P4: 79 | Q4: 32880 | R4: 0.7 | S4: 1154 | T4: 1 | U4: 1 | V4: 1 | W4: 0 | X4: 1292 | Y4: 3 | Z4: 1 | AA4: 3 | AB4: 0 | AC4: 1416 | AD4: 1 | AE4: 1 | AF4: 1 | AG4: 0 | AH4: 1506 | AI4: 181 | AJ4: 19 | AK4: 3661 | AL4: 0.1 | AM4: 1598 | AN4: 1551 | AO4: 25 | AP4: 41275 | AQ4: 0.8 | AR4: 1722 | AS4: 999 | AT4: 127 | AU4: 135052 | AV4: 2.7
A5: /Users/christophermarjo/Documents/Python/Projects/data/bushfire Raman/Horsefly Swamp/HF 0(4) | B5: 13.94 counts | C5: 0.990162 | D5: 1369 | E5: 9819 | F5: 326 | G5: 3407353 | H5: 73.2 | I5: 1590 | J5: 9787 | K5: 100 | L5: 1041794 | M5: 22.4 | N5: 1047 | O5: 429 | P5: 81 | Q5: 36989 | R5: 0.8 | S5: 1194 | T5: 3273 | U5: 1 | V5: 3484 | W5: 0.1 | X5: 1294 | Y5: 1 | Z5: 1 | AA5: 1 | AB5: 0 | AC5: 1416 | AD5: 1 | AE5: 1 | AF5: 1 | AG5: 0 | AH5: 1506 | AI5: 203 | AJ5: 29 | AK5: 6267 | AL5: 0.1 | AM5: 1598 | AN5: 1417 | AO5: 23 | AP5: 34692 | AQ5: 0.7 | AR5: 1726 | AS5: 771 | AT5: 155 | AU5: 127209 | AV5: 2.7
A6: /Users/christophermarjo/Documents/Python/Projects/data/bushfire Raman/Horsefly Swamp/HF 0(5) | B6: 18.22 counts | C6: 0.989709 | D6: 1369 | E6: 12473 | F6: 332 | G6: 4407996 | H6: 73.8 | I6: 1588 | J6: 12315 | K6: 100 | L6: 1310891 | M6: 21.9 | N6: 1043 | O6: 443 | P6: 77 | Q6: 36310 | R6: 0.6 | S6: 1154 | T6: 1 | U6: 1 | V6: 1 | W6: 0 | X6: 1292 | Y6: 37 | Z6: 1 | AA6: 39 | AB6: 0 | AC6: 1416 | AD6: 1 | AE6: 1 | AF6: 1 | AG6: 0 | AH6: 1506 | AI6: 303 | AJ6: 27 | AK6: 8708 | AL6: 0.1 | AM6: 1598 | AN6: 1563 | AO6: 25 | AP6: 41594 | AQ6: 0.7 | AR6: 1722 | AS6: 1099 | AT6: 143 | AU6: 167288 | AV6: 2.8
A7: /Users/christophermarjo/Documents/Python/Projects/data/bushfire Raman/Horsefly Swamp/HF 1.5 (1) | B7: 107.62 counts | C7: 0.317885 | D7: 1361 | E7: 4253 | F7: 200 | G7: 905436 | H7: 58.3 | I7: 1584 | J7: 5459 | K7: 100 | L7: 581093 | M7: 37.4 | N7: 1015 | O7: 1 | P7: 1 | Q7: 1 | R7: 0 | S7: 1174 | T7: 327 | U7: 57 | V7: 19841 | W7: 1.3 | X7: 1252 | Y7: 31 | Z7: 1 | AA7: 33 | AB7: 0 | AC7: 1456 | AD7: 23 | AE7: 137 | AF7: 3354 | AG7: 0.2 | AH7: 1500 | AI7: 209 | AJ7: 27 | AK7: 6007 | AL7: 0.4 | AM7: 1594 | AN7: 1039 | AO7: 33 | AP7: 36497 | AQ7: 2.4 | AR7: 1716 | AS7: 1 | AT7: 1 | AU7: 1 | AV7: 0
A8: /Users/christophermarjo/Documents/Python/Projects/data/bushfire Raman/Horsefly Swamp/HF 1.5 (2) | B8: 11.21 counts | C8: 0.960979 | D8: 1369 | E8: 3957 | F8: 282 | G8: 1187811 | H8: 64.1 | I8: 1596 | J8: 4207 | K8: 100 | L8: 447821 | M8: 24.2 | N8: 1073 | O8: 379 | P8: 129 | Q8: 52043 | R8: 2.8 | S8: 1156 | T8: 95 | U8: 37 | V8: 3742 | W8: 0.2 | X8: 1296 | Y8: 359 | Z8: 19 | AA8: 7261 | AB8: 0.4 | AC8: 1402 | AD8: 77 | AE8: 143 | AF8: 11721 | AG8: 0.6 | AH8: 1528 | AI8: 53 | AJ8: 33 | AK8: 1862 | AL8: 0.1 | AM8: 1598 | AN8: 829 | AO8: 27 | AP8: 23826 | AQ8: 1.3 | AR8: 1748 | AS8: 549 | AT8: 199 | AU8: 116294 | AV8: 6.3
A9: /Users/christophermarjo/Documents/Python/Projects/data/bushfire Raman/Horsefly Swamp/HF 1.5 (3) | B9: 7.68 counts | C9: 0.975696 | D9: 1369 | E9: 3415 | F9: 312 | G9: 1134168 | H9: 71.5 | I9: 1594 | J9: 3177 | K9: 100 | L9: 338181 | M9: 21.3 | N9: 1033 | O9: 267 | P9: 153 | Q9: 43485 | R9: 2.7 | S9: 1152 | T9: 41 | U9: 1 | V9: 44 | W9: 0 | X9: 1296 | Y9: 113 | Z9: 75 | AA9: 9021 | AB9: 0.6 | AC9: 1404 | AD9: 7 | AE9: 1 | AF9: 7 | AG9: 0 | AH9: 1500 | AI9: 71 | AJ9: 1 | AK9: 76 | AL9: 0 | AM9: 1598 | AN9: 857 | AO9: 29 | AP9: 26455 | AQ9: 1.7 | AR9: 1738 | AS9: 263 | AT9: 121 | AU9: 33875 | AV9: 2.1
A10: /Users/christophermarjo/Documents/Python/Projects/data/bushfire Raman/Horsefly Swamp/HF 1(1) | B10: 16.73 counts | C10: 0.990456 | D10: 1367 | E10: 12083 | F10: 324 | G10: 4167273 | H10: 70 | I10: 1584 | J10: 11335 | K10: 116 | L10: 1399625 | M10: 23.5 | N10: 1039 | O10: 551 | P10: 63 | Q10: 36951 | R10: 0.6 | S10: 1154 | T10: 1 | U10: 1 | V10: 1 | W10: 0 | X10: 1256 | Y10: 1 | Z10: 1 | AA10: 1 | AB10: 0 | AC10: 1424 | AD10: 309 | AE10: 125 | AF10: 41115 | AG10: 0.7 | AH10: 1482 | AI10: 609 | AJ10: 47 | AK10: 30468 | AL10: 0.5 | AM10: 1590 | AN10: 421 | AO10: 21 | AP10: 9411 | AQ10: 0.2 | AR10: 1746 | AS10: 1397 | AT10: 181 | AU10: 269158 | AV10: 4.5
A11: /Users/christophermarjo/Documents/Python/Projects/data/bushfire Raman/Horsefly Swamp/HF 1(2) | B11: 25.40 counts | C11: 0.991427 | D11: 1369 | E11: 19355 | F11: 328 | G11: 6757705 | H11: 71.3 | I11: 1584 | J11: 18341 | K11: 114 | L11: 2225666 | M11: 23.5 | N11: 1037 | O11: 739 | P11: 65 | Q11: 51132 | R11: 0.5 | S11: 1154 | T11: 1 | U11: 1 | V11: 1 | W11: 0 | X11: 1256 | Y11: 1 | Z11: 1 | AA11: 1 | AB11: 0 | AC11: 1440 | AD11: 29 | AE11: 137 | AF11: 4229 | AG11: 0 | AH11: 1486 | AI11: 895 | AJ11: 47 | AK11: 44777 | AL11: 0.5 | AM11: 1594 | AN11: 585 | AO11: 23 | AP11: 14322 | AQ11: 0.2 | AR11: 1736 | AS11: 2265 | AT11: 159 | AU11: 383352 | AV11: 4
A12: /Users/christophermarjo/Documents/Python/Projects/data/bushfire Raman/Horsefly Swamp/HF 1(3) | B12: 33.14 counts | C12: 0.988617 | D12: 1367 | E12: 22081 | F12: 334 | G12: 7850502 | H12: 70.4 | I12: 1584 | J12: 20743 | K12: 114 | L12: 2517147 | M12: 22.6 | N12: 1047 | O12: 845 | P12: 69 | Q12: 62064 | R12: 0.6 | S12: 1154 | T12: 1 | U12: 1 | V12: 1 | W12: 0 | X12: 1256 | Y12: 1 | Z12: 1 | AA12: 1 | AB12: 0 | AC12: 1424 | AD12: 127 | AE12: 143 | AF12: 19332 | AG12: 0.2 | AH12: 1490 | AI12: 1497 | AJ12: 49 | AK12: 78082 | AL12: 0.7 | AM12: 1594 | AN12: 661 | AO12: 21 | AP12: 14776 | AQ12: 0.1 | AR12: 1746 | AS12: 2887 | AT12: 199 | AU12: 611550 | AV12: 5.5
A13: /Users/christophermarjo/Documents/Python/Projects/data/bushfire Raman/Horsefly Swamp/HF 1(4) | B13: 18.31 counts | C13: 0.985638 | D13: 1367 | E13: 10707 | F13: 336 | G13: 3829476 | H13: 70.1 | I13: 1586 | J13: 10587 | K13: 116 | L13: 1307263 | M13: 23.9 | N13: 1025 | O13: 403 | P13: 51 | Q13: 21878 | R13: 0.4 | S13: 1154 | T13: 1 | U13: 1 | V13: 1 | W13: 0 | X13: 1256 | Y13: 1 | Z13: 1 | AA13: 1 | AB13: 0 | AC13: 1456 | AD13: 285 | AE13: 63 | AF13: 19113 | AG13: 0.3 | AH13: 1484 | AI13: 185 | AJ13: 37 | AK13: 7286 | AL13: 0.1 | AM13: 1582 | AN13: 23 | AO13: 3 | AP13: 73 | AQ13: 0 | AR13: 1748 | AS13: 1327 | AT13: 199 | AU13: 281097 | AV13: 5.1
... A72: /Users/christophermarjo/Documents/Python/Projects/data/bushfire Raman/Horsefly Swamp/HF 9 (5) | B72: 12.65 counts | C72: 0.985624 | D72: 1369 | E72: 7001 | F72: 336 | G72: 2503984 | H72: 70.8 | I72: 1588 | J72: 7795 | K72: 106 | L72: 879537 | M72: 24.9 | N72: 1035 | O72: 269 | P72: 57 | Q72: 16321 | R72: 0.5 | S72: 1150 | T72: 149 | U72: 1 | V72: 159 | W72: 0 | X72: 1260 | Y72: 1 | Z72: 1 | AA72: 1 | AB72: 0 | AC72: 1456 | AD72: 197 | AE72: 101 | AF72: 21180 | AG72: 0.6 | AH72: 1502 | AI72: 411 | AJ72: 45 | AK72: 19687 | AL72: 0.6 | AM72: 1598 | AN72: 269 | AO72: 17 | AP72: 4868 | AQ72: 0.1 | AR72: 1732 | AS72: 803 | AT72: 105 | AU72: 89751 | AV72: 2.5

Sheet Waterfall Creek
A1: File | B1: Std Err | C1: R_sqrd | D1: D pos | E1: D ht | F1: D fwhm | G1: D area | H1: D %area | I1: G_G pos | J1: G_G ht | K1: G_G fwhm | L1: G_G area | M1: G_G %area | N1: S_L pos | O1: S_L ht | P1: S_L fwhm | Q1: S_L area | R1: S_L %area | S1: S pos | T1: S ht | U1: S fwhm | V1: S area | W1: S %area | X1: D_S pos | Y1: D_S ht | Z1: D_S fwhm | AA1: D_S area | AB1: D_S %area | AC1: A_1 pos | AD1: A_1 ht | AE1: A_1 fwhm | AF1: A_1 area | AG1: A_1 %area | AH1: A_2 pos | AI1: A_2 ht | AJ1: A_2 fwhm | AK1: A_2 area | AL1: A_2 %area | AM1: G_L pos | AN1: G_L ht | AO1: G_L fwhm | AP1: G_L area | AQ1: G_L %area | AR1: C pos | AS1: C ht | AT1: C fwhm | AU1: C area | AV1: C %area
A2: /Users/christophermarjo/Documents/Python/Projects/data/bushfire Raman/Waterfall Creek/WFC 0 (1) | B2: 10.86 counts | C2: 0.986376 | D2: 1369 | E2: 6677 | F2: 332 | G2: 2359672 | H2: 75.7 | I2: 1588 | J2: 5957 | K2: 106 | L2: 672149 | M2: 21.6 | N2: 1027 | O2: 239 | P2: 63 | Q2: 16028 | R2: 0.5 | S2: 1154 | T2: 1 | U2: 1 | V2: 1 | W2: 0 | X2: 1298 | Y2: 67 | Z2: 1 | AA2: 71 | AB2: 0 | AC2: 1400 | AD2: 1 | AE2: 1 | AF2: 1 | AG2: 0 | AH2: 1500 | AI2: 181 | AJ2: 33 | AK2: 6358 | AL2: 0.2 | AM2: 1592 | AN2: 233 | AO2: 9 | AP2: 2232 | AQ2: 0.1 | AR2: 1722 | AS2: 559 | AT2: 101 | AU2: 60099 | AV2: 1.9
A3: /Users/christophermarjo/Documents/Python/Projects/data/bushfire Raman/Waterfall Creek/WFC 0 (2) | B3: 4.82 counts | C3: 0.975689 | D3: 1369 | E3: 2145 | F3: 256 | G3: 584520 | H3: 64.4 | I3: 1592 | J3: 2575 | K3: 102 | L3: 279582 | M3: 30.8 | N3: 1073 | O3: 65 | P3: 119 | Q3: 8234 | R3: 0.9 | S3: 1156 | T3: 131 | U3: 39 | V3: 5438 | W3: 0.6 | X3: 1270 | Y3: 1 | Z3: 1 | AA3: 1 | AB3: 0 | AC3: 1456 | AD3: 41 | AE3: 1 | AF3: 44 | AG3: 0 | AH3: 1500 | AI3: 293 | AJ3: 33 | AK3: 10292 | AL3: 1.1 | AM3: 1592 | AN3: 183 | AO3: 3 | AP3: 584 | AQ3: 0.1 | AR3: 1726 | AS3: 217 | AT3: 83 | AU3: 19172 | AV3: 2.1
A4: /Users/christophermarjo/Documents/Python/Projects/data/bushfire Raman/Waterfall Creek/WFC 0 (3) | B4: 21.92 counts | C4: 0.985605 | D4: 1369 | E4: 12021 | F4: 318 | G4: 4069115 | H4: 66.7 | I4: 1588 | J4: 14079 | K4: 118 | L4: 1768423 | M4: 29 | N4: 1027 | O4: 415 | P4: 49 | Q4: 21646 | R4: 0.4 | S4: 1170 | T4: 15 | U4: 1 | V4: 16 | W4: 0 | X4: 1270 | Y4: 1 | Z4: 1 | AA4: 1 | AB4: 0 | AC4: 1456 | AD4: 593 | AE4: 81 | AF4: 51130 | AG4: 0.8 | AH4: 1494 | AI4: 469 | AJ4: 21 | AK4: 10484 | AL4: 0.2 | AM4: 1592 | AN4: 335 | AO4: 19 | AP4: 6775 | AQ4: 0.1 | AR4: 1748 | AS4: 1365 | AT4: 121 | AU4: 175813 | AV4: 2.9
A5: /Users/christophermarjo/Documents/Python/Projects/data/bushfire Raman/Waterfall Creek/WFC 0.5 (1) | B5: 18.47 counts | C5: 0.98559 | D5: 1367 | E5: 10153 | F5: 274 | G5: 2961264 | H5: 61.6 | I5: 1594 | J5: 13917 | K5: 100 | L5: 1481419 | M5: 30.8 | N5: 1037 | O5: 277 | P5: 51 | Q5: 15038 | R5: 0.3 | S5: 1156 | T5: 353 | U5: 33 | V5: 12400 | W5: 0.3 | X5: 1270 | Y5: 1 | Z5: 1 | AA5: 1 | AB5: 0 | AC5: 1456 | AD5: 327 | AE5: 117 | AF5: 40725 | AG5: 0.8 | AH5: 1500 | AI5: 737 | AJ5: 37 | AK5: 29027 | AL5: 0.6 | AM5: 1592 | AN5: 347 | AO5: 27 | AP5: 9973 | AQ5: 0.2 | AR5: 1740 | AS5: 1315 | AT5: 185 | AU5: 258958 | AV5: 5.4
A6: /Users/christophermarjo/Documents/Python/Projects/data/bushfire Raman/Waterfall Creek/WFC 0.5 (2) | B6: 12.99 counts | C6: 0.992383 | D6: 1369 | E6: 9879 | F6: 324 | G6: 3407142 | H6: 70.2 | I6: 1590 | J6: 11439 | K6: 102 | L6: 1241997 | M6: 25.6 | N6: 1039 | O6: 399 | P6: 61 | Q6: 25908 | R6: 0.5 | S6: 1154 | T6: 1 | U6: 1 | V6: 1 | W6: 0 | X6: 1270 | Y6: 1 | Z6: 1 | AA6: 1 | AB6: 0 | AC6: 1430 | AD6: 3 | AE6: 1 | AF6: 3 | AG6: 0 | AH6: 1500 | AI6: 357 | AJ6: 33 | AK6: 12540 | AL6: 0.3 | AM6: 1596 | AN6: 839 | AO6: 29 | AP6: 25900 | AQ6: 0.5 | AR6: 1732 | AS6: 1007 | AT6: 129 | AU6: 138277 | AV6: 2.9
A7: /Users/christophermarjo/Documents/Python/Projects/data/bushfire Raman/Waterfall Creek/WFC 0.5 (3) | B7: 9.94 counts | C7: 0.990326 | D7: 1369 | E7: 6821 | F7: 326 | G7: 2366998 | H7: 70.2 | I7: 1592 | J7: 7815 | K7: 100 | L7: 831881 | M7: 24.7 | N7: 1033 | O7: 283 | P7: 77 | Q7: 23196 | R7: 0.7 | S7: 1154 | T7: 1 | U7: 1 | V7: 1 | W7: 0 | X7: 1270 | Y7: 1 | Z7: 1 | AA7: 1 | AB7: 0 | AC7: 1406 | AD7: 185 | AE7: 1 | AF7: 197 | AG7: 0 | AH7: 1500 | AI7: 293 | AJ7: 31 | AK7: 9669 | AL7: 0.3 | AM7: 1598 | AN7: 635 | AO7: 25 | AP7: 16898 | AQ7: 0.5 | AR7: 1732 | AS7: 753 | AT7: 155 | AU7: 124239 | AV7: 3.7
A8: /Users/christophermarjo/Documents/Python/Projects/data/bushfire Raman/Waterfall Creek/WFC 0.5 (4) | B8: 67.50 counts | C8: 0.985484 | D8: 1369 | E8: 29293 | F8: 298 | G8: 9292067 | H8: 54.6 | I8: 1584 | J8: 45027 | K8: 144 | L8: 6901885 | M8: 40.6 | N8: 1043 | O8: 233 | P8: 23 | Q8: 5704 | R8: 0 | S8: 1166 | T8: 43 | U8: 1 | V8: 46 | W8: 0 | X8: 1256 | Y8: 1 | Z8: 1 | AA8: 1 | AB8: 0 | AC8: 1440 | AD8: 3411 | AE8: 83 | AF8: 301364 | AG8: 1.8 | AH8: 1522 | AI8: 2183 | AJ8: 109 | AK8: 253287 | AL8: 1.5 | AM8: 1582 | AN8: 1691 | AO8: 9 | AP8: 16200 | AQ8: 0.1 | AR8: 1748 | AS8: 3633 | AT8: 61 | AU8: 235900 | AV8: 1.4
A9: /Users/christophermarjo/Documents/Python/Projects/data/bushfire Raman/Waterfall Creek/WFC 0.5 (5) | B9: 102.15 counts | C9: 0.978441 | D9: 1369 | E9: 29403 | F9: 178 | G9: 5571137 | H9: 36.9 | I9: 1584 | J9: 60647 | K9: 114 | L9: 7359468 | M9: 48.7 | N9: 999 | O9: 1 | P9: 1 | Q9: 1 | R9: 0 | S9: 1170 | T9: 1079 | U9: 3 | V9: 3446 | W9: 0 | X9: 1292 | Y9: 15 | Z9: 21 | AA9: 335 | AB9: 0 | AC9: 1458 | AD9: 9999 | AE9: 97 | AF9: 1032430 | AG9: 6.8 | AH9: 1510 | AI9: 9439 | AJ9: 109 | AK9: 1095178 | AL9: 7.3 | AM9: 1570 | AN9: 515 | AO9: 69 | AP9: 37826 | AQ9: 0.3 | AR9: 1700 | AS9: 1083 | AT9: 5 | AU9: 5764 | AV9: 0
A10: /Users/christophermarjo/Documents/Python/Projects/data/bushfire Raman/Waterfall Creek/WFC 1 (1) | B10: 24.29 counts | C10: 0.988703 | D10: 1369 | E10: 15273 | F10: 332 | G10: 5397525 | H10: 69.6 | I10: 1590 | J10: 17731 | K10: 102 | L10: 1925155 | M10: 24.8 | N10: 1045 | O10: 553 | P10: 53 | Q10: 31198 | R10: 0.4 | S10: 1160 | T10: 31 | U10: 1 | V10: 33 | W10: 0 | X10: 1270 | Y10: 1 | Z10: 1 | AA10: 1 | AB10: 0 | AC10: 1456 | AD10: 327 | AE10: 101 | AF10: 35156 | AG10: 0.5 | AH10: 1500 | AI10: 1129 | AJ10: 45 | AK10: 54080 | AL10: 0.7 | AM10: 1592 | AN10: 775 | AO10: 15 | AP10: 12374 | AQ10: 0.2 | AR10: 1730 | AS10: 1959 | AT10: 143 | AU10: 298197 | AV10: 3.8
A11: /Users/christophermarjo/Documents/Python/Projects/data/bushfire Raman/Waterfall Creek/WFC 1 (2) | B11: 35.18 counts | C11: 0.951658 | D11: 1369 | E11: 10479 | F11: 332 | G11: 3703311 | H11: 66.3 | I11: 1590 | J11: 12933 | K11: 102 | L11: 1404209 | M11: 25.2 | N11: 1009 | O11: 167 | P11: 35 | Q11: 6222 | R11: 0.1 | S11: 1174 | T11: 55 | U11: 1 | V11: 59 | W11: 0 | X11: 1270 | Y11: 1 | Z11: 1 | AA11: 1 | AB11: 0 | AC11: 1456 | AD11: 151 | AE11: 117 | AF11: 18806 | AG11: 0.3 | AH11: 1500 | AI11: 603 | AJ11: 47 | AK11: 30168 | AL11: 0.5 | AM11: 1598 | AN11: 969 | AO11: 29 | AP11: 29913 | AQ11: 0.5 | AR11: 1746 | AS11: 1893 | AT11: 193 | AU11: 388902 | AV11: 7
A12: /Users/christophermarjo/Documents/Python/Projects/data/bushfire Raman/Waterfall Creek/WFC 1 (3) | B12: 10.86 counts | C12: 0.986376 | D12: 1369 | E12: 6677 | F12: 332 | G12: 2359672 | H12: 75.7 | I12: 1588 | J12: 5957 | K12: 106 | L12: 672149 | M12: 21.6 | N12: 1027 | O12: 239 | P12: 63 | Q12: 16028 | R12: 0.5 | S12: 1154 | T12: 1 | U12: 1 | V12: 1 | W12: 0 | X12: 1298 | Y12: 67 | Z12: 1 | AA12: 71 | AB12: 0 | AC12: 1400 | AD12: 1 | AE12: 1 | AF12: 1 | AG12: 0 | AH12: 1500 | AI12: 181 | AJ12: 33 | AK12: 6358 | AL12: 0.2 | AM12: 1592 | AN12: 233 | AO12: 9 | AP12: 2232 | AQ12: 0.1 | AR12: 1722 | AS12: 559 | AT12: 101 | AU12: 60099 | AV12: 1.9
A13: /Users/christophermarjo/Documents/Python/Projects/data/bushfire Raman/Waterfall Creek/WFC 1.5 (1) | B13: 28.92 counts | C13: 0.982502 | D13: 1363 | E13: 15649 | F13: 286 | G13: 4764144 | H13: 69.5 | I13: 1596 | J13: 16609 | K13: 100 | L13: 1767973 | M13: 25.8 | N13: 1073 | O13: 615 | P13: 111 | Q13: 72666 | R13: 1.1 | S13: 1170 | T13: 37 | U13: 1 | V13: 39 | W13: 0 | X13: 1270 | Y13: 1 | Z13: 1 | AA13: 1 | AB13: 0 | AC13: 1400 | AD13: 1 | AE13: 155 | AF13: 165 | AG13: 0 | AH13: 1534 | AI13: 201 | AJ13: 101 | AK13: 21610 | AL13: 0.3 | AM13: 1598 | AN13: 2133 | AO13: 19 | AP13: 43140 | AQ13: 0.6 | AR13: 1736 | AS13: 1141 | AT13: 151 | AU13: 183398 | AV13: 2.7
... A62: /Users/christophermarjo/Documents/Python/Projects/data/bushfire Raman/Waterfall Creek/WFC 8.5 (5) | B62: 44.69 counts | C62: 0.985172 | D62: 1365 | E62: 23433 | F62: 328 | G62: 8181519 | H62: 66.5 | I62: 1588 | J62: 30039 | K62: 112 | L62: 3581259 | M62: 29.1 | N62: 1043 | O62: 733 | P62: 61 | Q62: 47596 | R62: 0.4 | S62: 1186 | T62: 1 | U62: 1 | V62: 1 | W62: 0 | X62: 1256 | Y62: 1 | Z62: 1 | AA62: 1 | AB62: 0 | AC62: 1440 | AD62: 525 | AE62: 111 | AF62: 62032 | AG62: 0.5 | AH62: 1506 | AI62: 695 | AJ62: 33 | AK62: 24414 | AL62: 0.2 | AM62: 1582 | AN62: 651 | AO62: 7 | AP62: 4851 | AQ62: 0 | AR62: 1724 | AS62: 4115 | AT62: 91 | AU62: 398606 | AV62: 3.2

Sheet Rocky Point
A1: File | B1: Std Err | C1: R_sqrd | D1: D pos | E1: D ht | F1: D fwhm | G1: D area | H1: D %area | I1: G_G pos | J1: G_G ht | K1: G_G fwhm | L1: G_G area | M1: G_G %area | N1: S_L pos | O1: S_L ht | P1: S_L fwhm | Q1: S_L area | R1: S_L %area | S1: S pos | T1: S ht | U1: S fwhm | V1: S area | W1: S %area | X1: D_S pos | Y1: D_S ht | Z1: D_S fwhm | AA1: D_S area | AB1: D_S %area | AC1: A_1 pos | AD1: A_1 ht | AE1: A_1 fwhm | AF1: A_1 area | AG1: A_1 %area | AH1: A_2 pos | AI1: A_2 ht | AJ1: A_2 fwhm | AK1: A_2 area | AL1: A_2 %area | AM1: G_L pos | AN1: G_L ht | AO1: G_L fwhm | AP1: G_L area | AQ1: G_L %area | AR1: C pos | AS1: C ht | AT1: C fwhm | AU1: C area | AV1: C %area
A2: /Users/z2134519/Documents/python/data/bushfire Raman/Rocky Point swamp/RP_M 2 (2) | B2: 15.50 counts | C2: 0.985011 | D2: 1365 | E2: 8711 | F2: 198 | G2: 1835969 | H2: 42.8 | I2: 1588 | J2: 11733 | K2: 139 | L2: 1736025 | M2: 40.5 | N2: 1073 | O2: 795 | P2: 144 | Q2: 121860 | R2: 2.8 | S2: 1188 | T2: 2027 | U2: 116 | V2: 250290 | W2: 5.8 | X2: 1254 | Y2: 99 | Z2: 50 | AA2: 5269 | AB2: 0.1 | AC2: 1454 | AD2: 919 | AE2: 60 | AF2: 58695 | AG2: 1.4 | AH2: 1486 | AI2: 583 | AJ2: 50 | AK2: 31029 | AL2: 0.7 | AM2: 1586 | AN2: 861 | AO2: 50 | AP2: 45825 | AQ2: 1.1 | AR2: 1748 | AS2: 969 | AT2: 198 | AU2: 204231 | AV2: 4.8
A3: /Users/z2134519/Documents/python/data/bushfire Raman/Rocky Point swamp/RP_M 1.5 (2) BL | B3: 6.48 counts | C3: 0.977475 | D3: 1365 | E3: 2723 | F3: 196 | G3: 568115 | H3: 54.8 | I3: 1590 | J3: 3879 | K3: 89 | L3: 367487 | M3: 35.4 | N3: 1041 | O3: 1 | P3: 50 | Q3: 53 | R3: 0 | S3: 1178 | T3: 209 | U3: 66 | V3: 14683 | W3: 1.4 | X3: 1250 | Y3: 3 | Z3: 50 | AA3: 160 | AB3: 0 | AC3: 1454 | AD3: 141 | AE3: 50 | AF3: 7504 | AG3: 0.7 | AH3: 1512 | AI3: 1103 | AJ3: 66 | AK3: 77491 | AL3: 7.5 | AM3: 1598 | AN3: 39 | AO3: 50 | AP3: 2076 | AQ3: 0.2 | AR3: 1700 | AS3: 1 | AT3: 50 | AU3: 53 | AV3: 0
A4: /Users/z2134519/Documents/python/data/bushfire Raman/Rocky Point swamp/RP_M 1.5 (2) | B4: 5.52 counts | C4: 0.989205 | D4: 1365 | E4: 3931 | F4: 198 | G4: 828515 | H4: 46.8 | I4: 1588 | J4: 4617 | K4: 139 | L4: 683136 | M4: 38.6 | N4: 1073 | O4: 375 | P4: 148 | Q4: 59078 | R4: 3.3 | S4: 1186 | T4: 845 | U4: 118 | V4: 106138 | W4: 6 | X4: 1264 | Y4: 79 | Z4: 50 | AA4: 4205 | AB4: 0.2 | AC4: 1454 | AD4: 319 | AE4: 50 | AF4: 16978 | AG4: 1 | AH4: 1492 | AI4: 403 | AJ4: 50 | AK4: 21449 | AL4: 1.2 | AM4: 1590 | AN4: 227 | AO4: 50 | AP4: 12082 | AQ4: 0.7 | AR4: 1748 | AS4: 489 | AT4: 74 | AU4: 38519 | AV4: 2.2
A5: /Users/z2134519/Documents/python/data/bushfire Raman/Rocky Point swamp/RP_M 1(2) BL | B5: 11.19 counts | C5: 0.997438 | D5: 1367 | E5: 14845 | F5: 198 | G5: 3128799 | H5: 53.1 | I5: 1588 | J5: 19185 | K5: 107 | L5: 2185133 | M5: 37.1 | N5: 1073 | O5: 1 | P5: 50 | Q5: 53 | R5: 0 | S5: 1184 | T5: 1321 | U5: 84 | V5: 118118 | W5: 2 | X5: 1250 | Y5: 143 | Z5: 50 | AA5: 7611 | AB5: 0.1 | AC5: 1458 | AD5: 1643 | AE5: 50 | AF5: 87446 | AG5: 1.5 | AH5: 1502 | AI5: 3765 | AJ5: 60 | AK5: 240463 | AL5: 4.1 | AM5: 1594 | AN5: 1389 | AO5: 50 | AP5: 73927 | AQ5: 1.3 | AR5: 1712 | AS5: 867 | AT5: 56 | AU5: 51682 | AV5: 0.9
A6: /Users/z2134519/Documents/python/data/bushfire Raman/Rocky Point swamp/RP_M 1BL | B6: 13.87 counts | C6: 0.992814 | D6: 1367 | E6: 11421 | F6: 196 | G6: 2382827 | H6: 53.3 | I6: 1588 | J6: 14467 | K6: 107 | L6: 1647762 | M6: 36.8 | N6: 1029 | O6: 21 | P6: 50 | Q6: 1118 | R6: 0 | S6: 1166 | T6: 1629 | U6: 68 | V6: 117913 | W6: 2.6 | X6: 1250 | Y6: 89 | Z6: 66 | AA6: 6253 | AB6: 0.1 | AC6: 1458 | AD6: 993 | AE6: 50 | AF6: 52851 | AG6: 1.2 | AH6: 1498 | AI6: 2959 | AJ6: 56 | AK6: 176386 | AL6: 3.9 | AM6: 1592 | AN6: 1093 | AO6: 50 | AP6: 58173 | AQ6: 1.3 | AR6: 1712 | AS6: 543 | AT6: 50 | AU6: 28900 | AV6: 0.6
A7: /Users/z2134519/Documents/python/data/bushfire Raman/Rocky Point swamp/RP_M 2(2) BL | B7: 9.33 counts | C7: 0.992454 | D7: 1369 | E7: 6265 | F7: 198 | G7: 1320439 | H7: 49.6 | I7: 1586 | J7: 10201 | K7: 99 | L7: 1075004 | M7: 40.4 | N7: 1011 | O7: 1 | P7: 50 | Q7: 53 | R7: 0 | S7: 1192 | T7: 809 | U7: 98 | V7: 84393 | W7: 3.2 | X7: 1254 | Y7: 89 | Z7: 50 | AA7: 4737 | AB7: 0.2 | AC7: 1458 | AD7: 689 | AE7: 62 | AF7: 45472 | AG7: 1.7 | AH7: 1508 | AI7: 1425 | AJ7: 60 | AK7: 91012 | AL7: 3.4 | AM7: 1596 | AN7: 593 | AO7: 50 | AP7: 31561 | AQ7: 1.2 | AR7: 1700 | AS7: 183 | AT7: 50 | AU7: 9740 | AV7: 0.4
A8: /Users/z2134519/Documents/python/data/bushfire Raman/Rocky Point swamp/RP_M 5.5 (1) | B8: 19.61 counts | C8: 0.930309 | D8: 1335 | E8: 1723 | F8: 100 | G8: 183408 | H8: 16.3 | I8: 1592 | J8: 9455 | K8: 79 | L8: 795098 | M8: 70.8 | N8: 1013 | O8: 415 | P8: 50 | Q8: 22088 | R8: 2 | S8: 1160 | T8: 1201 | U8: 52 | V8: 66478 | W8: 5.9 | X8: 1298 | Y8: 1 | Z8: 50 | AA8: 53 | AB8: 0 | AC8: 1400 | AD8: 1 | AE8: 50 | AF8: 53 | AG8: 0 | AH8: 1532 | AI8: 909 | AJ8: 50 | AK8: 48380 | AL8: 4.3 | AM8: 1598 | AN8: 125 | AO8: 50 | AP8: 6653 | AQ8: 0.6 | AR8: 1724 | AS8: 1 | AT8: 50 | AU8: 53 | AV8: 0
A9: /Users/z2134519/Documents/python/data/bushfire Raman/Rocky Point swamp/RP_M 5.5 (2) BL | B9: 14.99 counts | C9: 0.961938 | D9: 1339 | E9: 3731 | F9: 100 | G9: 397153 | H9: 34.2 | I9: 1594 | J9: 9633 | K9: 69 | L9: 707527 | M9: 61 | N9: 1073 | O9: 103 | P9: 74 | Q9: 8113 | R9: 0.7 | S9: 1150 | T9: 459 | U9: 60 | V9: 29315 | W9: 2.5 | X9: 1298 | Y9: 1 | Z9: 50 | AA9: 53 | AB9: 0 | AC9: 1400 | AD9: 1 | AE9: 50 | AF9: 53 | AG9: 0 | AH9: 1542 | AI9: 233 | AJ9: 50 | AK9: 12401 | AL9: 1.1 | AM9: 1598 | AN9: 101 | AO9: 50 | AP9: 5376 | AQ9: 0.5 | AR9: 1748 | AS9: 1 | AT9: 50 | AU9: 53 | AV9: 0
A10: /Users/z2134519/Documents/python/data/bushfire Raman/Rocky Point swamp/RP_M 5.5 (3) BL | B10: 6.93 counts | C10: 0.960292 | D10: 1347 | E10: 387 | F10: 100 | G10: 41195 | H10: 9.9 | I10: 1592 | J10: 4271 | K10: 79 | L10: 359161 | M10: 86.2 | N10: 1033 | O10: 1 | P10: 50 | Q10: 53 | R10: 0 | S10: 1160 | T10: 61 | U10: 50 | V10: 3247 | W10: 0.8 | X10: 1298 | Y10: 1 | Z10: 50 | AA10: 53 | AB10: 0 | AC10: 1400 | AD10: 1 | AE10: 50 | AF10: 53 | AG10: 0 | AH10: 1548 | AI10: 177 | AJ10: 50 | AK10: 9421 | AL10: 2.3 | AM10: 1598 | AN10: 53 | AO10: 50 | AP10: 2821 | AQ10: 0.7 | AR10: 1700 | AS10: 13 | AT10: 50 | AU10: 692 | AV10: 0.2
A11: /Users/z2134519/Documents/python/data/bushfire Raman/Rocky Point swamp/RP_M 5.5 (3) | B11: 1.46 counts | C11: 0.002593 | D11: 1339 | E11: 3 | F11: 198 | G11: 632 | H11: 9.1 | I11: 1598 | J11: 11 | K11: 351 | L11: 4110 | M11: 59.2 | N11: 987 | O11: 9 | P11: 98 | Q11: 939 | R11: 13.5 | S11: 1180 | T11: 5 | U11: 108 | V11: 575 | W11: 8.3 | X11: 1250 | Y11: 1 | Z11: 50 | AA11: 53 | AB11: 0.8 | AC11: 1436 | AD11: 1 | AE11: 50 | AF11: 53 | AG11: 0.8 | AH11: 1514 | AI11: 1 | AJ11: 50 | AK11: 53 | AL11: 0.8 | AM11: 1570 | AN11: 1 | AO11: 50 | AP11: 53 | AQ11: 0.8 | AR11: 1748 | AS11: 9 | AT11: 50 | AU11: 479 | AV11: 6.9
A12: /Users/z2134519/Documents/python/data/bushfire Raman/Rocky Point swamp/RP_M 5.5 (4) | B12: 21.83 counts | C12: 0.980268 | D12: 1365 | E12: 12793 | F12: 196 | G12: 2669074 | H12: 49.2 | I12: 1590 | J12: 12843 | K12: 139 | L12: 1900262 | M12: 35 | N12: 1073 | O12: 1359 | P12: 162 | Q12: 234351 | R12: 4.3 | S12: 1188 | T12: 2377 | U12: 126 | V12: 318810 | W12: 5.9 | X12: 1280 | Y12: 163 | Z12: 50 | AA12: 8675 | AB12: 0.2 | AC12: 1458 | AD12: 377 | AE12: 50 | AF12: 20065 | AG12: 0.4 | AH12: 1492 | AI12: 1769 | AJ12: 56 | AK12: 105450 | AL12: 1.9 | AM12: 1574 | AN12: 287 | AO12: 50 | AP12: 15275 | AQ12: 0.3 | AR12: 1748 | AS12: 747 | AT12: 198 | AU12: 157441 | AV12: 2.9
A13: /Users/z2134519/Documents/python/data/bushfire Raman/Rocky Point swamp/RP_M 5.5 (5) | B13: 14.11 counts | C13: 0.988135 | D13: 1367 | E13: 10093 | F13: 196 | G13: 2105759 | H13: 49.9 | I13: 1586 | J13: 10301 | K13: 137 | L13: 1502215 | M13: 35.6 | N13: 1073 | O13: 793 | P13: 130 | Q13: 109736 | R13: 2.6 | S13: 1178 | T13: 1971 | U13: 108 | V13: 226591 | W13: 5.4 | X13: 1284 | Y13: 523 | Z13: 52 | AA13: 28949 | AB13: 0.7 | AC13: 1458 | AD13: 817 | AE13: 50 | AF13: 43483 | AG13: 1 | AH13: 1496 | AI13: 1307 | AJ13: 54 | AK13: 75128 | AL13: 1.8 | AM13: 1578 | AN13: 733 | AO13: 50 | AP13: 39013 | AQ13: 0.9 | AR13: 1748 | AS13: 931 | AT13: 86 | AU13: 85228 | AV13: 2
... A68: /Users/z2134519/Documents/python/data/bushfire Raman/Rocky Point swamp/RPM-5 (3) | B68: 2.87 counts | C68: 0.983117 | D68: 1367 | E68: 1677 | F68: 198 | G68: 353452 | H68: 51.2 | I68: 1592 | J68: 2153 | K68: 103 | L68: 236055 | M68: 34.2 | N68: 1073 | O68: 145 | P68: 194 | Q68: 29943 | R68: 4.3 | S68: 1180 | T68: 277 | U68: 90 | V68: 26537 | W68: 3.8 | X68: 1250 | Y68: 13 | Z68: 50 | AA68: 692 | AB68: 0.1 | AC68: 1458 | AD68: 17 | AE68: 50 | AF68: 905 | AG68: 0.1 | AH68: 1490 | AI68: 301 | AJ68: 54 | AK68: 17302 | AL68: 2.5 | AM68: 1598 | AN68: 49 | AO68: 50 | AP68: 2608 | AQ68: 0.4 | AR68: 1722 | AS68: 255 | AT68: 86 | AU68: 23344 | AV68: 3.4

Sheet Fortress Creek
A1: File | B1: Std Err | C1: R_sqrd | D1: D pos | E1: D ht | F1: D fwhm | G1: D area | H1: D %area | I1: G_G pos | J1: G_G ht | K1: G_G fwhm | L1: G_G area | M1: G_G %area | N1: S_L pos | O1: S_L ht | P1: S_L fwhm | Q1: S_L area | R1: S_L %area | S1: S pos | T1: S ht | U1: S fwhm | V1: S area | W1: S %area | X1: D_S pos | Y1: D_S ht | Z1: D_S fwhm | AA1: D_S area | AB1: D_S %area | AC1: A_1 pos | AD1: A_1 ht | AE1: A_1 fwhm | AF1: A_1 area | AG1: A_1 %area | AH1: A_2 pos | AI1: A_2 ht | AJ1: A_2 fwhm | AK1: A_2 area | AL1: A_2 %area | AM1: G_L pos | AN1: G_L ht | AO1: G_L fwhm | AP1: G_L area | AQ1: G_L %area | AR1: C pos | AS1: C ht | AT1: C fwhm | AU1: C area | AV1: C %area
A2: /Users/christophermarjo/Documents/Python/Projects/data/bushfire Raman/Fortress Creek/FCM 0 (1) | B2: 18.60 counts | C2: 0.987479 | D2: 1369 | E2: 10809 | F2: 336 | G2: 3865957 | H2: 68.8 | I2: 1588 | J2: 13093 | K2: 106 | L2: 1477329 | M2: 26.3 | N2: 1035 | O2: 389 | P2: 51 | Q2: 21118 | R2: 0.4 | S2: 1154 | T2: 1 | U2: 1 | V2: 1 | W2: 0 | X2: 1270 | Y2: 1 | Z2: 1 | AA2: 1 | AB2: 0 | AC2: 1456 | AD2: 243 | AE2: 95 | AF2: 24573 | AG2: 0.4 | AH2: 1492 | AI2: 423 | AJ2: 43 | AK2: 19362 | AL2: 0.3 | AM2: 1592 | AN2: 305 | AO2: 15 | AP2: 4870 | AQ2: 0.1 | AR2: 1738 | AS2: 1239 | AT2: 155 | AU2: 204426 | AV2: 3.6
A3: /Users/christophermarjo/Documents/Python/Projects/data/bushfire Raman/Fortress Creek/FCM 0 (2) | B3: 21.66 counts | C3: 0.990596 | D3: 1369 | E3: 14261 | F3: 336 | G3: 5100602 | H3: 68.1 | I3: 1588 | J3: 18185 | K3: 104 | L3: 2013163 | M3: 26.9 | N3: 1035 | O3: 611 | P3: 71 | Q3: 46178 | R3: 0.6 | S3: 1154 | T3: 1 | U3: 1 | V3: 1 | W3: 0 | X3: 1270 | Y3: 1 | Z3: 1 | AA3: 1 | AB3: 0 | AC3: 1456 | AD3: 311 | AE3: 101 | AF3: 33436 | AG3: 0.4 | AH3: 1500 | AI3: 483 | AJ3: 39 | AK3: 20051 | AL3: 0.3 | AM3: 1598 | AN3: 589 | AO3: 17 | AP3: 10659 | AQ3: 0.1 | AR3: 1734 | AS3: 1871 | AT3: 133 | AU3: 264885 | AV3: 3.5
A4: /Users/christophermarjo/Documents/Python/Projects/data/bushfire Raman/Fortress Creek/FCM 0 (3) | B4: 21.66 counts | C4: 0.990596 | D4: 1369 | E4: 14261 | F4: 336 | G4: 5100602 | H4: 68.1 | I4: 1588 | J4: 18185 | K4: 104 | L4: 2013163 | M4: 26.9 | N4: 1035 | O4: 611 | P4: 71 | Q4: 46178 | R4: 0.6 | S4: 1154 | T4: 1 | U4: 1 | V4: 1 | W4: 0 | X4: 1270 | Y4: 1 | Z4: 1 | AA4: 1 | AB4: 0 | AC4: 1456 | AD4: 311 | AE4: 101 | AF4: 33436 | AG4: 0.4 | AH4: 1500 | AI4: 483 | AJ4: 39 | AK4: 20051 | AL4: 0.3 | AM4: 1598 | AN4: 589 | AO4: 17 | AP4: 10659 | AQ4: 0.1 | AR4: 1734 | AS4: 1871 | AT4: 133 | AU4: 264885 | AV4: 3.5
A5: /Users/christophermarjo/Documents/Python/Projects/data/bushfire Raman/Fortress Creek/FCM 0 (4) | B5: 21.53 counts | C5: 0.98953 | D5: 1369 | E5: 13359 | F5: 338 | G5: 4806433 | H5: 68.4 | I5: 1588 | J5: 17109 | K5: 104 | L5: 1894045 | M5: 26.9 | N5: 1035 | O5: 533 | P5: 55 | Q5: 31205 | R5: 0.4 | S5: 1154 | T5: 1 | U5: 1 | V5: 1 | W5: 0 | X5: 1270 | Y5: 1 | Z5: 1 | AA5: 1 | AB5: 0 | AC5: 1456 | AD5: 237 | AE5: 103 | AF5: 25985 | AG5: 0.4 | AH5: 1496 | AI5: 577 | AJ5: 43 | AK5: 26410 | AL5: 0.4 | AM5: 1584 | AN5: 807 | AO5: 3 | AP5: 2577 | AQ5: 0 | AR5: 1740 | AS5: 1533 | AT5: 149 | AU5: 243142 | AV5: 3.5
A6: /Users/christophermarjo/Documents/Python/Projects/data/bushfire Raman/Fortress Creek/FCM 0.5 (1) | B6: 16.23 counts | C6: 0.991555 | D6: 1369 | E6: 11223 | F6: 340 | G6: 4061815 | H6: 67.9 | I6: 1584 | J6: 12747 | K6: 124 | L6: 1682526 | M6: 28.1 | N6: 1061 | O6: 341 | P6: 55 | Q6: 19964 | R6: 0.3 | S6: 1154 | T6: 1 | U6: 1 | V6: 1 | W6: 0 | X6: 1270 | Y6: 1 | Z6: 1 | AA6: 1 | AB6: 0 | AC6: 1456 | AD6: 637 | AE6: 59 | AF6: 40006 | AG6: 0.7 | AH6: 1496 | AI6: 1 | AJ6: 17 | AK6: 18 | AL6: 0 | AM6: 1596 | AN6: 575 | AO6: 21 | AP6: 12853 | AQ6: 0.2 | AR6: 1748 | AS6: 1095 | AT6: 139 | AU6: 162017 | AV6: 2.7
A7: /Users/christophermarjo/Documents/Python/Projects/data/bushfire Raman/Fortress Creek/FCM 0.5 (2 ) | B7: 21.71 counts | C7: 0.988951 | D7: 1369 | E7: 13081 | F7: 344 | G7: 4789957 | H7: 68.3 | I7: 1586 | J7: 15793 | K7: 116 | L7: 1950091 | M7: 27.8 | N7: 1051 | O7: 293 | P7: 47 | Q7: 14659 | R7: 0.2 | S7: 1154 | T7: 1 | U7: 1 | V7: 1 | W7: 0 | X7: 1270 | Y7: 1 | Z7: 1 | AA7: 1 | AB7: 0 | AC7: 1456 | AD7: 751 | AE7: 53 | AF7: 42369 | AG7: 0.6 | AH7: 1498 | AI7: 263 | AJ7: 29 | AK7: 8119 | AL7: 0.1 | AM7: 1592 | AN7: 191 | AO7: 3 | AP7: 610 | AQ7: 0 | AR7: 1746 | AS7: 1389 | AT7: 137 | AU7: 202561 | AV7: 2.9
A8: /Users/christophermarjo/Documents/Python/Projects/data/bushfire Raman/Fortress Creek/FCM 0.5 (3) | B8: 11.05 counts | C8: 0.990915 | D8: 1369 | E8: 7425 | F8: 338 | G8: 2671440 | H8: 69 | I8: 1584 | J8: 8557 | K8: 116 | L8: 1056603 | M8: 27.3 | N8: 1037 | O8: 319 | P8: 61 | Q8: 20713 | R8: 0.5 | S8: 1154 | T8: 1 | U8: 1 | V8: 1 | W8: 0 | X8: 1270 | Y8: 1 | Z8: 1 | AA8: 1 | AB8: 0 | AC8: 1456 | AD8: 387 | AE8: 67 | AF8: 27601 | AG8: 0.7 | AH8: 1496 | AI8: 223 | AJ8: 39 | AK8: 9258 | AL8: 0.2 | AM8: 1596 | AN8: 41 | AO8: 21 | AP8: 917 | AQ8: 0 | AR8: 1734 | AS8: 779 | AT8: 103 | AU8: 85410 | AV8: 2.2
A9: /Users/christophermarjo/Documents/Python/Projects/data/bushfire Raman/Fortress Creek/FCM 1.5 (1) | B9: 9.01 counts | C9: 0.991257 | D9: 1369 | E9: 6353 | F9: 318 | G9: 2150494 | H9: 68.7 | I9: 1592 | J9: 7577 | K9: 100 | L9: 806547 | M9: 25.8 | N9: 1031 | O9: 255 | P9: 57 | Q9: 15472 | R9: 0.5 | S9: 1152 | T9: 129 | U9: 1 | V9: 137 | W9: 0 | X9: 1270 | Y9: 1 | Z9: 1 | AA9: 1 | AB9: 0 | AC9: 1402 | AD9: 5 | AE9: 1 | AF9: 5 | AG9: 0 | AH9: 1500 | AI9: 183 | AJ9: 33 | AK9: 6428 | AL9: 0.2 | AM9: 1594 | AN9: 995 | AO9: 31 | AP9: 32833 | AQ9: 1 | AR9: 1730 | AS9: 817 | AT9: 135 | AU9: 117405 | AV9: 3.8
A10: /Users/christophermarjo/Documents/Python/Projects/data/bushfire Raman/Fortress Creek/FCM 1.5 (2) | B10: 8.43 counts | C10: 0.991586 | D10: 1369 | E10: 6167 | F10: 328 | G10: 2153178 | H10: 70.3 | I10: 1590 | J10: 7095 | K10: 100 | L10: 755239 | M10: 24.7 | N10: 1039 | O10: 219 | P10: 75 | Q10: 17484 | R10: 0.6 | S10: 1154 | T10: 1 | U10: 1 | V10: 1 | W10: 0 | X10: 1270 | Y10: 1 | Z10: 1 | AA10: 1 | AB10: 0 | AC10: 1400 | AD10: 91 | AE10: 1 | AF10: 97 | AG10: 0 | AH10: 1500 | AI10: 217 | AJ10: 35 | AK10: 8085 | AL10: 0.3 | AM10: 1596 | AN10: 433 | AO10: 25 | AP10: 11523 | AQ10: 0.4 | AR10: 1736 | AS10: 659 | AT10: 167 | AU10: 117148 | AV10: 3.8
A11: /Users/christophermarjo/Documents/Python/Projects/data/bushfire Raman/Fortress Creek/FCM 1.5 (3) | B11: 12.19 counts | C11: 0.987631 | D11: 1369 | E11: 7161 | F11: 326 | G11: 2484983 | H11: 68.5 | I11: 1590 | J11: 8819 | K11: 102 | L11: 957529 | M11: 26.4 | N11: 1031 | O11: 253 | P11: 67 | Q11: 18044 | R11: 0.5 | S11: 1154 | T11: 1 | U11: 1 | V11: 1 | W11: 0 | X11: 1270 | Y11: 1 | Z11: 1 | AA11: 1 | AB11: 0 | AC11: 1440 | AD11: 3 | AE11: 143 | AF11: 457 | AG11: 0 | AH11: 1500 | AI11: 345 | AJ11: 29 | AK11: 10650 | AL11: 0.3 | AM11: 1598 | AN11: 707 | AO11: 25 | AP11: 18814 | AQ11: 0.5 | AR11: 1730 | AS11: 935 | AT11: 137 | AU11: 136353 | AV11: 3.8
A12: /Users/christophermarjo/Documents/Python/Projects/data/bushfire Raman/Fortress Creek/FCM 1(1) | B12: 15.75 counts | C12: 0.990441 | D12: 1369 | E12: 10381 | F12: 342 | G12: 3779179 | H12: 70.5 | I12: 1588 | J12: 12297 | K12: 102 | L12: 1335155 | M12: 24.9 | N12: 1025 | O12: 401 | P12: 59 | Q12: 25184 | R12: 0.5 | S12: 1154 | T12: 1 | U12: 1 | V12: 1 | W12: 0 | X12: 1270 | Y12: 1 | Z12: 1 | AA12: 1 | AB12: 0 | AC12: 1456 | AD12: 373 | AE12: 5 | AF12: 1985 | AG12: 0 | AH12: 1500 | AI12: 293 | AJ12: 27 | AK12: 8421 | AL12: 0.2 | AM12: 1598 | AN12: 1309 | AO12: 31 | AP12: 43195 | AQ12: 0.8 | AR12: 1734 | AS12: 1089 | AT12: 143 | AU12: 165766 | AV12: 3.1
A13: /Users/christophermarjo/Documents/Python/Projects/data/bushfire Raman/Fortress Creek/FCM 1(2) | B13: 19.84 counts | C13: 0.974746 | D13: 1369 | E13: 8341 | F13: 316 | G13: 2805675 | H13: 69.2 | I13: 1592 | J13: 9983 | K13: 102 | L13: 1083911 | M13: 26.7 | N13: 1037 | O13: 333 | P13: 77 | Q13: 27294 | R13: 0.7 | S13: 1154 | T13: 1 | U13: 1 | V13: 1 | W13: 0 | X13: 1270 | Y13: 1 | Z13: 1 | AA13: 1 | AB13: 0 | AC13: 1428 | AD13: 139 | AE13: 1 | AF13: 148 | AG13: 0 | AH13: 1500 | AI13: 457 | AJ13: 29 | AK13: 14107 | AL13: 0.3 | AM13: 1596 | AN13: 281 | AO13: 27 | AP13: 8076 | AQ13: 0.2 | AR13: 1728 | AS13: 1005 | AT13: 107 | AU13: 114467 | AV13: 2.8
... A58: /Users/christophermarjo/Documents/Python/Projects/data/bushfire Raman/Fortress Creek/FCM 10.5 (3) | B58: 21.67 counts | C58: 0.985848 | D58: 1369 | E58: 13185 | F58: 298 | G58: 4182429 | H58: 69.4 | I58: 1592 | J58: 13143 | K58: 100 | L58: 1399029 | M58: 23.2 | N58: 1053 | O58: 779 | P58: 109 | Q58: 90385 | R58: 1.5 | S58: 1156 | T58: 115 | U58: 1 | V58: 122 | W58: 0 | X58: 1270 | Y58: 1 | Z58: 1 | AA58: 1 | AB58: 0 | AC58: 1400 | AD58: 1 | AE58: 1 | AF58: 1 | AG58: 0 | AH58: 1500 | AI58: 365 | AJ58: 25 | AK58: 9713 | AL58: 0.2 | AM58: 1596 | AN58: 2141 | AO58: 27 | AP58: 61534 | AQ58: 1 | AR58: 1740 | AS58: 1435 | AT58: 183 | AU58: 279534 | AV58: 4.6

Sheet Kings Tableland
A1: File | B1: Std Err | C1: R_sqrd | D1: D pos | E1: D ht | F1: D fwhm | G1: D area | H1: D %area | I1: G_G pos | J1: G_G ht | K1: G_G fwhm | L1: G_G area | M1: G_G %area | N1: S_L pos | O1: S_L ht | P1: S_L fwhm | Q1: S_L area | R1: S_L %area | S1: S pos | T1: S ht | U1: S fwhm | V1: S area | W1: S %area | X1: D_S pos | Y1: D_S ht | Z1: D_S fwhm | AA1: D_S area | AB1: D_S %area | AC1: A_1 pos | AD1: A_1 ht | AE1: A_1 fwhm | AF1: A_1 area | AG1: A_1 %area | AH1: A_2 pos | AI1: A_2 ht | AJ1: A_2 fwhm | AK1: A_2 area | AL1: A_2 %area | AM1: G_L pos | AN1: G_L ht | AO1: G_L fwhm | AP1: G_L area | AQ1: G_L %area | AR1: C pos | AS1: C ht | AT1: C fwhm | AU1: C area | AV1: C %area
A2: /Users/christophermarjo/Documents/Python/Projects/data/bushfire Raman/Kings Tableland (RHS)/KT-M 1.5 (1) txt | B2: 44.96 counts | C2: 0.985161 | D2: 1369 | E2: 23313 | F2: 300 | G2: 7444776 | H2: 62.4 | I2: 1586 | J2: 29001 | K2: 124 | L2: 3827955 | M2: 32.1 | N2: 1029 | O2: 941 | P2: 45 | Q2: 45075 | R2: 0.4 | S2: 1160 | T2: 109 | U2: 1 | V2: 116 | W2: 0 | X2: 1260 | Y2: 1 | Z2: 1 | AA2: 1 | AB2: 0 | AC2: 1434 | AD2: 1203 | AE2: 89 | AF2: 113969 | AG2: 1 | AH2: 1488 | AI2: 2635 | AJ2: 45 | AK2: 126219 | AL2: 1.1 | AM2: 1598 | AN2: 743 | AO2: 25 | AP2: 19772 | AQ2: 0.2 | AR2: 1748 | AS2: 2861 | AT2: 115 | AU2: 350226 | AV2: 2.9
A3: /Users/christophermarjo/Documents/Python/Projects/data/bushfire Raman/Kings Tableland (RHS)/KT-M 1.5 (2) txt | B3: 23.90 counts | C3: 0.984693 | D3: 1369 | E3: 11925 | F3: 342 | G3: 4341269 | H3: 66.8 | I3: 1584 | J3: 13305 | K3: 136 | L3: 1926132 | M3: 29.7 | N3: 1013 | O3: 189 | P3: 73 | Q3: 14686 | R3: 0.2 | S3: 1158 | T3: 1 | U3: 1 | V3: 1 | W3: 0 | X3: 1260 | Y3: 1 | Z3: 1 | AA3: 1 | AB3: 0 | AC3: 1434 | AD3: 385 | AE3: 97 | AF3: 39753 | AG3: 0.6 | AH3: 1482 | AI3: 1171 | AJ3: 53 | AK3: 66064 | AL3: 1 | AM3: 1598 | AN3: 445 | AO3: 1 | AP3: 474 | AQ3: 0 | AR3: 1748 | AS3: 1409 | AT3: 71 | AU3: 106488 | AV3: 1.6
A4: /Users/christophermarjo/Documents/Python/Projects/data/bushfire Raman/Kings Tableland (RHS)/KTM 0 (1) .txt | B4: 11.00 counts | C4: 0.983528 | D4: 1369 | E4: 5433 | F4: 302 | G4: 1746541 | H4: 61.8 | I4: 1594 | J4: 7709 | K4: 104 | L4: 853422 | M4: 30.2 | N4: 1005 | O4: 221 | P4: 15 | Q4: 3529 | R4: 0.1 | S4: 1156 | T4: 301 | U4: 21 | V4: 6728 | W4: 0.2 | X4: 1260 | Y4: 1 | Z4: 1 | AA4: 1 | AB4: 0 | AC4: 1418 | AD4: 135 | AE4: 119 | AF4: 17101 | AG4: 0.6 | AH4: 1502 | AI4: 785 | AJ4: 35 | AK4: 29246 | AL4: 1 | AM4: 1598 | AN4: 101 | AO4: 17 | AP4: 1828 | AQ4: 0.1 | AR4: 1748 | AS4: 783 | AT4: 199 | AU4: 165862 | AV4: 5.9
A5: /Users/christophermarjo/Documents/Python/Projects/data/bushfire Raman/Kings Tableland (RHS)/KTM 0 (2). txt | B5: 9.49 counts | C5: 0.986118 | D5: 1369 | E5: 5373 | F5: 282 | G5: 1612866 | H5: 62.7 | I5: 1594 | J5: 7283 | K5: 100 | L5: 775251 | M5: 30.1 | N5: 1049 | O5: 225 | P5: 109 | Q5: 26106 | R5: 1 | S5: 1156 | T5: 309 | U5: 11 | V5: 3618 | W5: 0.1 | X5: 1260 | Y5: 1 | Z5: 1 | AA5: 1 | AB5: 0 | AC5: 1450 | AD5: 307 | AE5: 93 | AF5: 30392 | AG5: 1.2 | AH5: 1528 | AI5: 121 | AJ5: 3 | AK5: 386 | AL5: 0 | AM5: 1592 | AN5: 255 | AO5: 27 | AP5: 7329 | AQ5: 0.3 | AR5: 1730 | AS5: 789 | AT5: 139 | AU5: 116741 | AV5: 4.5
A6: /Users/christophermarjo/Documents/Python/Projects/data/bushfire Raman/Kings Tableland (RHS)/KTM 0 (3) .txt | B6: 11.04 counts | C6: 0.982555 | D6: 1365 | E6: 5779 | F6: 280 | G6: 1722435 | H6: 62.3 | I6: 1594 | J6: 7589 | K6: 100 | L6: 807824 | M6: 29.2 | N6: 1063 | O6: 257 | P6: 107 | Q6: 29272 | R6: 1.1 | S6: 1152 | T6: 51 | U6: 1 | V6: 54 | W6: 0 | X6: 1260 | Y6: 1 | Z6: 1 | AA6: 1 | AB6: 0 | AC6: 1450 | AD6: 103 | AE6: 133 | AF6: 14582 | AG6: 0.5 | AH6: 1494 | AI6: 231 | AJ6: 25 | AK6: 6147 | AL6: 0.2 | AM6: 1582 | AN6: 175 | AO6: 7 | AP6: 1304 | AQ6: 0 | AR6: 1730 | AS6: 979 | AT6: 175 | AU6: 182370 | AV6: 6.6
A7: /Users/christophermarjo/Documents/Python/Projects/data/bushfire Raman/Kings Tableland (RHS)/KTM 0. 5 (2) .txt | B7: 14.79 counts | C7: 0.97623 | D7: 1363 | E7: 6801 | F7: 260 | G7: 1882254 | H7: 56.7 | I7: 1598 | J7: 9137 | K7: 100 | L7: 972604 | M7: 29.3 | N7: 1073 | O7: 201 | P7: 117 | Q7: 25033 | R7: 0.8 | S7: 1156 | T7: 231 | U7: 33 | V7: 8114 | W7: 0.2 | X7: 1260 | Y7: 1 | Z7: 1 | AA7: 1 | AB7: 0 | AC7: 1418 | AD7: 149 | AE7: 141 | AF7: 22363 | AG7: 0.7 | AH7: 1494 | AI7: 745 | AJ7: 55 | AK7: 43617 | AL7: 1.3 | AM7: 1598 | AN7: 539 | AO7: 25 | AP7: 14344 | AQ7: 0.4 | AR7: 1748 | AS7: 1667 | AT7: 199 | AU7: 353119 | AV7: 10.6
A8: /Users/christophermarjo/Documents/Python/Projects/data/bushfire Raman/Kings Tableland (RHS)/KTM 0.5 (1). txt | B8: 11.92 counts | C8: 0.98428 | D8: 1359 | E8: 6565 | F8: 256 | G8: 1788986 | H8: 58.9 | I8: 1596 | J8: 8787 | K8: 100 | L8: 935347 | M8: 30.8 | N8: 1073 | O8: 291 | P8: 119 | Q8: 36861 | R8: 1.2 | S8: 1150 | T8: 463 | U8: 1 | V8: 493 | W8: 0 | X8: 1260 | Y8: 1 | Z8: 1 | AA8: 1 | AB8: 0 | AC8: 1450 | AD8: 49 | AE8: 163 | AF8: 8502 | AG8: 0.3 | AH8: 1494 | AI8: 479 | AJ8: 45 | AK8: 22945 | AL8: 0.8 | AM8: 1598 | AN8: 1121 | AO8: 31 | AP8: 36991 | AQ8: 1.2 | AR8: 1748 | AS8: 989 | AT8: 199 | AU8: 209499 | AV8: 6.9
A9: /Users/christophermarjo/Documents/Python/Projects/data/bushfire Raman/Kings Tableland (RHS)/KTM 1 (3).txt | B9: 13.95 counts | C9: 0.951879 | D9: 1365 | E9: 4483 | F9: 222 | G9: 1059385 | H9: 45.1 | I9: 1592 | J9: 5545 | K9: 128 | L9: 755516 | M9: 32.1 | N9: 1025 | O9: 241 | P9: 33 | Q9: 8466 | R9: 0.4 | S9: 1166 | T9: 665 | U9: 35 | V9: 24775 | W9: 1.1 | X9: 1260 | Y9: 1 | Z9: 1 | AA9: 1 | AB9: 0 | AC9: 1434 | AD9: 757 | AE9: 107 | AF9: 86221 | AG9: 3.7 | AH9: 1494 | AI9: 389 | AJ9: 37 | AK9: 15321 | AL9: 0.7 | AM9: 1598 | AN9: 355 | AO9: 11 | AP9: 4157 | AQ9: 0.2 | AR9: 1748 | AS9: 1891 | AT9: 197 | AU9: 396543 | AV9: 16.9
A10: /Users/christophermarjo/Documents/Python/Projects/data/bushfire Raman/Kings Tableland (RHS)/KTM 1(4).txt | B10: 6.04 counts | C10: 0.982512 | D10: 1367 | E10: 3737 | F10: 212 | G10: 843318 | H10: 60.9 | I10: 1596 | J10: 3791 | K10: 100 | L10: 403539 | M10: 29.1 | N10: 1073 | O10: 321 | P10: 151 | Q10: 51596 | R10: 3.7 | S10: 1156 | T10: 355 | U10: 85 | V10: 32120 | W10: 2.3 | X10: 1272 | Y10: 13 | Z10: 1 | AA10: 14 | AB10: 0 | AC10: 1400 | AD10: 1 | AE10: 1 | AF10: 1 | AG10: 0 | AH10: 1518 | AI10: 289 | AJ10: 31 | AK10: 9537 | AL10: 0.7 | AM10: 1598 | AN10: 327 | AO10: 21 | AP10: 7310 | AQ10: 0.5 | AR10: 1726 | AS10: 395 | AT10: 89 | AU10: 37421 | AV10: 2.7
A11: /Users/christophermarjo/Documents/Python/Projects/data/bushfire Raman/Kings Tableland (RHS)/KTM 2 (3) .txt | B11: 2.75 counts | C11: 0.980828 | D11: 1361 | E11: 1461 | F11: 264 | G11: 410569 | H11: 65.6 | I11: 1592 | J11: 1593 | K11: 100 | L11: 169570 | M11: 27.1 | N11: 1073 | O11: 57 | P11: 111 | Q11: 6735 | R11: 1.1 | S11: 1156 | T11: 17 | U11: 35 | V11: 633 | W11: 0.1 | X11: 1298 | Y11: 27 | Z11: 1 | AA11: 29 | AB11: 0 | AC11: 1400 | AD11: 1 | AE11: 1 | AF11: 1 | AG11: 0 | AH11: 1522 | AI11: 71 | AJ11: 23 | AK11: 1738 | AL11: 0.3 | AM11: 1598 | AN11: 313 | AO11: 21 | AP11: 6997 | AQ11: 1.1 | AR11: 1744 | AS11: 141 | AT11: 199 | AU11: 29868 | AV11: 4.8
A12: /Users/christophermarjo/Documents/Python/Projects/data/bushfire Raman/Kings Tableland (RHS)/KTM 2.5 (1) txt | B12: 7.27 counts | C12: 0.987943 | D12: 1365 | E12: 4695 | F12: 270 | G12: 1349372 | H12: 63.5 | I12: 1594 | J12: 5669 | K12: 100 | L12: 603446 | M12: 28.4 | N12: 1073 | O12: 267 | P12: 125 | Q12: 35527 | R12: 1.7 | S12: 1170 | T12: 67 | U12: 21 | V12: 1498 | W12: 0.1 | X12: 1260 | Y12: 1 | Z12: 1 | AA12: 1 | AB12: 0 | AC12: 1440 | AD12: 37 | AE12: 167 | AF12: 6577 | AG12: 0.3 | AH12: 1528 | AI12: 51 | AJ12: 3 | AK12: 163 | AL12: 0 | AM12: 1592 | AN12: 187 | AO12: 27 | AP12: 5374 | AQ12: 0.3 | AR12: 1744 | AS12: 587 | AT12: 199 | AU12: 124344 | AV12: 5.8
A13: /Users/christophermarjo/Documents/Python/Projects/data/bushfire Raman/Kings Tableland (RHS)/KTM 2.5 (2).txt | B13: 14.15 counts | C13: 0.973639 | D13: 1361 | E13: 6293 | F13: 270 | G13: 1808647 | H13: 59 | I13: 1596 | J13: 7965 | K13: 102 | L13: 864805 | M13: 28.2 | N13: 1035 | O13: 307 | P13: 57 | Q13: 18627 | R13: 0.6 | S13: 1160 | T13: 327 | U13: 1 | V13: 348 | W13: 0 | X13: 1260 | Y13: 1 | Z13: 1 | AA13: 1 | AB13: 0 | AC13: 1434 | AD13: 31 | AE13: 153 | AF13: 5049 | AG13: 0.2 | AH13: 1528 | AI13: 207 | AJ13: 189 | AK13: 41645 | AL13: 1.4 | AM13: 1590 | AN13: 125 | AO13: 1 | AP13: 133 | AQ13: 0 | AR13: 1748 | AS13: 1537 | AT13: 199 | AU13: 325581 | AV13: 10.6
... A40: /Users/christophermarjo/Documents/Python/Projects/data/bushfire Raman/Kings Tableland (RHS)/KTM- 1.5 (3) txt | B40: 21.89 counts | C40: 0.987523 | D40: 1369 | E40: 12079 | F40: 312 | G40: 4011602 | H40: 63 | I40: 1584 | J40: 13901 | K40: 148 | L40: 2189979 | M40: 34.4 | N40: 1013 | O40: 235 | P40: 71 | Q40: 17761 | R40: 0.3 | S40: 1166 | T40: 49 | U40: 1 | V40: 52 | W40: 0 | X40: 1260 | Y40: 1 | Z40: 1 | AA40: 1 | AB40: 0 | AC40: 1434 | AD40: 421 | AE40: 93 | AF40: 41677 | AG40: 0.7 | AH40: 1480 | AI40: 435 | AJ40: 47 | AK40: 21763 | AL40: 0.3 | AM40: 1592 | AN40: 143 | AO40: 15 | AP40: 2283 | AQ40: 0 | AR40: 1748 | AS40: 1187 | AT40: 65 | AU40: 82129 | AV40: 1.3

Sheet Urella Brook
A1: File | B1: Std Err | C1: R_sqrd | D1: D pos | E1: D ht | F1: D fwhm | G1: D area | H1: D %area | I1: G_G pos | J1: G_G ht | K1: G_G fwhm | L1: G_G area | M1: G_G %area | N1: S_L pos | O1: S_L ht | P1: S_L fwhm | Q1: S_L area | R1: S_L %area | S1: S pos | T1: S ht | U1: S fwhm | V1: S area | W1: S %area | X1: D_S pos | Y1: D_S ht | Z1: D_S fwhm | AA1: D_S area | AB1: D_S %area | AC1: A_1 pos | AD1: A_1 ht | AE1: A_1 fwhm | AF1: A_1 area | AG1: A_1 %area | AH1: A_2 pos | AI1: A_2 ht | AJ1: A_2 fwhm | AK1: A_2 area | AL1: A_2 %area | AM1: G_L pos | AN1: G_L ht | AO1: G_L fwhm | AP1: G_L area | AQ1: G_L %area | AR1: C pos | AS1: C ht | AT1: C fwhm | AU1: C area | AV1: C %area
A2: /Users/christophermarjo/Documents/Python/Projects/data/bushfire Raman/Urella Brook/UB 9 (1) | B2: 5.39 counts | C2: 0.990878 | D2: 1369 | E2: 3851 | F2: 298 | G2: 1221580 | H2: 68.1 | I2: 1592 | J2: 4533 | K2: 102 | L2: 492173 | M2: 27.4 | N2: 1063 | O2: 117 | P2: 81 | Q2: 10088 | R2: 0.6 | S2: 1170 | T2: 3 | U2: 3 | V2: 10 | W2: 0 | X2: 1260 | Y2: 1 | Z2: 1 | AA2: 1 | AB2: 0 | AC2: 1450 | AD2: 13 | AE2: 5 | AF2: 69 | AG2: 0 | AH2: 1494 | AI2: 155 | AJ2: 27 | AK2: 4455 | AL2: 0.2 | AM2: 1598 | AN2: 247 | AO2: 27 | AP2: 7099 | AQ2: 0.4 | AR2: 1730 | AS2: 447 | AT2: 125 | AU2: 59477 | AV2: 3.3
A3: /Users/christophermarjo/Documents/Python/Projects/data/bushfire Raman/Urella Brook/UB 0.5 (1) | B3: 13.52 counts | C3: 0.990653 | D3: 1369 | E3: 9593 | F3: 320 | G3: 3267658 | H3: 71.4 | I3: 1592 | J3: 10303 | K3: 100 | L3: 1096720 | M3: 24 | N3: 1045 | O3: 343 | P3: 85 | Q3: 31035 | R3: 0.7 | S3: 1158 | T3: 1 | U3: 1 | V3: 1 | W3: 0 | X3: 1260 | Y3: 1 | Z3: 1 | AA3: 1 | AB3: 0 | AC3: 1400 | AD3: 1 | AE3: 1 | AF3: 1 | AG3: 0 | AH3: 1494 | AI3: 383 | AJ3: 13 | AK3: 5300 | AL3: 0.1 | AM3: 1594 | AN3: 1075 | AO3: 29 | AP3: 33185 | AQ3: 0.7 | AR3: 1744 | AS3: 749 | AT3: 177 | AU3: 141120 | AV3: 3.1
A4: /Users/christophermarjo/Documents/Python/Projects/data/bushfire Raman/Urella Brook/UB 0.5 (2) | B4: 4.47 counts | C4: 0.988365 | D4: 1369 | E4: 2815 | F4: 298 | G4: 892949 | H4: 67.3 | I4: 1592 | J4: 3349 | K4: 104 | L4: 370750 | M4: 27.9 | N4: 1047 | O4: 113 | P4: 81 | Q4: 9743 | R4: 0.7 | S4: 1152 | T4: 13 | U4: 11 | V4: 152 | W4: 0 | X4: 1260 | Y4: 1 | Z4: 1 | AA4: 1 | AB4: 0 | AC4: 1456 | AD4: 47 | AE4: 103 | AF4: 5153 | AG4: 0.4 | AH4: 1510 | AI4: 289 | AJ4: 37 | AK4: 11382 | AL4: 0.9 | AM4: 1598 | AN4: 1 | AO4: 21 | AP4: 22 | AQ4: 0 | AR4: 1732 | AS4: 297 | AT4: 117 | AU4: 36989 | AV4: 2.8
A5: /Users/christophermarjo/Documents/Python/Projects/data/bushfire Raman/Urella Brook/UB 0.5 (3) | B5: 15.34 counts | C5: 0.988905 | D5: 1369 | E5: 10029 | F5: 332 | G5: 3544279 | H5: 72.2 | I5: 1590 | J5: 10315 | K5: 106 | L5: 1163878 | M5: 23.7 | N5: 1037 | O5: 347 | P5: 55 | Q5: 20315 | R5: 0.4 | S5: 1158 | T5: 1 | U5: 1 | V5: 1 | W5: 0 | X5: 1260 | Y5: 1 | Z5: 1 | AA5: 1 | AB5: 0 | AC5: 1456 | AD5: 31 | AE5: 133 | AF5: 4389 | AG5: 0.1 | AH5: 1506 | AI5: 779 | AJ5: 43 | AK5: 35656 | AL5: 0.7 | AM5: 1598 | AN5: 321 | AO5: 1 | AP5: 342 | AQ5: 0 | AR5: 1730 | AS5: 1057 | AT5: 125 | AU5: 140643 | AV5: 2.9
A6: /Users/christophermarjo/Documents/Python/Projects/data/bushfire Raman/Urella Brook/UB 1.5 (1) | B6: 17.71 counts | C6: 0.985208 | D6: 1369 | E6: 9613 | F6: 346 | G6: 3540522 | H6: 69.8 | I6: 1590 | J6: 11435 | K6: 102 | L6: 1241562 | M6: 24.5 | N6: 1035 | O6: 365 | P6: 51 | Q6: 19815 | R6: 0.4 | S6: 1158 | T6: 1 | U6: 1 | V6: 1 | W6: 0 | X6: 1260 | Y6: 1 | Z6: 1 | AA6: 1 | AB6: 0 | AC6: 1408 | AD6: 93 | AE6: 109 | AF6: 10791 | AG6: 0.2 | AH6: 1494 | AI6: 351 | AJ6: 39 | AK6: 14571 | AL6: 0.3 | AM6: 1594 | AN6: 129 | AO6: 21 | AP6: 2884 | AQ6: 0.1 | AR6: 1742 | AS6: 1177 | AT6: 191 | AU6: 239300 | AV6: 4.7
A7: /Users/christophermarjo/Documents/Python/Projects/data/bushfire Raman/Urella Brook/UB 1.5 (1)txt | B7: 19.02 counts | C7: 0.986727 | D7: 1369 | E7: 10725 | F7: 348 | G7: 3972910 | H7: 70.7 | I7: 1590 | J7: 12871 | K7: 104 | L7: 1424879 | M7: 25.3 | N7: 1029 | O7: 397 | P7: 51 | Q7: 21552 | R7: 0.4 | S7: 1158 | T7: 1 | U7: 1 | V7: 1 | W7: 0 | X7: 1260 | Y7: 1 | Z7: 1 | AA7: 1 | AB7: 0 | AC7: 1456 | AD7: 123 | AE7: 123 | AF7: 16104 | AG7: 0.3 | AH7: 1500 | AI7: 481 | AJ7: 43 | AK7: 22016 | AL7: 0.4 | AM7: 1598 | AN7: 139 | AO7: 21 | AP7: 3107 | AQ7: 0.1 | AR7: 1738 | AS7: 1163 | AT7: 131 | AU7: 162175 | AV7: 2.9
A8: /Users/christophermarjo/Documents/Python/Projects/data/bushfire Raman/Urella Brook/UB 1.5 (2) | B8: 20.87 counts | C8: 0.988849 | D8: 1369 | E8: 12993 | F8: 332 | G8: 4591766 | H8: 69.4 | I8: 1590 | J8: 15287 | K8: 104 | L8: 1692341 | M8: 25.6 | N8: 1013 | O8: 301 | P8: 45 | Q8: 14418 | R8: 0.2 | S8: 1158 | T8: 1 | U8: 1 | V8: 1 | W8: 0 | X8: 1260 | Y8: 1 | Z8: 1 | AA8: 1 | AB8: 0 | AC8: 1456 | AD8: 483 | AE8: 91 | AF8: 46787 | AG8: 0.7 | AH8: 1512 | AI8: 945 | AJ8: 43 | AK8: 43255 | AL8: 0.7 | AM8: 1588 | AN8: 23 | AO8: 7 | AP8: 171 | AQ8: 0 | AR8: 1748 | AS8: 1309 | AT8: 163 | AU8: 227122 | AV8: 3.4
A9: /Users/christophermarjo/Documents/Python/Projects/data/bushfire Raman/Urella Brook/UB 1.5 (3) | B9: 19.62 counts | C9: 0.992023 | D9: 1367 | E9: 14743 | F9: 316 | G9: 4959126 | H9: 68.7 | I9: 1588 | J9: 17307 | K9: 102 | L9: 1879119 | M9: 26 | N9: 1029 | O9: 541 | P9: 55 | Q9: 31673 | R9: 0.4 | S9: 1158 | T9: 1 | U9: 1 | V9: 1 | W9: 0 | X9: 1260 | Y9: 1 | Z9: 1 | AA9: 1 | AB9: 0 | AC9: 1450 | AD9: 33 | AE9: 1 | AF9: 35 | AG9: 0 | AH9: 1498 | AI9: 575 | AJ9: 37 | AK9: 22647 | AL9: 0.3 | AM9: 1598 | AN9: 1223 | AO9: 27 | AP9: 35150 | AQ9: 0.5 | AR9: 1746 | AS9: 1515 | AT9: 179 | AU9: 288667 | AV9: 4
