Workbook

Sheet Calculations
A1: Species | B1: Thermal Energy | C1: D pos | D1: D ht | E1: D fwhm | F1: D area | G1: G_G pos | H1: G_G ht | I1: G_G fwhm | J1: G_G area | K1: Thermal Energy | L1: D-FWHM/G-FWHM | M1: R1 (ID/IG) | N1: AD/AG | O1: RBS | Q1: D-FWHM/G-FWHM | Z1: R1 (ID/IG) | AH1: AD/AG | AP1: RBS
K2: kW/m2 | Q2: r= | T2: p=
A3: Silvertop Ash | B3: 20kW/m2 | C3: 1367 | D3: 31959 | E3: 200 | F3: 6803860 | G3: 1584 | H3: 61721 | I3: 123 | J3: 8081096 | K3: 20 | L3: 1.6260163 | M3: 0.51779783 | N3: 0.84194768 | O3: 217 | Q3: =CORREL(K3:K100,L3:L100) -> 0.44115016 | R3: silvertop ash only | T3: <0.00001 | U3: signif | Z3: =CORREL(K3:K100,M3:M100) -> 0.60088383 | AA3: silvertop ash only | AC3: <0.00001 | AD3: signif | AH3: =CORREL(K3:K100, N3:N100) -> 0.62632445 | AI3: silvertop ash only | AK3: <0.00001 | AL3: signif | AP3: =CORREL(K3:K100,O3:O100) -> 0.26085855 | AQ3: silvertop ash only | AS3: <0.00001 | AT3: signif
A4: Silvertop Ash | B4: 20kW/m2 | C4: 1367 | D4: 33995 | E4: 200 | F4: 7237311 | G4: 1586 | H4: 72713 | I4: 127 | J4: 9829875 | K4: 20 | L4: 1.5748031 | M4: 0.467523 | N4: 0.73625667 | O4: 219 | Q4: =CORREL(K3:K145,L3:L145) -> 0.43236187 | R4: all spp | T4: <0.00001 | U4: signif | V4: df=141 | Z4: =CORREL(K3:K145,M3:M145) -> 0.4030289 | AA4: all spp | AC4: <0.00001 | AD4: signif | AH4: =CORREL(K3:K145, N3:N145) -> 0.49583864 | AI4: all spp | AK4: <0.00001 | AL4: signif | AP4: =CORREL(K3:K145,O3:O145) -> 0.18527831 | AQ4: all spp | AS4: 0.02782 | AT4: signif
A5: Silvertop Ash | B5: 20kW/m2 | C5: 1369 | D5: 275 | E5: 188 | F5: 55033 | G5: 1584 | H5: 641 | I5: 101 | J5: 68915 | K5: 20 | L5: 1.8613861 | M5: 0.42901716 | N5: 0.79856345 | O5: 215
A6: Silvertop Ash | B6: 20kW/m2 | C6: 1367 | D6: 39493 | E6: 200 | F6: 8407799 | G6: 1588 | H6: 73305 | I6: 119 | J6: 9285660 | K6: 20 | L6: 1.6806723 | M6: 0.53874906 | N6: 0.90546057 | O6: 221
A7: Silvertop Ash | B7: 20kW/m2 | C7: 1367 | D7: 36337 | E7: 200 | F7: 7735908 | G7: 1588 | H7: 66583 | I7: 117 | J7: 8292423 | K7: 20 | L7: 1.7094017 | M7: 0.5457399 | N7: 0.93288874 | O7: 221
A8: Silvertop Ash | B8: 20kW/m2 | C8: 1365 | D8: 45811 | E8: 200 | F8: 9752860 | G8: 1584 | H8: 80295 | I8: 127 | J8: 10854865 | K8: 20 | L8: 1.5748031 | M8: 0.57053366 | N8: 0.89847824 | O8: 219
A9: Silvertop Ash | B9: 20kW/m2 | C9: 1365 | D9: 6219 | E9: 200 | F9: 1323984 | G9: 1584 | H9: 10913 | I9: 137 | J9: 1591464 | K9: 20 | L9: 1.459854 | M9: 0.5698708 | N9: 0.83192834 | O9: 219
A10: Silvertop Ash | B10: 20kW/m2 | C10: 1367 | D10: 10383 | E10: 200 | F10: 2210472 | G10: 1586 | H10: 18801 | I10: 127 | J10: 2541657 | K10: 20 | L10: 1.5748031 | M10: 0.55225786 | N10: 0.86969721 | O10: 219
A11: Silvertop Ash | B11: 20kW/m2 | C11: 1365 | D11: 9983 | E11: 200 | F11: 2125315 | G11: 1586 | H11: 19413 | I11: 139 | J11: 2872365 | K11: 20 | L11: 1.4388489 | M11: 0.51424303 | N11: 0.73991815 | O11: 221
A12: Silvertop Ash | B12: 20kW/m2 | C12: 1367 | D12: 6011 | E12: 200 | F12: 1279702 | G12: 1586 | H12: 12299 | I12: 127 | J12: 1662669 | K12: 20 | L12: 1.5748031 | M12: 0.48873892 | N12: 0.76966732 | O12: 219
A13: Silvertop Ash | B13: 20kW/m2 | C13: 1367 | D13: 36105 | E13: 200 | F13: 7686516 | G13: 1584 | H13: 64351 | I13: 137 | J13: 9384434 | K13: 20 | L13: 1.459854 | M13: 0.56106354 | N13: 0.81907081 | O13: 217
A14: Silvertop Ash | B14: 20kW/m2 | C14: 1365 | D14: 25793 | E14: 200 | F14: 5491160 | G14: 1584 | H14: 50809 | I14: 137 | J14: 7409577 | K14: 20 | L14: 1.459854 | M14: 0.50764628 | N14: 0.74108954 | O14: 219
A15: Silvertop Ash | B15: 20kW/m2 | C15: 1365 | D15: 25215 | E15: 200 | F15: 5368107 | G15: 1584 | H15: 47273 | I15: 147 | J15: 7397121 | K15: 20 | L15: 1.3605442 | M15: 0.53339115 | N15: 0.7257022 | O15: 219
A16: Silvertop Ash | B16: 20kW/m2 | C16: 1369 | D16: 11227 | E16: 146 | F16: 1744813 | G16: 1584 | H16: 66007 | I16: 101 | J16: 7096490 | K16: 20 | L16: 1.4455446 | M16: 0.17008802 | N16: 0.24586986 | O16: 215 | Q16: =AVERAGE(M16:M19) -> 0.17567954
A17: Silvertop Ash | B17: 20kW/m2 | C17: 1369 | D17: 11843 | E17: 150 | F17: 1890972 | G17: 1586 | H17: 59945 | I17: 107 | J17: 6827614 | K17: 20 | L17: 1.4018692 | M17: 0.19756443 | N17: 0.27695942 | O17: 217
A18: Silvertop Ash | B18: 20kW/m2 | C18: 1369 | D18: 1665 | E18: 142 | F18: 251672 | G18: 1590 | H18: 10657 | I18: 101 | J18: 1145747 | K18: 20 | L18: 1.4059406 | M18: 0.15623534 | N18: 0.21965757 | O18: 221
A19: Silvertop Ash | B19: 20kW/m2 | C19: 1369 | D19: 3379 | E19: 156 | F19: 561106 | G19: 1584 | H19: 18895 | I19: 117 | J19: 2353233 | K19: 20 | L19: 1.3333333 | M19: 0.17883038 | N19: 0.23844048 | O19: 215
A20: Silvertop Ash | B20: 25kW/m2 | C20: 1365 | D20: 19515 | E20: 200 | F20: 4154615 | G20: 1590 | H20: 27357 | I20: 103 | J20: 2999424 | K20: 25 | L20: 1.9417476 | M20: 0.71334576 | N20: 1.3851376 | O20: 225
A21: Silvertop Ash | B21: 25kW/m2 | C21: 1367 | D21: 15855 | E21: 200 | F21: 3375425 | G21: 1588 | H21: 30041 | I21: 119 | J21: 3805341 | K21: 25 | L21: 1.6806723 | M21: 0.5277787 | N21: 0.887023 | O21: 221
A22: Silvertop Ash | B22: 25kW/m2 | C22: 1365 | D22: 19839 | E22: 200 | F22: 4223592 | G22: 1584 | H22: 28405 | I22: 119 | J22: 3598106 | K22: 25 | L22: 1.6806723 | M22: 0.69843337 | N22: 1.1738376 | O22: 219
A23: Silvertop Ash | B23: 25kW/m2 | C23: 1365 | D23: 28415 | E23: 200 | F23: 6049366 | G23: 1592 | H23: 38873 | I23: 113 | J23: 4675830 | K23: 25 | L23: 1.7699115 | M23: 0.73097008 | N23: 1.2937523 | O23: 227
A24: Silvertop Ash | B24: 25kW/m2 | C24: 1365 | D24: 27517 | E24: 200 | F24: 5858188 | G24: 1590 | H24: 37903 | I24: 113 | J24: 4559154 | K24: 25 | L24: 1.7699115 | M24: 0.72598475 | N24: 1.2849287 | O24: 225
A25: Silvertop Ash | B25: 25kW/m2 | C25: 1367 | D25: 30765 | E25: 200 | F25: 6549666 | G25: 1590 | H25: 41883 | I25: 113 | J25: 5037887 | K25: 25 | L25: 1.7699115 | M25: 0.73454624 | N25: 1.300082 | O25: 223
A26: Silvertop Ash | B26: 25kW/m2 | C26: 1367 | D26: 30765 | E26: 200 | F26: 6549666 | G26: 1590 | H26: 41883 | I26: 113 | J26: 5037887 | K26: 25 | L26: 1.7699115 | M26: 0.73454624 | N26: 1.300082 | O26: 223
A27: Silvertop Ash | B27: 25kW/m2 | C27: 1365 | D27: 31883 | E27: 200 | F27: 6787681 | G27: 1590 | H27: 44225 | I27: 113 | J27: 5319594 | K27: 25 | L27: 1.7699115 | M27: 0.72092708 | N27: 1.2759773 | O27: 225
A28: Silvertop Ash | B28: 25kW/m2 | C28: 1367 | D28: 30607 | E28: 200 | F28: 6516029 | G28: 1590 | H28: 42093 | I28: 113 | J28: 5063147 | K28: 25 | L28: 1.7699115 | M28: 0.72712803 | N28: 1.2869524 | O28: 223
... A37: Silvertop Ash | B37: 25kW/m2 | C37: 1365 | D37: 16051 | E37: 200 | F37: 3417152 | G37: 1588 | H37: 29055 | I37: 119 | J37: 3680443 | K37: 25 | L37: 1.6806723 | M37: 0.55243504 | N37: 0.92846214 | O37: 223
A38: Silvertop Ash | B38: 25kW/m2 | C38: 1367 | D38: 20885 | E38: 200 | F38: 4446279 | G38: 1588 | H38: 34779 | I38: 119 | J38: 4405511 | K38: 25 | L38: 1.6806723 | M38: 0.60050605 | N38: 1.0092539 | O38: 221 | Q38: if consider only lower applied energy
A39: Silvertop Ash | B39: 25kW/m2 | C39: 1365 | D39: 20987 | E39: 200 | F39: 4467994 | G39: 1584 | H39: 30483 | I39: 117 | J39: 3796433 | K39: 25 | L39: 1.7094017 | M39: 0.6884821 | N39: 1.1768926 | O39: 219
A40: Silvertop Ash | B40: 25kW/m2 | C40: 1365 | D40: 34369 | E40: 200 | F40: 7316934 | G40: 1584 | H40: 50371 | I40: 127 | J40: 6809520 | K40: 25 | L40: 1.5748031 | M40: 0.68231721 | N40: 1.0745154 | O40: 219 | Q40: r=
A41: Silvertop Ash | B41: 30kW/m2 | C41: 1365 | D41: 5783 | E41: 200 | F41: 1231163 | G41: 1592 | H41: 9373 | I41: 103 | J41: 1027657 | K41: 30 | L41: 1.9417476 | M41: 0.61698496 | N41: 1.1980291 | O41: 227 | Q41: =CORREL(K3:K80,L3:L80) -> 0.77175821 | R41: silverrtop ash only
A42: Silvertop Ash | B42: 30kW/m2 | C42: 1365 | D42: 8927 | E42: 200 | F42: 1900499 | G42: 1594 | H42: 14259 | I42: 103 | J42: 1563358 | K42: 30 | L42: 1.9417476 | M42: 0.62606073 | N42: 1.2156518 | O42: 229 | Q42: p=
A43: Silvertop Ash | B43: 30kW/m2 | C43: 1365 | D43: 5889 | E43: 200 | F43: 1253729 | G43: 1596 | H43: 8839 | I43: 101 | J43: 950291 | K43: 30 | L43: 1.980198 | M43: 0.66625184 | N43: 1.3193106 | O43: 231 | Q43: <0.00001
A44: Silvertop Ash | B44: 30kW/m2 | C44: 1365 | D44: 2993 | E44: 200 | F44: 637190 | G44: 1588 | H44: 5329 | I44: 111 | J44: 629652 | K44: 30 | L44: 1.8018018 | M44: 0.56164384 | N44: 1.0119717 | O44: 223 | Q44: signif
A45: Silvertop Ash | B45: 30kW/m2 | C45: 1365 | D45: 23595 | E45: 200 | F45: 5023220 | G45: 1588 | H45: 41087 | I45: 129 | J45: 5641913 | K45: 30 | L45: 1.5503876 | M45: 0.57426923 | N45: 0.89033986 | O45: 223 | R45: all species
A46: Silvertop Ash | B46: 30kW/m2 | C46: 1365 | D46: 22891 | E46: 200 | F46: 4873343 | G46: 1584 | H46: 37305 | I46: 127 | J46: 5043163 | K46: 30 | L46: 1.5748031 | M46: 0.61361748 | N46: 0.96632669 | O46: 219
A47: Silvertop Ash | B47: 30kW/m2 | C47: 1365 | D47: 33233 | E47: 200 | F47: 7075087 | G47: 1586 | H47: 58821 | I47: 117 | J47: 7325723 | K47: 30 | L47: 1.7094017 | M47: 0.56498529 | N47: 0.96578686 | O47: 221
A48: Silvertop Ash | B48: 30kW/m2 | C48: 1367 | D48: 22081 | E48: 200 | F48: 4700899 | G48: 1586 | H48: 37397 | I48: 115 | J48: 4577905 | K48: 30 | L48: 1.7391304 | M48: 0.59044843 | N48: 1.0268669 | O48: 219
...

Sheet ANOVA data
A1: Thermal Energy | B1: D-FWHM/G-FWHM | C1: R1 (ID/IG) | D1: AD/AG | E1: RBS | F1: Species
A2: kW/m2
A3: 20 | B3: 1.6260163 | C3: 0.51779783 | D3: 0.84194768 | E3: 217 | F3: Silvertop Ash
A4: 20 | B4: 1.5748031 | C4: 0.467523 | D4: 0.73625667 | E4: 219 | F4: Silvertop Ash
A5: 20 | B5: 1.8613861 | C5: 0.42901716 | D5: 0.79856345 | E5: 215 | F5: Silvertop Ash
A6: 20 | B6: 1.6806723 | C6: 0.53874906 | D6: 0.90546057 | E6: 221 | F6: Silvertop Ash
A7: 20 | B7: 1.7094017 | C7: 0.5457399 | D7: 0.93288874 | E7: 221 | F7: Silvertop Ash
A8: 20 | B8: 1.5748031 | C8: 0.57053366 | D8: 0.89847824 | E8: 219 | F8: Silvertop Ash
A9: 20 | B9: 1.459854 | C9: 0.5698708 | D9: 0.83192834 | E9: 219 | F9: Silvertop Ash
A10: 20 | B10: 1.5748031 | C10: 0.55225786 | D10: 0.86969721 | E10: 219 | F10: Silvertop Ash
A11: 20 | B11: 1.4388489 | C11: 0.51424303 | D11: 0.73991815 | E11: 221 | F11: Silvertop Ash
A12: 20 | B12: 1.5748031 | C12: 0.48873892 | D12: 0.76966732 | E12: 219 | F12: Silvertop Ash
A13: 20 | B13: 1.459854 | C13: 0.56106354 | D13: 0.81907081 | E13: 217 | F13: Silvertop Ash
A14: 20 | B14: 1.459854 | C14: 0.50764628 | D14: 0.74108954 | E14: 219 | F14: Silvertop Ash
... A145: 50 | B145: 1.7391304 | C145: 0.60883672 | D145: 1.0588467 | E145: 217 | F145: Spotted Gum

Sheet r using averages
B1: applied energy | C1: D-FWHM/G-FWHM | D1: R1 (ID/IG) | E1: AD/AG | F1: RBS
B2: 20 | C2: =AVERAGE(Calculations!L3:L19) -> 1.5260195 | D2: =AVERAGE(Calculations!M3:M19) -> 0.44113473 | E2: =AVERAGE(Calculations!N3:N19) -> 0.6818586 | F2: =AVERAGE(Calculations!O3:O19) -> 218.41176 | G2: Perasons Correlation | H2: =CORREL(B2:B6,C2:C6) -> 0.59261805 | I2: =CORREL(B2:B6,D2:D6) -> 0.74278948 | J2: =CORREL(B2:B6,E2:E6) -> 0.71743875 | K2: =CORREL(B2:B6,F2:F6) -> 0.41004183
B3: 25 | C3: =AVERAGE(Calculations!L20:L40) -> 1.7665862 | D3: =AVERAGE(Calculations!M20:M40) -> 0.69963243 | E3: =AVERAGE(Calculations!N20:N40) -> 1.2383269 | F3: =AVERAGE(Calculations!O20:O40) -> 222.71429 | G3: p value | H3: 0.292321 | I3: 0.150394 | J3: 0.172491 | K3: 0.49299
B4: 30 | C4: =AVERAGE(Calculations!L41:L60) -> 1.8198276 | D4: =AVERAGE(Calculations!M41:M60) -> 0.60011455 | E4: =AVERAGE(Calculations!N41:N60) -> 1.0928122 | F4: =AVERAGE(Calculations!O41:O60) -> 224.4 | H4: None of these results are significant at p < .05.
B5: 35 | C5: =AVERAGE(Calculations!L61:L80) -> 2.0618203 | D5: =AVERAGE(Calculations!M61:M80) -> 0.74609005 | E5: =AVERAGE(Calculations!N61:N80) -> 1.530806 | F5: =AVERAGE(Calculations!O61:O80) -> 226.3
B6: 50 | C6: =AVERAGE(Calculations!L81:L100) -> 1.8544316 | D6: =AVERAGE(Calculations!M81:M100) -> 0.75947918 | E6: =AVERAGE(Calculations!N81:N100) -> 1.4061297 | F6: =AVERAGE(Calculations!O81:O100) -> 222.5

Sheet Descriptive stats
B1: Thermal Energy | C1: Mean | D1: Std. Deviation | E1: Minimum | F1: Maximum
A2: D fwhm | B2: 20 | C2: 187.18 | D2: 22.45 | E2: 142 | F2: 200
B3: 25 | C3: 200 | D3: 0 | E3: 200 | F3: 200
B4: 30 | C4: 200 | D4: 0 | E4: 200 | F4: 200
B5: 35 | C5: 200 | D5: 0 | E5: 200 | F5: 200
B6: 50 | C6: 200 | D6: 0 | E6: 200 | F6: 200
C9: Mean | D9: Std. Deviation | E9: Minimum | F9: Maximum
B10: 20 | C10: 123 | D10: 14.32 | E10: 101 | F10: 147
A11: G_G fwhm | B11: 25 | C11: 113.48 | D11: 5.58 | E11: 101 | F11: 127
B12: 30 | C12: 111.1 | D12: 12.06 | E12: 93 | F12: 129
B13: 35 | C13: 97.5 | D13: 7.31 | E13: 85 | F13: 111
B14: 50 | C14: 108.2 | D14: 6.14 | E14: 91 | F14: 119
C17: Mean | D17: Std. Deviation | E17: Minimum | F17: Maximum
B18: 20 | C18: 0.44 | D18: 0.16 | E18: 0.16 | F18: 0.57
A19: R1 (ID/IG) | B19: 25 | C19: 0.7 | D19: 0.06 | E19: 0.53 | F19: 0.76
B20: 30 | C20: 0.6 | D20: 0.03 | E20: 0.53 | F20: 0.67
B21: 35 | C21: 0.75 | D21: 0.06 | E21: 0.63 | F21: 0.85
B22: 50 | C22: 0.76 | D22: 0.03 | E22: 0.68 | F22: 0.82
C26: Mean | D26: Std. Deviation | E26: Minimum | F26: Maximum
B27: 20 | C27: 0.68 | D27: 0.26 | E27: 0.22 | F27: 0.93
A28: AD/AG | B28: 25 | C28: 1.24 | D28: 0.14 | E28: 0.89 | F28: 1.39
B29: 30 | C29: 1.09 | D29: 0.13 | E29: 0.89 | F29: 1.32
B30: 35 | C30: 1.53 | D30: 0.05 | E30: 1.44 | F30: 1.65
B31: 50 | C31: 1.41 | D31: 0.06 | E31: 1.28 | F31: 1.52
C34: Mean | D34: Std. Deviation | E34: Minimum | F34: Maximum
B35: 20 | C35: 218.41 | D35: 2.09 | E35: 215 | F35: 221
A36: RBS | B36: 25 | C36: 222.71 | D36: 2.39 | E36: 219 | F36: 227
B37: 30 | C37: 224.4 | D37: 4.31 | E37: 219 | F37: 231
B38: 35 | C38: 226.3 | D38: 1.63 | E38: 223 | F38: 229
B39: 50 | C39: 222.5 | D39: 1.82 | E39: 219 | F39: 225
C42: Mean | D42: Std. Deviation | E42: Minimum | F42: Maximum
B43: 20 | C43: 1.53 | D43: 0.14 | E43: 1.33 | F43: 1.86
A44: Dfwhm/Gfwhm | B44: 25 | C44: 1.77 | D44: 0.09 | E44: 1.57 | F44: 1.98
B45: 30 | C45: 1.82 | D45: 0.19 | E45: 1.55 | F45: 2.15
B46: 35 | C46: 2.06 | D46: 0.15 | E46: 1.8 | F46: 2.35
B47: 50 | C47: 1.85 | D47: 0.11 | E47: 1.68 | F47: 2.2
